Workbook

Sheet 引用数据库
A1: 面板可见 | B1: 实际参与游戏内功能或数值计算，当数值存在(非空)时，在对应道具的面板可见 | I1: Item大类 | N1: 武器类型 | P1: ="种类" & COUNTIF(Q2:Q100,">0") | Q1: ="数量" & SUM(Q2:Q100) | R1: ="技能" & SUM(R2:R100) | S1: 伤害/子弹类型 | V1: =SUM(V2:V15) | W1: 品质 | Y1: 类目 | Z1: 阵营 | AD1: 装备 | AE1: 系列 | AF1: 装备系列 | AG1: Name | AH1: 来自阵营 | AI1: 描述 | AJ1: Count | AL1: 义体类型 | AO1: =SUM(AO3:AO11) | AQ1: 效果TAG | AR1: =SUM(AR2:AR100) | AS1: 描述
A2: 特殊显示 | B2: 只显示在特定（比如游戏内wiki）页面的信息 | I2: WPN | J2: Weapon | K2: 武器 | N2: 手枪 | O2: Pistol | P2: 01 | Q2: =COUNTIF('武器'!H:H,N2)/6 | R2: =COUNTIF('武器技能'!E:E,N2) | S2: 动能 | T2: Kinetic | U2: 01 | V2: =COUNTIF('武器'!I:I,S2) | W2: 01 | Y2: CYB | Z2: 纪念碑 | AA2: Monument | AB2: MM | AC2: 01 | AD2: =COUNTIF('义体&义体技能'!E:E,Z2) | AE2: =COUNTIF(AH:AH,Z2) | AF2: 奥德赛 | AG2: Odyssey | AH2: 纪念碑 | AI2: 用于归纳所有“致敬”类的义体和芯片。 | AJ2: =IF(COUNTIF('义体&义体技能'!Z:Z,AF2)=0,"",COUNTIF('义体&义体技能'!Z:Z,AF2)) | AL2: 行为芯片 | AM2: Chip | AN2: 99 | AO2: =COUNTIF('义体&义体技能'!F:F,AL2) | AQ2: 增伤 | AR2: =COUNTIF('义体&义体技能'!AE:AE,AQ2) | AS2: 增加造成的伤害 | AU2: 智脑 | AV2: ExoBrain | AW2: 00 | AX2: =COUNTIF('武器'!H:H,AU2)/6 | AY2: =COUNTIF('武器技能'!E:E,AU2)
A3: 面板隐藏 | B3: 实际参与游戏内功能或数值计算，在对应道具的面板不可见 | I3: EOB | J3: ExoBrain | K3: 智脑 | N3: 步枪 | O3: Rifle | P3: 02 | Q3: =COUNTIF('武器'!H:H,N3)/6 | R3: =COUNTIF('武器技能'!E:E,N3) | S3: 电磁 | T3: Electrical | U3: 02 | V3: =COUNTIF('武器'!I:I,S3) | W3: 02 | Z3: 野望 | AA3: Wild Watch | AB3: WW | AC3: 02 | AD3: =COUNTIF('义体&义体技能'!E:E,Z3) | AE3: =COUNTIF(AH:AH,Z3) | AF3: 公域 | AG3: Public Domain | AH3: 纪念碑 | AI3: 不提供特殊机制，但按百分比提升所有基础属性（血、攻、防、速）。装备的“公域”系列越多，加成越高。简单的数值美学。 | AJ3: =IF(COUNTIF('义体&义体技能'!Z:Z,AF3)=0,"",COUNTIF('义体&义体技能'!Z:Z,AF3)) | AL3: 主手 | AM3: MainHand | AN3: 01 | AO3: =COUNTIF('义体&义体技能'!F:F,AL3) | AQ3: 减伤 | AR3: =COUNTIF('义体&义体技能'!AE:AE,AQ3) | AS3: 伤害减免、生存强化
A4: 仅用于计算 | B4: 不参与实际游戏内功能或数值计算，仅用于在配表时计算数据平衡 | I4: CYB | J4: Cyborg | K4: 义体 | N4: 冲锋枪 | O4: Submachine Gun | P4: 03 | Q4: =COUNTIF('武器'!H:H,N4)/6 | R4: =COUNTIF('武器技能'!E:E,N4) | S4: 热能 | T4: Thermal | U4: 03 | V4: =COUNTIF('武器'!I:I,S4) | W4: 03 | Z4: 劳旅 | AA4: L.Labor | AB4: LL | AC4: 03 | AD4: =COUNTIF('义体&义体技能'!E:E,Z4) | AE4: =COUNTIF(AH:AH,Z4) | AF4: 档案馆 | AG4: Archive | AH4: 纪念碑 | AI4: 在一个关卡内，击杀敌人越多，临时属性提升越高（关卡结束重置）。或者提供额外的经验值/熟练度获取。 | AJ4: =IF(COUNTIF('义体&义体技能'!Z:Z,AF4)=0,"",COUNTIF('义体&义体技能'!Z:Z,AF4)) | AL4: 副手 | AM4: OffHand | AN4: 02 | AO4: =COUNTIF('义体&义体技能'!F:F,AL4) | AQ4: 会心 | AR4: =COUNTIF('义体&义体技能'!AE:AE,AQ4) | AS4: 暴击率、暴击伤害
A5: 游戏内不涉及 | B5: 仅涉及项目管理、设计等信息 | I5: CHP | J5: BehaviorChip | K5: 行为芯片 | N5: 霰弹枪 | O5: Shotgun | P5: 04 | Q5: =COUNTIF('武器'!H:H,N5)/6 | R5: =COUNTIF('武器技能'!E:E,N5) | S5: 纳米 | T5: Nano | U5: 04 | V5: =COUNTIF('武器'!I:I,S5) | W5: 04 | Z5: 新浦会 | AA5: Syn Pu | AB5: SP | AC5: 04 | AD5: =COUNTIF('义体&义体技能'!E:E,Z5) | AE5: =COUNTIF(AH:AH,Z5) | AF5: 图灵 | AG5: Turing | AH5: 纪念碑 | AI5: 成功“完美闪避”敌人的攻击后，该敌人进入“被看破”状态，受到的下一次伤害翻倍。适合高手“防反流”。 | AJ5: =IF(COUNTIF('义体&义体技能'!Z:Z,AF5)=0,"",COUNTIF('义体&义体技能'!Z:Z,AF5)) | AL5: 腿部 | AM5: Leg | AN5: 03 | AO5: =COUNTIF('义体&义体技能'!F:F,AL5) | AQ5: DOT | AR5: =COUNTIF('义体&义体技能'!AE:AE,AQ5) | AS5: 持续伤害
I6: SDA/SDP | J6: Spell | K6: 技能 | N6: 狙击枪 | O6: Sniper Rifle | P6: 05 | Q6: =COUNTIF('武器'!H:H,N6)/6 | R6: =COUNTIF('武器技能'!E:E,N6) | T6: Radioactive | U6: 05 | V6: =COUNTIF('武器'!I:I,S6) | W6: 05 | Z6: 洛克海德 | AA6: Lock Header | AB6: LH | AC6: 05 | AD6: =COUNTIF('义体&义体技能'!E:E,Z6) | AE6: =COUNTIF(AH:AH,Z6) | AF6: 泰坦 | AG6: Titan | AH6: 纪念碑 | AI6: 缩窄攻击范围，强化所有的直线型攻击（如刺击、激光），增加其射程和判定宽度。 | AJ6: =IF(COUNTIF('义体&义体技能'!Z:Z,AF6)=0,"",COUNTIF('义体&义体技能'!Z:Z,AF6)) | AL6: 皮肤 | AM6: Skin | AN6: 04 | AO6: =COUNTIF('义体&义体技能'!F:F,AL6) | AQ6: 扩散 | AR6: =COUNTIF('义体&义体技能'!AE:AE,AQ6) | AS6: 范围传递、连锁爆炸
A7: 技能序号介绍 | B7: SKL01010001 | C7: SKL (技能) | D7: 01 (主/被动) | E7: 01 (武器种类/义体部位/智脑释放) | F7: 01 (技能用途) | G7: 00 (名称哈希) | I7: AMM | J7: Ammo | K7: 弹药 | N7: 喷射器 | O7: Thrower | P7: 06 | Q7: =COUNTIF('武器'!H:H,N7)/6 | R7: =COUNTIF('武器技能'!E:E,N7) | T7: Neural | U7: 06 | V7: =COUNTIF('武器'!I:I,S7) | Z7: 寰宇 | AA7: Omniverse | AB7: OV | AC7: 06 | AD7: =COUNTIF('义体&义体技能'!E:E,Z7) | AE7: =COUNTIF(AH:AH,Z7) | AF7: 街头小子 | AG7: Street Kid | AH7: 野望 | AI7: 持有的金钱（或代币）越多，伤害越高。或者击杀敌人掉落更多金钱。适合“贪婪流”运营。 | AJ7: =IF(COUNTIF('义体&义体技能'!Z:Z,AF7)=0,"",COUNTIF('义体&义体技能'!Z:Z,AF7)) | AL7: 骨骼 | AM7: Bones | AN7: 05 | AO7: =COUNTIF('义体&义体技能'!F:F,AL7) | AQ7: 减益 | AR7: =COUNTIF('义体&义体技能'!AE:AE,AQ7) | AS7: 麻痹、易伤、降防等非伤害负面状态
A8: 武器序号介绍 | B8: WPN01010101 | C8: WPN (武器) | D8: 01 (阵营) | E8: 01 (武器种类) | F8: 01 (伤害类型) | G8: 01 (品质) | I8: BUF | K8: BUFF | N8: 发射器 | O8: Launcher | P8: 07 | Q8: =COUNTIF('武器'!H:H,N8)/6 | R8: =COUNTIF('武器技能'!E:E,N8) | Z8: 致远生物 | AA8: Bio Nexus | AB8: BN | AC8: 07 | AD8: =COUNTIF('义体&义体技能'!E:E,Z8) | AE8: =COUNTIF(AH:AH,Z8) | AF8: 夜幕刺客 | AG8: Night Assassin | AH8: 野望 | AI8: 爆发、暴击、脆皮。极致的玻璃大炮，追求一击必杀，但自身防御极低。 | AJ8: =IF(COUNTIF('义体&义体技能'!Z:Z,AF8)=0,"",COUNTIF('义体&义体技能'!Z:Z,AF8)) | AL8: 肺叶 | AM8: Lung | AN8: 06 | AO8: =COUNTIF('义体&义体技能'!F:F,AL8) | AQ8: 冷却 | AR8: =COUNTIF('义体&义体技能'!AE:AE,AQ8) | AS8: 技能冷却、能量回复
A9: 义体序号介绍 | B9: CYB01010101 | C9: CYB (义体) | D9: 01 (阵营) | E9: 01 (部位) | F9: 01 (系列) | G9: 00 (名称哈希) | I9: HPT | K9: 回复道具 | N9: 短刀 | O9: Kinfe | P9: 08 | Q9: =COUNTIF('武器'!H:H,N9)/6 | R9: =COUNTIF('武器技能'!E:E,N9) | Z9: 律动智能 | AA9: Rhythm Intelligence | AB9: RI | AC9: 08 | AD9: =COUNTIF('义体&义体技能'!E:E,Z9) | AE9: =COUNTIF(AH:AH,Z9) | AF9: 炼狱 | AG9: Inferno | AH9: 野望 | AI9: 火焰、爆炸、自伤。大范围的燃烧和爆炸伤害，往往容易误伤自己或队友。 | AJ9: =IF(COUNTIF('义体&义体技能'!Z:Z,AF9)=0,"",COUNTIF('义体&义体技能'!Z:Z,AF9)) | AL9: 眼球 | AM9: Eye | AN9: 07 | AO9: =COUNTIF('义体&义体技能'!F:F,AL9) | AQ9: 增益 | AR9: =COUNTIF('义体&义体技能'!AE:AE,AQ9) | AS9: 攻速叠加、属性成长
A10: 智脑序号介绍 | B10: CYB01010101 | C10: ITB (智脑) | D10: 01 (阵营) | E10: 00 (占位符) | F10: 00 (占位符) | G10: 00 (名称哈希) | I10: LVL | K10: 关卡道具 | N10: 长刀 | O10: Sword | P10: 09 | Q10: =COUNTIF('武器'!H:H,N10)/6 | R10: =COUNTIF('武器技能'!E:E,N10) | Z10: 耶利哥 | AA10: Jericho | AB10: JC | AC10: 09 | AD10: =COUNTIF('义体&义体技能'!E:E,Z10) | AE10: =COUNTIF(AH:AH,Z10) | AF10: 头奖 | AG10: Jackpot | AH10: 野望 | AI10: 随机性、赌博、暴富。攻击伤害浮动巨大，或有几率造成特殊的“幸运一击”（如秒杀小怪或掉落翻倍）。 | AJ10: =IF(COUNTIF('义体&义体技能'!Z:Z,AF10)=0,"",COUNTIF('义体&义体技能'!Z:Z,AF10)) | AL10: 心脏 | AM10: Heart | AN10: 08 | AO10: =COUNTIF('义体&义体技能'!F:F,AL10) | AQ10: 控制 | AR10: =COUNTIF('义体&义体技能'!AE:AE,AQ10) | AS10: 击倒、眩晕、硬直
I11: STY | K11: 剧情道具 | N11: 武士刀 | O11: Katana | P11: 10 | Q11: =COUNTIF('武器'!H:H,N11)/6 | R11: =COUNTIF('武器技能'!E:E,N11) | Z11: 东海工业 | AA11: Donghai Industry | AB11: DH | AC11: 10 | AD11: =COUNTIF('义体&义体技能'!E:E,Z11) | AE11: =COUNTIF(AH:AH,Z11) | AF11: 废土 | AG11: Wasteland | AH11: 野望 | AI11: 霸体 + 反伤的“刺猬流”被动输出。 | AJ11: =IF(COUNTIF('义体&义体技能'!Z:Z,AF11)=0,"",COUNTIF('义体&义体技能'!Z:Z,AF11)) | AL11: 内脑 | AM11: InnerBrain | AN11: 09 | AO11: =COUNTIF('义体&义体技能'!F:F,AL11) | AQ11: 体力 | AR11: =COUNTIF('义体&义体技能'!AE:AE,AQ11) | AS11: 体力消耗、恢复
N12: 巨剑 | O12: Great Sword | P12: 11 | Q12: =COUNTIF('武器'!H:H,N12)/6 | R12: =COUNTIF('武器技能'!E:E,N12) | AF12: 劳工 | AG12: Workforce | AH12: 劳旅 | AI12: 负重、耐力、持续作业。基础工业外骨骼，增加耐力条上限、恢复效率和武器、装备的使用效率。 | AJ12: =IF(COUNTIF('义体&义体技能'!Z:Z,AF12)=0,"",COUNTIF('义体&义体技能'!Z:Z,AF12)) | AQ12: 潜行 | AR12: =COUNTIF('义体&义体技能'!AE:AE,AQ12) | AS12: 潜行、光学迷彩
N13: 锤 | O13: Hammer | P13: 12 | Q13: =COUNTIF('武器'!H:H,N13)/6 | R13: =COUNTIF('武器技能'!E:E,N13) | AF13: 强袭 | AG13: Strike | AH13: 劳旅 | AI13: 大幅提升攻击的“削韧值”（打出敌人硬直的能力）。对已被击晕/倒地的敌人造成巨额额外伤害。 | AJ13: =IF(COUNTIF('义体&义体技能'!Z:Z,AF13)=0,"",COUNTIF('义体&义体技能'!Z:Z,AF13)) | AQ13: 反伤 | AR13: =COUNTIF('义体&义体技能'!AE:AE,AQ13) | AS13: 受击触发反击、能量脉冲
N14: 巨锤 | O14: Great Hammer | P14: 13 | Q14: =COUNTIF('武器'!H:H,N14)/6 | R14: =COUNTIF('武器技能'!E:E,N14) | AF14: 爆破组 | AG14: Demolition | AH14: 劳旅 | AI14: 定点爆破、陷阱、破坏环境。基于矿业炸药改装，擅长埋设地雷或炸开墙壁/掩体。 | AJ14: =IF(COUNTIF('义体&义体技能'!Z:Z,AF14)=0,"",COUNTIF('义体&义体技能'!Z:Z,AF14)) | AQ14: 随机性 | AR14: =COUNTIF('义体&义体技能'!AE:AE,AQ14) | AS14: 概率触发、超载风险
N15: 拳套 | O15: Kuckles | P15: 14 | Q15: =COUNTIF('武器'!H:H,N15)/6 | R15: =COUNTIF('武器技能'!E:E,N15) | AF15: 重构 | AG15: Reconstruct | AH15: 劳旅 | AI15: 建造、修理、炮塔。搭建临时掩体或维修友方机械单位。 | AJ15: =IF(COUNTIF('义体&义体技能'!Z:Z,AF15)=0,"",COUNTIF('义体&义体技能'!Z:Z,AF15)) | AQ15: 射程 | AR15: =COUNTIF('义体&义体技能'!AE:AE,AQ15) | AS15: 远程精准、有效距离
N16: 弓 | O16: Bow | P16: 15 | Q16: =COUNTIF('武器'!H:H,N16)/6 | R16: =COUNTIF('武器技能'!E:E,N16) | AF16: 液压 | AG16: Hydraulic | AH16: 劳旅 | AI16: 蓄力、极高单发伤害。利用液压系统进行超强力的蓄力攻击，机动性差但威力惊人。 | AJ16: =IF(COUNTIF('义体&义体技能'!Z:Z,AF16)=0,"",COUNTIF('义体&义体技能'!Z:Z,AF16)) | AQ16: 位移 | AR16: =COUNTIF('义体&义体技能'!AE:AE,AQ16) | AS16: 冲刺、翻滚、穿透
N17: 特殊 | O17: Special | P17: 16 | Q17: =COUNTIF('武器'!H:H,N17)/6 | R17: =COUNTIF('武器技能'!E:E,N17) | AF17: 小巷手艺 | AG17: Traceless | AH17: 新浦会 | AI17: 潜行、高机动、消音。不仅提供隐身能力，还能在移动中规避伤害，适合刺客流。 | AJ17: =IF(COUNTIF('义体&义体技能'!Z:Z,AF17)=0,"",COUNTIF('义体&义体技能'!Z:Z,AF17)) | AQ17: 经济 | AR17: =COUNTIF('义体&义体技能'!AE:AE,AQ17) | AS17: 折扣、资源获取优化
AF18: 踏雪无痕 | AG18: Alleycraft | AH18: 新浦会 | AI18: 处决、背刺、流血。 | AJ18: =IF(COUNTIF('义体&义体技能'!Z:Z,AF18)=0,"",COUNTIF('义体&义体技能'!Z:Z,AF18)) | AQ18: 攻速 | AR18: =COUNTIF('义体&义体技能'!AE:AE,AQ18) | AS18: 攻击速度相关
AF19: 龙头 | AG19: Dragon Head | AH19: 新浦会 | AI19: 周围的敌人攻击力降低、受到的伤害增加。适合喜欢冲入敌群站桩输出的近战Build。 | AJ19: =IF(COUNTIF('义体&义体技能'!Z:Z,AF19)=0,"",COUNTIF('义体&义体技能'!Z:Z,AF19)) | AQ19: 切换 | AR19: =COUNTIF('义体&义体技能'!AE:AE,AQ19) | AS19: 武器切换相关
AF20: 夜宴 | AG20: Banquet | AH20: 新浦会 | AI20: 恢复、增益、投掷。通过特殊的“食物”或药物提供临时Buff，或投掷燃烧瓶/毒酒。 | AJ20: =IF(COUNTIF('义体&义体技能'!Z:Z,AF20)=0,"",COUNTIF('义体&义体技能'!Z:Z,AF20))
AF21: 清道夫 | AG21: Cleaner | AH21: 新浦会 | AI21: 尸体利用、战后处理。击杀敌人后获得额外收益，或利用尸体制造陷阱/障碍。 | AJ21: =IF(COUNTIF('义体&义体技能'!Z:Z,AF21)=0,"",COUNTIF('义体&义体技能'!Z:Z,AF21))
AF22: 私人武装 | AG22: PMC Issue | AH22: 洛克海德 | AI22: 连续命中同一敌人时，伤害逐次提升（可叠加层数）。一旦未命中则层数清零。鼓励高精准度的持续输出。 | AJ22: =IF(COUNTIF('义体&义体技能'!Z:Z,AF22)=0,"",COUNTIF('义体&义体技能'!Z:Z,AF22))
AF23: 风暴 | AG23: Huracan | AH23: 洛克海德 | AI23: 自动“标记”血量最高的敌人，对标记目标造成的伤害提升或者尝试造成额外伤害判定。专攻精英怪和BOSS。 | AJ23: =IF(COUNTIF('义体&义体技能'!Z:Z,AF23)=0,"",COUNTIF('义体&义体技能'!Z:Z,AF23))
AF24: 先锋 | AG24: Vanguard | AH24: 洛克海德 | AI24: 向着敌人移动或冲刺时，受到的伤害大幅降低。冲刺结束时会对面前敌人造成击退。适合近战突脸。 | AJ24: =IF(COUNTIF('义体&义体技能'!Z:Z,AF24)=0,"",COUNTIF('义体&义体技能'!Z:Z,AF24))
AF25: 重装 | AG25: Heavy Duty | AH25: 洛克海德 | AI25: 原地站立不动时，攻速和射速随时间提升。移动会重置加成。适合“炮台流”玩法。 | AJ25: =IF(COUNTIF('义体&义体技能'!Z:Z,AF25)=0,"",COUNTIF('义体&义体技能'!Z:Z,AF25))
AF26: 维和 | AG26: Peacekeeper | AH26: 洛克海德 | AI26: 生命值低时，自动触发回血或无敌效果（有冷却）。减少异常状态的持续时间。万金油生存系列。 | AJ26: =IF(COUNTIF('义体&义体技能'!Z:Z,AF26)=0,"",COUNTIF('义体&义体技能'!Z:Z,AF26))
AF27: 链接者 | AG27: Linker | AH27: 寰宇 | AI27: 伤害传递、群体株连。通过在敌人间建立数据链接，让单体攻击变为群体毁灭。 | AJ27: =IF(COUNTIF('义体&义体技能'!Z:Z,AF27)=0,"",COUNTIF('义体&义体技能'!Z:Z,AF27))
AF28: 防火墙 | AG28: Faraday Cage | AH28: 寰宇 | AI28: 提供一层可再生的“能量护盾”（独立于血量）。护盾存在时，受击会向周围释放冲击波反弹伤害。适合“护盾流”或容错率较高的Build。 | AJ28: =IF(COUNTIF('义体&义体技能'!Z:Z,AF28)=0,"",COUNTIF('义体&义体技能'!Z:Z,AF28))
AF29: 超频 | AG29: Overclock | AH29: 寰宇 | AI29: 大幅缩减技能（行为芯片/智脑）的冷却时间，但每次使用技能都会扣除自身微量生命值或增加受到的伤害。适合“技能狂轰滥炸”流派。 | AJ29: =IF(COUNTIF('义体&义体技能'!Z:Z,AF29)=0,"",COUNTIF('义体&义体技能'!Z:Z,AF29))
AF30: 法拉第笼 | AG30: Counter-Net | AH30: 寰宇 | AI30: 干扰、削弱、视觉剥夺。使敌人致盲、命中率下降或瘫痪其特殊能力。 | AJ30: =IF(COUNTIF('义体&义体技能'!Z:Z,AF30)=0,"",COUNTIF('义体&义体技能'!Z:Z,AF30))
AF31: 临时任务 | AG31: Zero-Day | AH31: 寰宇 | AI31: 爆发、一次性、高风险。基于漏洞利用的高伤装备，往往伴随着过热或自身负面效果。 | AJ31: =IF(COUNTIF('义体&义体技能'!Z:Z,AF31)=0,"",COUNTIF('义体&义体技能'!Z:Z,AF31))
... AF51: 反应堆 | AG51: Reactor | AH51: 东海工业 | AI51: 辐射、能量光环。背负小型反应堆，持续对周围造成辐射伤害。 | AJ51: =IF(COUNTIF('义体&义体技能'!Z:Z,AF51)=0,"",COUNTIF('义体&义体技能'!Z:Z,AF51))

Sheet 阵营列表
A1: 编号 | B1: 名称 | C1: 性质 | D1: 公司定位 | E1: 装备风格 | F1: 命名风格
A2: 01 | B2: 纪念碑 | C2: 组织 | D2: 即使公司们一拖再拖，20世纪的大部分技术专利都已经入公共知识产权领域。而AI梦时代创造的大部分技术都遵循开源法规，这批科技古董反而成了最值钱的复古科幻纪念品。一直以来，大量非盈利团体致力于保证这些专利产品的持续开放性。 2032年，几个重要团体共同建立了纪念碑基金会，全权托管于管理ASI「M.O.N.U.M.」，意图创造没有偏见的公共知识产权管理组织。 数年后，「M.O.N.U.M.」被发现自上线之初，便无差别的窃取所有可访问的知识产权，并将其公开发布到互联网，但由于纪念碑组织的特殊性，该基金会既没有被关停，也没有任何人被问责，只是法律上被定义为非法。 即使步入了数据隔离时代，「M.O.N.U.M.」则依旧在旧互联网活跃。 | E2: 纪念碑的武器大多为现实世界已有、已经构思的武器，或者基于其微调、整合的版本。 | F2: 大多围绕欧美传说出发，也契合纪念碑本身来自欧美非盈利组织的根源性？
A3: 02 | B3: 野望 | C3: 组织 | D3: 活跃于全球的分布式地下组织，被大部分政府和公司定义为恐怖组织，但从未有人或团体以野望的名义对任何活动或袭击负责。 通过独特的交易与金融体系，野望为任何人提供任何其想要的产品和装备，无论是否受到专利保护、是否在该地区合法、是否对使用者本身有危险。 野望没有一个明确的动机，似乎只是一群人借用一个名号行事，也因此几乎无法被打击清除，事实上，大部分特许政府和中立公司都与野望有过不同形式的合作。 野望的产品标识最早出现的时间已不可考，应远早于「数据隔离」时代。 | E3: 野望的武器大多数为非常野路子的组合，特色看点/描述在于组合思路而非武器本身。 | F3: 围绕各种流行网络梗、黑客概念命名。
A4: 03 | B4: 劳旅 | C4: 组织 | D4: “不夜城”最大的劳动力外包团体，提供所有你能想到的工业、建筑、体力、流水线人力外包服务，之所以从未以公司自称，据说是为了规避各种企业法和税款。 由于其不是公司，因此其雇员也不受任何公司或政府的劳动法保护，但即便如此，在自动化机械大行其道的今天，一份劳旅的工作邀约已经是不夜城底层居民能找到的最为体面的工作之一。 劳旅自消泡事件后成立，大规模去AI运动，给带来前所未有的基础生产力缺口，动荡的环境也给了它成长的机会。 | E4: 劳旅的武器大多为工业器械而非武器，但有着不错的战斗表现。 | F4: 围绕装备本身的趣闻触发，有丰富的街头戏谑质感。
A5: 04 | B5: 新浦会 | C5: 组织 | D5: “不夜城”核心城区的最主要黑帮组织，为中立公司、特许政府提供各类服务，包括但不限于地区管控、强制征收、黑色军事行动等。 「新浦会」的历史源远流长。「AI梦」时代，所有非法暴力团体都受到大数据监控，导致影响力受限，但「新浦会」凭借其扎实的地方影响力和相对稳定的合法生意存活了下来。 自「消泡」事件后，它快速重新占据特许政府和中立公司无法触及的社区角落，提供餐饮、外送以及其他一系列个人服务，成为城市“毛细血管”的真正领导者，但内部也随着快速膨胀开始动荡。 “师傅” - 家钰（Yacco）成年后，以雷厉之势肃清了内部异己，前所未有团结的「新浦会」很快成为了不夜城核心城区毫无争议的地下之王。 | E5: 新浦会大多数武器有着隐蔽的外形和解构，便于在各类潜入任务中藏匿武器，作为不夜城最大的餐饮联盟，它们能藏的地方很多。 | F5: 围绕中国传统、尤其是春秋时期、山海经等老故事取材命名。
A6: 05 | B6: 洛克海德 | C6: 中立公司 | D6: 来自北美洲的老牌军工复合体，其自研的「S.T.O.R.M.」系统是世界上最早出现、也可能是最优秀的战术战略指挥ASI。 在过去的几十年时间里，通过结合自身的战斗装备硬件与AI战术部署服务，一直在军备领域占据绝对主导地位，即使是进入数据隔离时代，其武器订单依旧处于行业领先地位。 企业战争开始的前10年，洛克海德将总部迁至不夜城，并最终打响了企业战争的第一枪。 | E6: 典型的新美国风格制式装备，恰到好处的精密和可靠性，一切都为了高性价比的完成任务设计。 | F6: 风格类似典型的美制式武器命名。
A7: 06 | B7: 寰宇 | C7: 中立公司 | D7: 来自北欧、专注于信息技术和网络安全的公司，最初推出了SDN技术。 在企业战争中，寰宇通过提供先进的网络战技术和数据服务，借此机会在不夜城（Noctropolis）开展了自己的业务。 | E7: 专注于高水平的数字战，武器显得科幻、大多数附带各种网络攻击手段。 | F7: 围绕新浪潮和赛博朋克科幻小说的内容、梗、标题命名。
A8: 07 | B8: 东海工业 | C8: 中立公司 | D8: 东亚地区的工业巨头，引领了21世纪下半叶一系列工业、尤其是重工业与建筑工业的技术进步，最早在不夜城实现了的纤维大厦商业化建设。 作为不夜城（Noctropolis）本地发展起来的中立公司，有着难以撼动的民间支持率。 | E8: 扎实的装备、可靠、务实、质朴，而技术本身具备相当的领先性和实用性，尤其是在防御装备方面。 | F8: 围绕中国近代历史故事和地理特色命名。
A9: 08 | B9: 耶利哥 | C9: 中立公司 | D9: 成立于中亚地区的中立公司，在湿件控制领域有着领先的技术，与律动智能（Rhythm Intelligence）有着频繁的业务冲突。 消泡事件期间，耶利哥是首先公开销毁所有ASI的集团。 | E9: 在湿件研发领域有着相当的技术领先性，也是少数具有纳米武器量产经验的公司。 | F9: 围绕中亚、伊斯兰世界的传说和经典故事出发命名。
A10: 09 | B10: 律动智能 | C10: 中立公司 | D10: 发源自东南亚的机器人与人工智能企业。即使在ASI被宣布违法后，依旧致力于传统AI技术的开发。 该公司现在提供了大部分纤维城的无人浮空车控制系统，也在全球交通运输市场占有最高份额。 | E10: 大量围绕自动化（自动瞄准、追踪）技术的武器被装备给该公司的员工。 | F10: 围绕中、日、韩的传说和小说、经典故事出发。本来赛博朋克故事里亚洲才是世界的中心。
A11: 10 | B11: 致远生物 | C11: 中立公司 | D11: 来自于西欧的生物科技公司，在融合打印技术上的积累无人能敌。 似乎在基因改造技术上也颇有建树，但受制于社会伦理，并没有太多公开成果。 该公司提供了市场上超过40%份额的药物品类。 | E11: 有相当多提供肉体强化的义体，让员工可以以“超人”的强度作战，充分发挥其基因科研优势。 | F11: 围绕欧洲神话、经典故事命名。

Sheet 武器
B1: Name | D1: UUID | E1: Faction | F1: Quality | N1: DamageRange | W1: MinSpreadAngle | X1: MaxSpreadAngle | Y1: SpreadDelta | Z1: SpreadReduce | AA1: SpreadReduceInterval | AB1: MoveSpreadIncrease | AC1: MoveSpreadMultiply | AG1: SpreadRange | AJ1: Strength | AK1: Reflex | AL1: Intelligence | BB1: AdjustFactor | BH1: PoiseDamage | BL1: A.A. | BQ1: AmmoC | BR1: AmmoValue | BS1: InitialActionCnt | BT1: CheckPerAttack | BW1: StaminaCost | CA1: BaseDamage | CB1: AdjustDamage | CC1: PreCorrectDamage | CJ1: WeaponFactorCal | CK1: WeaponFactor | CN1: PostCorrectDamage | CP1: DPA | CQ1: DPS | CV1: APS | DC1: 开发 | DD1: 配置
A2: 资产名称 | B2: 中文名称 | C2: 英文名称 | D2: UUID | E2: 阵营 | F2: 品质 | G2: 攻击类型 | H2: 武器类型 | I2: 伤害类型 | J2: 攻击模式 | K2: 伤害类型 | M2: 移速 | N2: 伤害半径 | O2: 伤害角度 | P2: 前摇 | Q2: 伤害 | R2: 后摇 | S2: 间隔 | T2: 攻击时长 | U2: 卡肉时长 | W2: 最小散布 | X2: 最大散布 | Y2: 扩张速度 | Z2: 回馈速度 | AA2: 散布回复间隔 | AB2: 移动散布增长 | AC2: 移动散布倍率 | AD2: 移动最小散布 | AE2: 移动最大散布 | AG2: 攻击声音范围 | AH2: 击中声音范围 | AJ2: 力量补正 | AK2: 反应补正 | AL2: 智力补正 | AM2: 力量等级 | AN2: 反应等级 | AO2: 智力等级 | AP2: 力量假设 | AQ2: 反应假设 | AR2: 智力假设 | AS2: 代谢补正 | AT2: 适应补正 | AU2: 耐力补正 | AV2: 单项上限 | AW2: 最大单项 | AX2: 专精率 | AY2: 总和上限 | AZ2: 补正总和 | BA2: 利用率 | BB2: 补正系数 | BD2: 冲击等级 | BE2: 冲击类型 | BF2: 韧性伤害水平 | BG2: 参考韧性伤害 | BH2: 韧性伤害 | BJ2: 异常积蓄水平 | BK2: 参考异常积蓄 | BL2: 异常积蓄 | BN2: 装弹量 | BO2: 装弹间隔 | BP2: 参考子弹消耗 | BQ2: 子弹消耗 | BR2: 子弹价值 | BS2: 发射弹丸 | BT2: 每动判定 | BV2: 期望体力消耗 | BW2: 体力消耗 | BX2: 体力价值 | BY2: 体力消耗/s | CA2: 基础伤害 | CB2: 补正伤害 | CC2: 矫正前伤害 | CD2: 伤害系数 | CE2: 射程系数 | CF2: 命中系数 | CG2: 冲击系数 | CH2: 异常系数 | CI2: 霰弹系数 | CJ2: 期望系数 | CK2: 武器系数 | CL2: 标准系数 | CM2: 系数价值 | CN2: 矫正后伤害 | CP2: 每动伤害 | CQ2: 每秒伤害 | CR2: ATK | CS2: TTK | CT2: 增额 | CU2: 增幅 | CV2: 每秒异常 | CW2: TTA | CY2: 描述 | DA2: 武器技能 | DC2: =COUNTIF(DC3:DC996,"完成") | DD2: =COUNTIF(DD3:DD996,"完成")
A3: DSRevolver | B3: DS左轮 | D3: =IF($A3="","","WPN"&VLOOKUP(E3,'引用数据库'!Z:AC,4,FALSE)&VLOOKUP(H3,'引用数据库'!N:P,3,FALSE)&VLOOKUP(I3,'引用数据库'!S:U,3,FALSE)&TEXT(F3,"00")) | E3: 纪念碑 | F3: 0 | G3: 远程 | H3: 手枪 | I3: 动能 | J3: 手动 | K3: 1 | M3: 1 | N3: =BO3 | O3: N/A | P3: 0 | Q3: 0 | R3: 0.35 | S3: 0 | T3: =SUM(P3:S3) | U3: =2*T3/(15*(1+(5-BD3)*0.1)) | W3: 0 | X3: 20 | Y3: 0.075 | Z3: 0.15 | AA3: 0.5 | AB3: 5 | AC3: 1.5 | AD3: =(W3+AB3)*AC3 | AE3: =(X3+AB3)*AC3 | AJ3: 0.3 | AK3: 0.763 | AL3: 0 | AM3: =IFS(AJ3 > 1.25, "S", AJ3 > 1, "A", AJ3 > 0.75, "B", AJ3 > 0.5, "C", AJ3 > 0.25, "D", AJ3 > 0, "E", TRUE, "-") | AN3: =IFS(AK3 > 1.25, "S", AK3 > 1, "A", AK3 > 0.75, "B", AK3 > 0.5, "C", AK3 > 0.25, "D", AK3 > 0, "E", TRUE, "-") | AO3: =IFS(AL3 > 1.25, "S", AL3 > 1, "A", AL3 > 0.75, "B", AL3 > 0.5, "C", AL3 > 0.25, "D", AL3 > 0, "E", TRUE, "-") | AP3: 10 | AQ3: 10 | AR3: 10 | AV3: =IF(SUM(AJ3:AL3)=0, 0, (1 + F3 * 0.1) * (0.75 + 0.25 * MAX(0, MIN(1, IF(MAX(AJ3:AL3)=0, 0, (3*MAX(AJ3:AL3)-SUM(AJ3:AL3)) / (2*MAX(AJ3:AL3))))))) | AW3: =MAX(AJ3:AL3) | AX3: =IF(AW3=0, "", AW3 / ((1 + 0.1*N(F3)))) | AY3: =IF(SUM(AJ3:AL3)=0, 0, (1 + F3 * 0.1) * (1 + ((SUM(AJ3:AL3) - MAX(AJ3:AL3)) / (2 * MAX(AJ3:AL3))) * (1/0.75 - 1))) | AZ3: =AJ3+AK3+AL3 | BA3: =IF(AZ3=0, "", AZ3 / ((1 + 0.1*N(F3))/0.75)) | BB3: 0.1 | BD3: 10 | BE3: 7 | BF3: 3 | BG3: =T3*20*(16 * BF3) / (15 + 20 * BF3 - 3 * POWER(BF3, 2))/BT3/BS3 | BH3: =BG3 | BJ3: 3 | BK3: =T3*33*(16 * BJ3) / (15 + 20 * BJ3 - 3 * POWER(BJ3, 2))/BT3/BS3 | BL3: =BK3 | BN3: 6 | BO3: 3 | BP3: =ROUND(CP3/10,2) | BQ3: 1 | BR3: =IFERROR(BQ3*100/CP3,"N/A") | BS3: 1 | BT3: 1 | BV3: =CP3/1.5 | BW3: =ROUND(BV3) | BX3: =CP3/BW3 | BY3: =BW3/T3 | CA3: 10 | CB3: =CA3*BB3*(AP3*AJ3+AQ3*AK3+AR3*AL3) | CC3: =CA3+CB3 | CD3: =T3 * 2 / BS3 / BT3 * (0.9 + 0.2 * IF(G3="近战", EXP(-64 * (T3 - 0.75)^2), EXP(-400 * (T3 - 0.15)^2))) | CE3: =0.9 + 0.2 / (1 + (N3/600)^1) | CF3: =LET( k, K9, be, BS9, bf, BT9, m, N9, n, O9, v, X9, vEff, IF(ISNUMBER(v), v, 0), angle, IF( ISNUMBER(n), IF(n>0, n, IF(ISNUMBER(v), IF(v>0, v, 0), 0 ) ), IF(ISNUMBER(v), IF(v>0, v, 0), 0 ) ), T, IF(k=1, be * bf * 20 / MAX(vEff, 1), IF(k=2, (m/150)^2 * (angle/120), IF(k=3, be * (MIN(bf, 99)/99) * (m/1000), be * bf * (m/1000) * (n/200)^2 ))), b, 0.8, c, 1.2, r, (c-1)/(1-b), k_s, 1, b + (c-b) / (1 + r * EXP(-k_s*(1-T)))) | CG3: =IF(T3<=0,1, (0.9 + 0.2 / (1 + EXP(-0.8 * (5 - BD3)))) * (0.9 + 0.2 / (1 + EXP(-1 * (3.5 - BE3)))) * (0.9 + 0.2 / (1 + EXP(-0.6 * (20 - BS3*BH3/T3))))) | CH3: =IF(T3<=0, 1, 0.9 + 0.2 / (1 + EXP(0.1 * (BL3*BS3*BT3/T3 - 33)))) | CI3: =LET( x_val, W3, bq_val, BS3, Check_Fail, OR(NOT(ISNUMBER(x_val)), bq_val <= 1), IF(Check_Fail, 1, LET( Ratio, x_val / bq_val, calc_A, 2.2 / (1 + EXP(-0.276 * (Ratio - 0.66))), calc_B, 2.2 / (1 + EXP(-0.0138 * (x_val - 13.2))), calc_A + calc_B ) )) | CJ3: =CD3*CE3*CF3*CG3*CH3*CI3 | CK3: =CJ3 | CL3: =T3 * 2 / BS3 / BT3 | CM3: =CK3/CL3 | CN3: =CK3*CC3 | CP3: =CN3*BS3*BT3 | CQ3: =CP3/T3 | CR3: =100/CP3 | CS3: =100/CQ3 | CV3: =BL3/T3 | CW3: =100/CV3 | CY3: 黑市中最常见的左轮手枪。 设计精巧，操控简单，一般人也能迅速上手。 设计蓝图在数据隔离时代之前就已经流入黑市。 几经迭代后，在各路雇佣兵手里活跃至今天。 | DA3: =TEXTJOIN("、", TRUE, FILTER('武器技能'!B:B, '武器技能'!E:E = H3)) | DC3: 完成 | DD3: 完成
A4: DSRevolver | B4: DS左轮 | D4: =IF($A4="","","WPN"&VLOOKUP(E4,'引用数据库'!Z:AC,4,FALSE)&VLOOKUP(H4,'引用数据库'!N:P,3,FALSE)&VLOOKUP(I4,'引用数据库'!S:U,3,FALSE)&TEXT(F4,"00")) | E4: 纪念碑 | F4: 1 | G4: 远程 | H4: 手枪 | I4: 动能 | J4: 手动 | K4: =K3 | M4: =M3 | N4: =N3 | O4: N/A | P4: 0 | Q4: 0 | R4: 0.35 | S4: 0 | T4: =SUM(P4:S4) | U4: =2*T4/(15*(1+(5-BD4)*0.1)) | W4: =W3 | X4: =X3 | Y4: =Y3 | Z4: =Z3 | AA4: =AA3 | AB4: =AB3 | AC4: =AC3 | AD4: =AD3 | AE4: =AE3 | AJ4: =AJ3+0.05 | AK4: 0.83 | AL4: 0 | AM4: =IFS(AJ4 > 1.25, "S", AJ4 > 1, "A", AJ4 > 0.75, "B", AJ4 > 0.5, "C", AJ4 > 0.25, "D", AJ4 > 0, "E", TRUE, "-") | AN4: =IFS(AK4 > 1.25, "S", AK4 > 1, "A", AK4 > 0.75, "B", AK4 > 0.5, "C", AK4 > 0.25, "D", AK4 > 0, "E", TRUE, "-") | AO4: =IFS(AL4 > 1.25, "S", AL4 > 1, "A", AL4 > 0.75, "B", AL4 > 0.5, "C", AL4 > 0.25, "D", AL4 > 0, "E", TRUE, "-") | AP4: 10 | AQ4: 10 | AR4: 10 | AV4: =IF(SUM(AJ4:AL4)=0, 0, (1 + F4 * 0.1) * (0.75 + 0.25 * MAX(0, MIN(1, IF(MAX(AJ4:AL4)=0, 0, (3*MAX(AJ4:AL4)-SUM(AJ4:AL4)) / (2*MAX(AJ4:AL4))))))) | AW4: =MAX(AJ4:AL4) | AX4: =IF(AW4=0, "", AW4 / ((1 + 0.1*N(F4)))) | AY4: =IF(SUM(AJ4:AL4)=0, 0, (1 + F4 * 0.1) * (1 + ((SUM(AJ4:AL4) - MAX(AJ4:AL4)) / (2 * MAX(AJ4:AL4))) * (1/0.75 - 1))) | AZ4: =AJ4+AK4+AL4 | BA4: =IF(AZ4=0, "", AZ4 / ((1 + 0.1*N(F4))/0.75)) | BB4: 0.1 | BD4: =BD3 | BE4: =BE3 | BH4: =BH3 | BL4: =BL3 | BN4: =BN3 | BO4: =BO3 | BQ4: =BQ3 | BR4: =IFERROR(BQ4*100/CP4,"N/A") | BS4: 1 | BT4: =BT3 | BW4: =BW3 | BX4: =CP4/BW4 | BY4: =BW4/T4 | CA4: =CA3+20 | CB4: =CA4*BB4*(AP4*AJ4+AQ4*AK4+AR4*AL4) | CC4: =CA4+CB4 | CK4: =CK3 | CN4: =CK4*CC4 | CP4: =CN4*BS4*BT4 | CQ4: =CP4/T4 | CR4: =100/CP4 | CS4: =100/CQ4 | CT4: =CQ4-CQ3 | CU4: =(CQ4-CQ3)/CQ3 | CV4: =BL4/T4 | CW4: =100/CV4 | DC4: 完成 | DD4: 完成
A5: DSRevolver | B5: DS左轮 | D5: =IF($A5="","","WPN"&VLOOKUP(E5,'引用数据库'!Z:AC,4,FALSE)&VLOOKUP(H5,'引用数据库'!N:P,3,FALSE)&VLOOKUP(I5,'引用数据库'!S:U,3,FALSE)&TEXT(F5,"00")) | E5: 纪念碑 | F5: 2 | G5: 远程 | H5: 手枪 | I5: 动能 | J5: 手动 | K5: =K4 | M5: =M4 | N5: =N4 | O5: N/A | P5: 0 | Q5: 0 | R5: 0.35 | S5: 0 | T5: =SUM(P5:S5) | U5: =2*T5/(15*(1+(5-BD5)*0.1)) | W5: =W4 | X5: =X4 | Y5: =Y4 | Z5: =Z4 | AA5: =AA4 | AB5: =AB4 | AC5: =AC4 | AD5: =AD4 | AE5: =AE4 | AJ5: =AJ4+0.05 | AK5: 0.89 | AL5: 0 | AM5: =IFS(AJ5 > 1.25, "S", AJ5 > 1, "A", AJ5 > 0.75, "B", AJ5 > 0.5, "C", AJ5 > 0.25, "D", AJ5 > 0, "E", TRUE, "-") | AN5: =IFS(AK5 > 1.25, "S", AK5 > 1, "A", AK5 > 0.75, "B", AK5 > 0.5, "C", AK5 > 0.25, "D", AK5 > 0, "E", TRUE, "-") | AO5: =IFS(AL5 > 1.25, "S", AL5 > 1, "A", AL5 > 0.75, "B", AL5 > 0.5, "C", AL5 > 0.25, "D", AL5 > 0, "E", TRUE, "-") | AP5: 10 | AQ5: 10 | AR5: 10 | AV5: =IF(SUM(AJ5:AL5)=0, 0, (1 + F5 * 0.1) * (0.75 + 0.25 * MAX(0, MIN(1, IF(MAX(AJ5:AL5)=0, 0, (3*MAX(AJ5:AL5)-SUM(AJ5:AL5)) / (2*MAX(AJ5:AL5))))))) | AW5: =MAX(AJ5:AL5) | AX5: =IF(AW5=0, "", AW5 / ((1 + 0.1*N(F5)))) | AY5: =IF(SUM(AJ5:AL5)=0, 0, (1 + F5 * 0.1) * (1 + ((SUM(AJ5:AL5) - MAX(AJ5:AL5)) / (2 * MAX(AJ5:AL5))) * (1/0.75 - 1))) | AZ5: =AJ5+AK5+AL5 | BA5: =IF(AZ5=0, "", AZ5 / ((1 + 0.1*N(F5))/0.75)) | BB5: 0.1 | BD5: =BD4 | BE5: =BE4 | BH5: =BH4 | BL5: =BL4 | BN5: =BN4 | BO5: =BO4 | BQ5: =BQ4 | BR5: =IFERROR(BQ5*100/CP5,"N/A") | BS5: 1 | BT5: =BT4 | BW5: =BW4 | BX5: =CP5/BW5 | BY5: =BW5/T5 | CA5: =CA4+10 | CB5: =CA5*BB5*(AP5*AJ5+AQ5*AK5+AR5*AL5) | CC5: =CA5+CB5 | CK5: =CK4 | CN5: =CK5*CC5 | CP5: =CN5*BS5*BT5 | CQ5: =CP5/T5 | CR5: =100/CP5 | CS5: =100/CQ5 | CT5: =CQ5-CQ4 | CU5: =(CQ5-CQ4)/CQ4 | CV5: =BL5/T5 | CW5: =100/CV5 | DC5: 完成 | DD5: 完成
A6: DSRevolver | B6: DS左轮 | D6: =IF($A6="","","WPN"&VLOOKUP(E6,'引用数据库'!Z:AC,4,FALSE)&VLOOKUP(H6,'引用数据库'!N:P,3,FALSE)&VLOOKUP(I6,'引用数据库'!S:U,3,FALSE)&TEXT(F6,"00")) | E6: 纪念碑 | F6: 3 | G6: 远程 | H6: 手枪 | I6: 动能 | J6: 手动 | K6: =K5 | M6: =M5 | N6: =N5 | O6: N/A | P6: 0 | Q6: 0 | R6: 0.35 | S6: 0 | T6: =SUM(P6:S6) | U6: =2*T6/(15*(1+(5-BD6)*0.1)) | W6: =W5 | X6: =X5 | Y6: =Y5 | Z6: =Z5 | AA6: =AA5 | AB6: =AB5 | AC6: =AC5 | AD6: =AD5 | AE6: =AE5 | AJ6: =AJ5+0.05 | AK6: 0.95 | AL6: 0 | AM6: =IFS(AJ6 > 1.25, "S", AJ6 > 1, "A", AJ6 > 0.75, "B", AJ6 > 0.5, "C", AJ6 > 0.25, "D", AJ6 > 0, "E", TRUE, "-") | AN6: =IFS(AK6 > 1.25, "S", AK6 > 1, "A", AK6 > 0.75, "B", AK6 > 0.5, "C", AK6 > 0.25, "D", AK6 > 0, "E", TRUE, "-") | AO6: =IFS(AL6 > 1.25, "S", AL6 > 1, "A", AL6 > 0.75, "B", AL6 > 0.5, "C", AL6 > 0.25, "D", AL6 > 0, "E", TRUE, "-") | AP6: 10 | AQ6: 10 | AR6: 10 | AV6: =IF(SUM(AJ6:AL6)=0, 0, (1 + F6 * 0.1) * (0.75 + 0.25 * MAX(0, MIN(1, IF(MAX(AJ6:AL6)=0, 0, (3*MAX(AJ6:AL6)-SUM(AJ6:AL6)) / (2*MAX(AJ6:AL6))))))) | AW6: =MAX(AJ6:AL6) | AX6: =IF(AW6=0, "", AW6 / ((1 + 0.1*N(F6)))) | AY6: =IF(SUM(AJ6:AL6)=0, 0, (1 + F6 * 0.1) * (1 + ((SUM(AJ6:AL6) - MAX(AJ6:AL6)) / (2 * MAX(AJ6:AL6))) * (1/0.75 - 1))) | AZ6: =AJ6+AK6+AL6 | BA6: =IF(AZ6=0, "", AZ6 / ((1 + 0.1*N(F6))/0.75)) | BB6: 0.1 | BD6: =BD5 | BE6: =BE5 | BH6: =BH5 | BL6: =BL5 | BN6: =BN5 | BO6: =BO5 | BQ6: =BQ5 | BR6: =IFERROR(BQ6*100/CP6,"N/A") | BS6: 1 | BT6: =BT5 | BW6: =BW5 | BX6: =CP6/BW6 | BY6: =BW6/T6 | CA6: =CA5+10 | CB6: =CA6*BB6*(AP6*AJ6+AQ6*AK6+AR6*AL6) | CC6: =CA6+CB6 | CK6: =CK5 | CN6: =CK6*CC6 | CP6: =CN6*BS6*BT6 | CQ6: =CP6/T6 | CR6: =100/CP6 | CS6: =100/CQ6 | CT6: =CQ6-CQ5 | CU6: =(CQ6-CQ5)/CQ5 | CV6: =BL6/T6 | CW6: =100/CV6 | DC6: 完成 | DD6: 完成
A7: DSRevolver | B7: DS左轮 | D7: =IF($A7="","","WPN"&VLOOKUP(E7,'引用数据库'!Z:AC,4,FALSE)&VLOOKUP(H7,'引用数据库'!N:P,3,FALSE)&VLOOKUP(I7,'引用数据库'!S:U,3,FALSE)&TEXT(F7,"00")) | E7: 纪念碑 | F7: 4 | G7: 远程 | H7: 手枪 | I7: 动能 | J7: 手动 | K7: =K6 | M7: =M6 | N7: =N6 | O7: N/A | P7: 0 | Q7: 0 | R7: 0.35 | S7: 0 | T7: =SUM(P7:S7) | U7: =2*T7/(15*(1+(5-BD7)*0.1)) | W7: =W6 | X7: =X6 | Y7: =Y6 | Z7: =Z6 | AA7: =AA6 | AB7: =AB6 | AC7: =AC6 | AD7: =AD6 | AE7: =AE6 | AJ7: =AJ6+0.05 | AK7: 1.02 | AL7: 0 | AM7: =IFS(AJ7 > 1.25, "S", AJ7 > 1, "A", AJ7 > 0.75, "B", AJ7 > 0.5, "C", AJ7 > 0.25, "D", AJ7 > 0, "E", TRUE, "-") | AN7: =IFS(AK7 > 1.25, "S", AK7 > 1, "A", AK7 > 0.75, "B", AK7 > 0.5, "C", AK7 > 0.25, "D", AK7 > 0, "E", TRUE, "-") | AO7: =IFS(AL7 > 1.25, "S", AL7 > 1, "A", AL7 > 0.75, "B", AL7 > 0.5, "C", AL7 > 0.25, "D", AL7 > 0, "E", TRUE, "-") | AP7: 10 | AQ7: 10 | AR7: 10 | AV7: =IF(SUM(AJ7:AL7)=0, 0, (1 + F7 * 0.1) * (0.75 + 0.25 * MAX(0, MIN(1, IF(MAX(AJ7:AL7)=0, 0, (3*MAX(AJ7:AL7)-SUM(AJ7:AL7)) / (2*MAX(AJ7:AL7))))))) | AW7: =MAX(AJ7:AL7) | AX7: =IF(AW7=0, "", AW7 / ((1 + 0.1*N(F7)))) | AY7: =IF(SUM(AJ7:AL7)=0, 0, (1 + F7 * 0.1) * (1 + ((SUM(AJ7:AL7) - MAX(AJ7:AL7)) / (2 * MAX(AJ7:AL7))) * (1/0.75 - 1))) | AZ7: =AJ7+AK7+AL7 | BA7: =IF(AZ7=0, "", AZ7 / ((1 + 0.1*N(F7))/0.75)) | BB7: 0.1 | BD7: =BD6 | BE7: =BE6 | BH7: =BH6 | BL7: =BL6 | BN7: =BN6 | BO7: =BO6 | BQ7: =BQ6 | BR7: =IFERROR(BQ7*100/CP7,"N/A") | BS7: 1 | BT7: =BT6 | BW7: =BW6 | BX7: =CP7/BW7 | BY7: =BW7/T7 | CA7: =CA6+10 | CB7: =CA7*BB7*(AP7*AJ7+AQ7*AK7+AR7*AL7) | CC7: =CA7+CB7 | CK7: =CK6 | CN7: =CK7*CC7 | CP7: =CN7*BS7*BT7 | CQ7: =CP7/T7 | CR7: =100/CP7 | CS7: =100/CQ7 | CT7: =CQ7-CQ6 | CU7: =(CQ7-CQ6)/CQ6 | CV7: =BL7/T7 | CW7: =100/CV7 | DC7: 完成 | DD7: 完成
A8: DSRevolver | B8: DS左轮 | D8: =IF($A8="","","WPN"&VLOOKUP(E8,'引用数据库'!Z:AC,4,FALSE)&VLOOKUP(H8,'引用数据库'!N:P,3,FALSE)&VLOOKUP(I8,'引用数据库'!S:U,3,FALSE)&TEXT(F8,"00")) | E8: 纪念碑 | F8: 5 | G8: 远程 | H8: 手枪 | I8: 动能 | J8: 手动 | K8: =K7 | M8: =M7 | N8: =N7 | O8: N/A | P8: 0 | Q8: 0 | R8: 0.35 | S8: 0 | T8: =SUM(P8:S8) | U8: =2*T8/(15*(1+(5-BD8)*0.1)) | W8: =W7 | X8: =X7 | Y8: =Y7 | Z8: =Z7 | AA8: =AA7 | AB8: =AB7 | AC8: =AC7 | AD8: =AD7 | AE8: =AE7 | AJ8: =AJ7+0.05 | AK8: 1.08 | AL8: 0 | AM8: =IFS(AJ8 > 1.25, "S", AJ8 > 1, "A", AJ8 > 0.75, "B", AJ8 > 0.5, "C", AJ8 > 0.25, "D", AJ8 > 0, "E", TRUE, "-") | AN8: =IFS(AK8 > 1.25, "S", AK8 > 1, "A", AK8 > 0.75, "B", AK8 > 0.5, "C", AK8 > 0.25, "D", AK8 > 0, "E", TRUE, "-") | AO8: =IFS(AL8 > 1.25, "S", AL8 > 1, "A", AL8 > 0.75, "B", AL8 > 0.5, "C", AL8 > 0.25, "D", AL8 > 0, "E", TRUE, "-") | AP8: 10 | AQ8: 10 | AR8: 10 | AV8: =IF(SUM(AJ8:AL8)=0, 0, (1 + F8 * 0.1) * (0.75 + 0.25 * MAX(0, MIN(1, IF(MAX(AJ8:AL8)=0, 0, (3*MAX(AJ8:AL8)-SUM(AJ8:AL8)) / (2*MAX(AJ8:AL8))))))) | AW8: =MAX(AJ8:AL8) | AX8: =IF(AW8=0, "", AW8 / ((1 + 0.1*N(F8)))) | AY8: =IF(SUM(AJ8:AL8)=0, 0, (1 + F8 * 0.1) * (1 + ((SUM(AJ8:AL8) - MAX(AJ8:AL8)) / (2 * MAX(AJ8:AL8))) * (1/0.75 - 1))) | AZ8: =AJ8+AK8+AL8 | BA8: =IF(AZ8=0, "", AZ8 / ((1 + 0.1*N(F8))/0.75)) | BB8: 0.1 | BD8: =BD7 | BE8: =BE7 | BH8: =BH7 | BL8: =BL7 | BN8: =BN7 | BO8: =BO7 | BQ8: =BQ7 | BR8: =IFERROR(BQ8*100/CP8,"N/A") | BS8: 1 | BT8: =BT7 | BW8: =BW7 | BX8: =CP8/BW8 | BY8: =BW8/T8 | CA8: =CA7+10 | CB8: =CA8*BB8*(AP8*AJ8+AQ8*AK8+AR8*AL8) | CC8: =CA8+CB8 | CK8: =CK7 | CN8: =CK8*CC8 | CP8: =CN8*BS8*BT8 | CQ8: =CP8/T8 | CR8: =100/CP8 | CS8: =100/CQ8 | CT8: =CQ8-CQ7 | CU8: =(CQ8-CQ7)/CQ7 | CV8: =BL8/T8 | CW8: =100/CV8 | DC8: 完成 | DD8: 完成
A9: AsFire | B9: 若火 | D9: =IF($A9="","","WPN"&VLOOKUP(E9,'引用数据库'!Z:AC,4,FALSE)&VLOOKUP(H9,'引用数据库'!N:P,3,FALSE)&VLOOKUP(I9,'引用数据库'!S:U,3,FALSE)&TEXT(F9,"00")) | E9: 野望 | F9: 0 | G9: 近战 | H9: 武士刀 | I9: 热能 | J9: 手动 | K9: 2 | M9: 1 | N9: 170 | O9: 120 | P9: 0.367 | Q9: 0.176 | R9: 0.257 | S9: 0 | T9: =SUM(P9:S9) | U9: =2*T9/(15*(1+(5-BD9)*0.1)) | W9: N/A | X9: N/A | Y9: N/A | Z9: N/A | AD9: N/A | AE9: N/A | AJ9: 0.12 | AK9: 0.9 | AL9: 0 | AM9: =IFS(AJ9 > 1.25, "S", AJ9 > 1, "A", AJ9 > 0.75, "B", AJ9 > 0.5, "C", AJ9 > 0.25, "D", AJ9 > 0, "E", TRUE, "-") | AN9: =IFS(AK9 > 1.25, "S", AK9 > 1, "A", AK9 > 0.75, "B", AK9 > 0.5, "C", AK9 > 0.25, "D", AK9 > 0, "E", TRUE, "-") | AO9: =IFS(AL9 > 1.25, "S", AL9 > 1, "A", AL9 > 0.75, "B", AL9 > 0.5, "C", AL9 > 0.25, "D", AL9 > 0, "E", TRUE, "-") | AP9: 10 | AQ9: 10 | AR9: 10 | AV9: =IF(SUM(AJ9:AL9)=0, 0, (1 + F9 * 0.1) * (0.75 + 0.25 * MAX(0, MIN(1, IF(MAX(AJ9:AL9)=0, 0, (3*MAX(AJ9:AL9)-SUM(AJ9:AL9)) / (2*MAX(AJ9:AL9))))))) | AW9: =MAX(AJ9:AL9) | AX9: =IF(AW9=0, "", AW9 / ((1 + 0.1*N(F9)))) | AY9: =IF(SUM(AJ9:AL9)=0, 0, (1 + F9 * 0.1) * (1 + ((SUM(AJ9:AL9) - MAX(AJ9:AL9)) / (2 * MAX(AJ9:AL9))) * (1/0.75 - 1))) | AZ9: =AJ9+AK9+AL9 | BA9: =IF(AZ9=0, "", AZ9 / ((1 + 0.1*N(F9))/0.75)) | BB9: 0.1 | BD9: 3 | BE9: 2 | BF9: 3 | BG9: =T9*20*(16 * BF9) / (15 + 20 * BF9 - 3 * POWER(BF9, 2))/BT9/BS9 | BH9: =BG9 | BJ9: 4 | BK9: =T9*33*(16 * BJ9) / (15 + 20 * BJ9 - 3 * POWER(BJ9, 2))/BT9/BS9 | BL9: =BK9 | BN9: N/A | BO9: N/A | BP9: 0 | BQ9: 0 | BR9: =IFERROR(BQ9*100/CP9,"N/A") | BS9: 1 | BT9: 1 | BV9: =CP9/1.5 | BW9: =ROUND(BV9) | BX9: =CP9/BW9 | BY9: =BW9/T9 | CA9: 10 | CB9: =CA9*BB9*(AP9*AJ9+AQ9*AK9+AR9*AL9) | CC9: =CA9+CB9 | CD9: =T9 * 2 / BS9 / BT9 * (0.9 + 0.2 * IF(G9="近战", EXP(-64 * (T9 - 0.75)^2), EXP(-400 * (T9 - 0.15)^2))) | CE9: =0.9 + 0.2 / (1 + (N9/600)^1) | CF9: =LET( k, K9, be, BS9, bf, BT9, m, N9, n, O9, v, X9, vEff, IF(ISNUMBER(v), v, 0), angle, IF( ISNUMBER(n), IF(n>0, n, IF(ISNUMBER(v), IF(v>0, v, 0), 0 ) ), IF(ISNUMBER(v), IF(v>0, v, 0), 0 ) ), T, IF(k=1, be * bf * 20 / MAX(vEff, 1), IF(k=2, (m/150)^2 * (angle/120), IF(k=3, be * (MIN(bf, 99)/99) * (m/1000), be * bf * (m/1000) * (n/200)^2 ))), b, 0.8, c, 1.2, r, (c-1)/(1-b), k_s, 1, b + (c-b) / (1 + r * EXP(-k_s*(1-T)))) | CG9: =IF(T9<=0,1, (0.9 + 0.2 / (1 + EXP(-0.8 * (5 - BD9)))) * (0.9 + 0.2 / (1 + EXP(-1 * (3.5 - BE9)))) * (0.9 + 0.2 / (1 + EXP(-0.6 * (20 - BS9*BH9/T9))))) | CH9: =IF(T9<=0, 1, 0.9 + 0.2 / (1 + EXP(0.1 * (BL9*BS9*BT9/T9 - 33)))) | CI9: =LET( x_val, W9, bq_val, BS9, Check_Fail, OR(NOT(ISNUMBER(x_val)), bq_val <= 1), IF(Check_Fail, 1, LET( Ratio, x_val / bq_val, calc_A, 2.2 / (1 + EXP(-0.276 * (Ratio - 0.66))), calc_B, 2.2 / (1 + EXP(-0.0138 * (x_val - 13.2))), calc_A + calc_B ) )) | CJ9: =CD9*CE9*CF9*CG9*CH9*CI9 | CK9: =CJ9 | CL9: =T9 * 2 / BS9 / BT9 | CM9: =CK9/CL9 | CN9: =CK9*CC9 | CP9: =CN9*BS9*BT9 | CQ9: =CP9/T9 | CR9: =100/CP9 | CS9: =100/CQ9 | CV9: =BL9/T9 | CW9: =100/CV9 | CY9: 在低阶雇佣兵圈广泛流通的近战武器。 采用热能刀身设计，可以应对多种作战需求。 黑市上流通的多种版本蓝图使其稳定性堪忧， 各大企业均未将其纳入制式装备序列。 | DA9: =TEXTJOIN("、", TRUE, FILTER('武器技能'!B:B, '武器技能'!E:E = H9)) | DC9: 完成 | DD9: 完成
A10: AsFire | B10: 若火 | D10: =IF($A10="","","WPN"&VLOOKUP(E10,'引用数据库'!Z:AC,4,FALSE)&VLOOKUP(H10,'引用数据库'!N:P,3,FALSE)&VLOOKUP(I10,'引用数据库'!S:U,3,FALSE)&TEXT(F10,"00")) | E10: 野望 | F10: 1 | G10: =G9 | H10: 武士刀 | I10: 热能 | J10: 手动 | K10: =K9 | M10: =M9 | N10: 170 | O10: 120 | P10: =P9 | Q10: =Q9 | R10: =R9 | S10: 0 | T10: =SUM(P10:S10) | U10: =2*T10/(15*(1+(5-BD10)*0.1)) | W10: N/A | X10: N/A | Y10: N/A | Z10: N/A | AD10: N/A | AE10: N/A | AJ10: =AJ9 | AK10: 0.92 | AL10: 0.1 | AM10: =IFS(AJ10 > 1.25, "S", AJ10 > 1, "A", AJ10 > 0.75, "B", AJ10 > 0.5, "C", AJ10 > 0.25, "D", AJ10 > 0, "E", TRUE, "-") | AN10: =IFS(AK10 > 1.25, "S", AK10 > 1, "A", AK10 > 0.75, "B", AK10 > 0.5, "C", AK10 > 0.25, "D", AK10 > 0, "E", TRUE, "-") | AO10: =IFS(AL10 > 1.25, "S", AL10 > 1, "A", AL10 > 0.75, "B", AL10 > 0.5, "C", AL10 > 0.25, "D", AL10 > 0, "E", TRUE, "-") | AP10: 10 | AQ10: 10 | AR10: 10 | AV10: =IF(SUM(AJ10:AL10)=0, 0, (1 + F10 * 0.1) * (0.75 + 0.25 * MAX(0, MIN(1, IF(MAX(AJ10:AL10)=0, 0, (3*MAX(AJ10:AL10)-SUM(AJ10:AL10)) / (2*MAX(AJ10:AL10))))))) | AW10: =MAX(AJ10:AL10) | AX10: =IF(AW10=0, "", AW10 / ((1 + 0.1*N(F10)))) | AY10: =IF(SUM(AJ10:AL10)=0, 0, (1 + F10 * 0.1) * (1 + ((SUM(AJ10:AL10) - MAX(AJ10:AL10)) / (2 * MAX(AJ10:AL10))) * (1/0.75 - 1))) | AZ10: =AJ10+AK10+AL10 | BA10: =IF(AZ10=0, "", AZ10 / ((1 + 0.1*N(F10))/0.75)) | BB10: 0.1 | BD10: =BD9 | BE10: =BE9 | BH10: =BH9 | BL10: =BL9 | BN10: N/A | BO10: N/A | BQ10: =BQ9 | BR10: =IFERROR(BQ10*100/CP10,"N/A") | BS10: 1 | BT10: 1 | BW10: =BW9 | BX10: =CP10/BW10 | BY10: =BW10/T10 | CA10: =CA9+20 | CB10: =CA10*BB10*(AP10*AJ10+AQ10*AK10+AR10*AL10) | CC10: =CA10+CB10 | CK10: =CK9 | CN10: =CK10*CC10 | CP10: =CN10*BS10*BT10 | CQ10: =CP10/T10 | CR10: =100/CP10 | CS10: =100/CQ10 | CT10: =CQ10-CQ9 | CU10: =(CQ10-CQ9)/CQ9 | CV10: =BL10/T10 | CW10: =100/CV10 | DC10: 完成 | DD10: 完成
A11: AsFire | B11: 若火 | D11: =IF($A11="","","WPN"&VLOOKUP(E11,'引用数据库'!Z:AC,4,FALSE)&VLOOKUP(H11,'引用数据库'!N:P,3,FALSE)&VLOOKUP(I11,'引用数据库'!S:U,3,FALSE)&TEXT(F11,"00")) | E11: 野望 | F11: 2 | G11: =G10 | H11: 武士刀 | I11: 热能 | J11: 手动 | K11: =K10 | M11: =M10 | N11: 170 | O11: 120 | P11: =P10 | Q11: =Q10 | R11: =R10 | S11: 0 | T11: =SUM(P11:S11) | U11: =2*T11/(15*(1+(5-BD11)*0.1)) | W11: N/A | X11: N/A | Y11: N/A | Z11: N/A | AD11: N/A | AE11: N/A | AJ11: =AJ10 | AK11: =AK10+0.1 | AL11: 0.1 | AM11: =IFS(AJ11 > 1.25, "S", AJ11 > 1, "A", AJ11 > 0.75, "B", AJ11 > 0.5, "C", AJ11 > 0.25, "D", AJ11 > 0, "E", TRUE, "-") | AN11: =IFS(AK11 > 1.25, "S", AK11 > 1, "A", AK11 > 0.75, "B", AK11 > 0.5, "C", AK11 > 0.25, "D", AK11 > 0, "E", TRUE, "-") | AO11: =IFS(AL11 > 1.25, "S", AL11 > 1, "A", AL11 > 0.75, "B", AL11 > 0.5, "C", AL11 > 0.25, "D", AL11 > 0, "E", TRUE, "-") | AP11: 10 | AQ11: 10 | AR11: 10 | AV11: =IF(SUM(AJ11:AL11)=0, 0, (1 + F11 * 0.1) * (0.75 + 0.25 * MAX(0, MIN(1, IF(MAX(AJ11:AL11)=0, 0, (3*MAX(AJ11:AL11)-SUM(AJ11:AL11)) / (2*MAX(AJ11:AL11))))))) | AW11: =MAX(AJ11:AL11) | AX11: =IF(AW11=0, "", AW11 / ((1 + 0.1*N(F11)))) | AY11: =IF(SUM(AJ11:AL11)=0, 0, (1 + F11 * 0.1) * (1 + ((SUM(AJ11:AL11) - MAX(AJ11:AL11)) / (2 * MAX(AJ11:AL11))) * (1/0.75 - 1))) | AZ11: =AJ11+AK11+AL11 | BA11: =IF(AZ11=0, "", AZ11 / ((1 + 0.1*N(F11))/0.75)) | BB11: 0.1 | BD11: =BD10 | BE11: =BE10 | BH11: =BH10 | BL11: =BL10 | BN11: N/A | BO11: N/A | BQ11: =BQ10 | BR11: =IFERROR(BQ11*100/CP11,"N/A") | BS11: 1 | BT11: 1 | BW11: =BW10 | BX11: =CP11/BW11 | BY11: =BW11/T11 | CA11: =CA10+10 | CB11: =CA11*BB11*(AP11*AJ11+AQ11*AK11+AR11*AL11) | CC11: =CA11+CB11 | CK11: =CK10 | CN11: =CK11*CC11 | CP11: =CN11*BS11*BT11 | CQ11: =CP11/T11 | CR11: =100/CP11 | CS11: =100/CQ11 | CT11: =CQ11-CQ10 | CU11: =(CQ11-CQ10)/CQ10 | CV11: =BL11/T11 | CW11: =100/CV11 | DC11: 完成 | DD11: 完成
A12: AsFire | B12: 若火 | D12: =IF($A12="","","WPN"&VLOOKUP(E12,'引用数据库'!Z:AC,4,FALSE)&VLOOKUP(H12,'引用数据库'!N:P,3,FALSE)&VLOOKUP(I12,'引用数据库'!S:U,3,FALSE)&TEXT(F12,"00")) | E12: 野望 | F12: 3 | G12: =G11 | H12: 武士刀 | I12: 热能 | J12: 手动 | K12: =K11 | M12: =M11 | N12: 170 | O12: 120 | P12: =P11 | Q12: =Q11 | R12: =R11 | S12: 0 | T12: =SUM(P12:S12) | U12: =2*T12/(15*(1+(5-BD12)*0.1)) | W12: N/A | X12: N/A | Y12: N/A | Z12: N/A | AD12: N/A | AE12: N/A | AJ12: =AJ11 | AK12: =AK11+0.1 | AL12: 0.1 | AM12: =IFS(AJ12 > 1.25, "S", AJ12 > 1, "A", AJ12 > 0.75, "B", AJ12 > 0.5, "C", AJ12 > 0.25, "D", AJ12 > 0, "E", TRUE, "-") | AN12: =IFS(AK12 > 1.25, "S", AK12 > 1, "A", AK12 > 0.75, "B", AK12 > 0.5, "C", AK12 > 0.25, "D", AK12 > 0, "E", TRUE, "-") | AO12: =IFS(AL12 > 1.25, "S", AL12 > 1, "A", AL12 > 0.75, "B", AL12 > 0.5, "C", AL12 > 0.25, "D", AL12 > 0, "E", TRUE, "-") | AP12: 10 | AQ12: 10 | AR12: 10 | AV12: =IF(SUM(AJ12:AL12)=0, 0, (1 + F12 * 0.1) * (0.75 + 0.25 * MAX(0, MIN(1, IF(MAX(AJ12:AL12)=0, 0, (3*MAX(AJ12:AL12)-SUM(AJ12:AL12)) / (2*MAX(AJ12:AL12))))))) | AW12: =MAX(AJ12:AL12) | AX12: =IF(AW12=0, "", AW12 / ((1 + 0.1*N(F12)))) | AY12: =IF(SUM(AJ12:AL12)=0, 0, (1 + F12 * 0.1) * (1 + ((SUM(AJ12:AL12) - MAX(AJ12:AL12)) / (2 * MAX(AJ12:AL12))) * (1/0.75 - 1))) | AZ12: =AJ12+AK12+AL12 | BA12: =IF(AZ12=0, "", AZ12 / ((1 + 0.1*N(F12))/0.75)) | BB12: 0.1 | BD12: =BD11 | BE12: =BE11 | BH12: =BH11 | BL12: =BL11 | BN12: N/A | BO12: N/A | BQ12: =BQ11 | BR12: =IFERROR(BQ12*100/CP12,"N/A") | BS12: 1 | BT12: 1 | BW12: =BW11 | BX12: =CP12/BW12 | BY12: =BW12/T12 | CA12: =CA11+10 | CB12: =CA12*BB12*(AP12*AJ12+AQ12*AK12+AR12*AL12) | CC12: =CA12+CB12 | CK12: =CK11 | CN12: =CK12*CC12 | CP12: =CN12*BS12*BT12 | CQ12: =CP12/T12 | CR12: =100/CP12 | CS12: =100/CQ12 | CT12: =CQ12-CQ11 | CU12: =(CQ12-CQ11)/CQ11 | CV12: =BL12/T12 | CW12: =100/CV12 | DC12: 完成 | DD12: 完成
A13: AsFire | B13: 若火 | D13: =IF($A13="","","WPN"&VLOOKUP(E13,'引用数据库'!Z:AC,4,FALSE)&VLOOKUP(H13,'引用数据库'!N:P,3,FALSE)&VLOOKUP(I13,'引用数据库'!S:U,3,FALSE)&TEXT(F13,"00")) | E13: 野望 | F13: 4 | G13: =G12 | H13: 武士刀 | I13: 热能 | J13: 手动 | K13: =K12 | M13: =M12 | N13: 170 | O13: 120 | P13: =P12 | Q13: =Q12 | R13: =R12 | S13: 0 | T13: =SUM(P13:S13) | U13: =2*T13/(15*(1+(5-BD13)*0.1)) | W13: N/A | X13: N/A | Y13: N/A | Z13: N/A | AD13: N/A | AE13: N/A | AJ13: =AJ12 | AK13: 1.15 | AL13: 0.2 | AM13: =IFS(AJ13 > 1.25, "S", AJ13 > 1, "A", AJ13 > 0.75, "B", AJ13 > 0.5, "C", AJ13 > 0.25, "D", AJ13 > 0, "E", TRUE, "-") | AN13: =IFS(AK13 > 1.25, "S", AK13 > 1, "A", AK13 > 0.75, "B", AK13 > 0.5, "C", AK13 > 0.25, "D", AK13 > 0, "E", TRUE, "-") | AO13: =IFS(AL13 > 1.25, "S", AL13 > 1, "A", AL13 > 0.75, "B", AL13 > 0.5, "C", AL13 > 0.25, "D", AL13 > 0, "E", TRUE, "-") | AP13: 10 | AQ13: 10 | AR13: 10 | AV13: =IF(SUM(AJ13:AL13)=0, 0, (1 + F13 * 0.1) * (0.75 + 0.25 * MAX(0, MIN(1, IF(MAX(AJ13:AL13)=0, 0, (3*MAX(AJ13:AL13)-SUM(AJ13:AL13)) / (2*MAX(AJ13:AL13))))))) | AW13: =MAX(AJ13:AL13) | AX13: =IF(AW13=0, "", AW13 / ((1 + 0.1*N(F13)))) | AY13: =IF(SUM(AJ13:AL13)=0, 0, (1 + F13 * 0.1) * (1 + ((SUM(AJ13:AL13) - MAX(AJ13:AL13)) / (2 * MAX(AJ13:AL13))) * (1/0.75 - 1))) | AZ13: =AJ13+AK13+AL13 | BA13: =IF(AZ13=0, "", AZ13 / ((1 + 0.1*N(F13))/0.75)) | BB13: 0.1 | BD13: =BD12 | BE13: =BE12 | BH13: =BH12 | BL13: =BL12 | BN13: N/A | BO13: N/A | BQ13: =BQ12 | BR13: =IFERROR(BQ13*100/CP13,"N/A") | BS13: 1 | BT13: 1 | BW13: =BW12 | BX13: =CP13/BW13 | BY13: =BW13/T13 | CA13: =CA12+10 | CB13: =CA13*BB13*(AP13*AJ13+AQ13*AK13+AR13*AL13) | CC13: =CA13+CB13 | CK13: =CK12 | CN13: =CK13*CC13 | CP13: =CN13*BS13*BT13 | CQ13: =CP13/T13 | CR13: =100/CP13 | CS13: =100/CQ13 | CT13: =CQ13-CQ12 | CU13: =(CQ13-CQ12)/CQ12 | CV13: =BL13/T13 | CW13: =100/CV13 | DC13: 完成 | DD13: 完成
A14: AsFire | B14: 若火 | D14: =IF($A14="","","WPN"&VLOOKUP(E14,'引用数据库'!Z:AC,4,FALSE)&VLOOKUP(H14,'引用数据库'!N:P,3,FALSE)&VLOOKUP(I14,'引用数据库'!S:U,3,FALSE)&TEXT(F14,"00")) | E14: 野望 | F14: 5 | G14: =G13 | H14: 武士刀 | I14: 热能 | J14: 手动 | K14: =K13 | M14: =M13 | N14: 170 | O14: 120 | P14: =P13 | Q14: =Q13 | R14: =R13 | S14: 0 | T14: =SUM(P14:S14) | U14: =2*T14/(15*(1+(5-BD14)*0.1)) | W14: N/A | X14: N/A | Y14: N/A | Z14: N/A | AD14: N/A | AE14: N/A | AJ14: 0.2 | AK14: 1.15 | AL14: 0.25 | AM14: =IFS(AJ14 > 1.25, "S", AJ14 > 1, "A", AJ14 > 0.75, "B", AJ14 > 0.5, "C", AJ14 > 0.25, "D", AJ14 > 0, "E", TRUE, "-") | AN14: =IFS(AK14 > 1.25, "S", AK14 > 1, "A", AK14 > 0.75, "B", AK14 > 0.5, "C", AK14 > 0.25, "D", AK14 > 0, "E", TRUE, "-") | AO14: =IFS(AL14 > 1.25, "S", AL14 > 1, "A", AL14 > 0.75, "B", AL14 > 0.5, "C", AL14 > 0.25, "D", AL14 > 0, "E", TRUE, "-") | AP14: 10 | AQ14: 10 | AR14: 10 | AV14: =IF(SUM(AJ14:AL14)=0, 0, (1 + F14 * 0.1) * (0.75 + 0.25 * MAX(0, MIN(1, IF(MAX(AJ14:AL14)=0, 0, (3*MAX(AJ14:AL14)-SUM(AJ14:AL14)) / (2*MAX(AJ14:AL14))))))) | AW14: =MAX(AJ14:AL14) | AX14: =IF(AW14=0, "", AW14 / ((1 + 0.1*N(F14)))) | AY14: =IF(SUM(AJ14:AL14)=0, 0, (1 + F14 * 0.1) * (1 + ((SUM(AJ14:AL14) - MAX(AJ14:AL14)) / (2 * MAX(AJ14:AL14))) * (1/0.75 - 1))) | AZ14: =AJ14+AK14+AL14 | BA14: =IF(AZ14=0, "", AZ14 / ((1 + 0.1*N(F14))/0.75)) | BB14: 0.1 | BD14: =BD13 | BE14: =BE13 | BH14: =BH13 | BL14: =BL13 | BN14: N/A | BO14: N/A | BQ14: =BQ13 | BR14: =IFERROR(BQ14*100/CP14,"N/A") | BS14: 1 | BT14: 1 | BW14: =BW13 | BX14: =CP14/BW14 | BY14: =BW14/T14 | CA14: =CA13+10 | CB14: =CA14*BB14*(AP14*AJ14+AQ14*AK14+AR14*AL14) | CC14: =CA14+CB14 | CK14: =CK13 | CN14: =CK14*CC14 | CP14: =CN14*BS14*BT14 | CQ14: =CP14/T14 | CR14: =100/CP14 | CS14: =100/CQ14 | CT14: =CQ14-CQ13 | CU14: =(CQ14-CQ13)/CQ13 | CV14: =BL14/T14 | CW14: =100/CV14 | DC14: 完成 | DD14: 完成
A15: MagneticWrench | B15: 磁阻扳手 | D15: =IF($A15="","","WPN"&VLOOKUP(E15,'引用数据库'!Z:AC,4,FALSE)&VLOOKUP(H15,'引用数据库'!N:P,3,FALSE)&VLOOKUP(I15,'引用数据库'!S:U,3,FALSE)&TEXT(F15,"00")) | E15: 劳旅 | F15: 0 | G15: 近战 | H15: 锤 | I15: 电磁 | J15: 手动 | K15: 2 | M15: 1 | N15: 140 | O15: 90 | P15: 0.251 | Q15: 0.05 | R15: 0.299 | S15: 0 | T15: =SUM(P15:S15) | U15: =2*T15/(15*(1+(5-BD15)*0.1)) | W15: N/A | X15: N/A | Y15: N/A | Z15: N/A | AD15: N/A | AE15: N/A | AJ15: 0.64 | AK15: 0.3 | AL15: 0.2 | AM15: =IFS(AJ15 > 1.25, "S", AJ15 > 1, "A", AJ15 > 0.75, "B", AJ15 > 0.5, "C", AJ15 > 0.25, "D", AJ15 > 0, "E", TRUE, "-") | AN15: =IFS(AK15 > 1.25, "S", AK15 > 1, "A", AK15 > 0.75, "B", AK15 > 0.5, "C", AK15 > 0.25, "D", AK15 > 0, "E", TRUE, "-") | AO15: =IFS(AL15 > 1.25, "S", AL15 > 1, "A", AL15 > 0.75, "B", AL15 > 0.5, "C", AL15 > 0.25, "D", AL15 > 0, "E", TRUE, "-") | AP15: 10 | AQ15: 10 | AR15: 10 | AV15: =IF(SUM(AJ15:AL15)=0, 0, (1 + F15 * 0.1) * (0.75 + 0.25 * MAX(0, MIN(1, IF(MAX(AJ15:AL15)=0, 0, (3*MAX(AJ15:AL15)-SUM(AJ15:AL15)) / (2*MAX(AJ15:AL15))))))) | AW15: =MAX(AJ15:AL15) | AX15: =IF(AW15=0, "", AW15 / ((1 + 0.1*N(F15)))) | AY15: =IF(SUM(AJ15:AL15)=0, 0, (1 + F15 * 0.1) * (1 + ((SUM(AJ15:AL15) - MAX(AJ15:AL15)) / (2 * MAX(AJ15:AL15))) * (1/0.75 - 1))) | AZ15: =AJ15+AK15+AL15 | BA15: =IF(AZ15=0, "", AZ15 / ((1 + 0.1*N(F15))/0.75)) | BB15: 0.1 | BD15: 2 | BE15: 2 | BF15: 2 | BG15: =T15*20*(16 * BF15) / (15 + 20 * BF15 - 3 * POWER(BF15, 2))/BT15/BS15 | BH15: =BG15 | BJ15: 4 | BK15: =T15*33*(16 * BJ15) / (15 + 20 * BJ15 - 3 * POWER(BJ15, 2))/BT15/BS15 | BL15: =BK15 | BN15: N/A | BO15: N/A | BP15: 0 | BQ15: 0 | BR15: =IFERROR(BQ15*100/CP15,"N/A") | BS15: 1 | BT15: 1 | BV15: =CP15/1.5 | BW15: =ROUND(BV15) | BX15: =CP15/BW15 | BY15: =BW15/T15 | CA15: 10 | CB15: =CA15*BB15*(AP15*AJ15+AQ15*AK15+AR15*AL15) | CC15: =CA15+CB15 | CD15: =T15 * 2 / BS15 / BT15 * (0.9 + 0.2 * IF(G15="近战", EXP(-64 * (T15 - 0.75)^2), EXP(-400 * (T15 - 0.15)^2))) | CE15: =0.9 + 0.2 / (1 + (N15/600)^1) | CF15: =LET( k, K15, be, BS15, bf, BT15, m, N15, n, O15, v, X15, vEff, IF(ISNUMBER(v), v, 0), angle, IF( ISNUMBER(n), IF(n>0, n, IF(ISNUMBER(v), IF(v>0, v, 0), 0 ) ), IF(ISNUMBER(v), IF(v>0, v, 0), 0 ) ), T, IF(k=1, be * bf * 20 / MAX(vEff, 1), IF(k=2, (m/150)^2 * (angle/120), IF(k=3, be * (MIN(bf, 99)/99) * (m/1000), be * bf * (m/1000) * (n/200)^2 ))), b, 0.8, c, 1.2, r, (c-1)/(1-b), k_s, 1, b + (c-b) / (1 + r * EXP(-k_s*(1-T)))) | CG15: =IF(T15<=0,1, (0.9 + 0.2 / (1 + EXP(-0.8 * (5 - BD15)))) * (0.9 + 0.2 / (1 + EXP(-1 * (3.5 - BE15)))) * (0.9 + 0.2 / (1 + EXP(-0.6 * (20 - BS15*BH15/T15))))) | CH15: =IF(T15<=0, 1, 0.9 + 0.2 / (1 + EXP(0.1 * (BL15*BS15*BT15/T15 - 33)))) | CI15: =LET( x_val, X15, bq_val, BS15, Check_Fail, OR(NOT(ISNUMBER(x_val)), bq_val <= 1), IF(Check_Fail, 1, LET( Ratio, x_val / bq_val, calc_A, 2.5 / (1 + EXP(-0.23105 * (Ratio - 3))), calc_B, 2.5 / (1 + EXP(-0.008664 * (x_val - 20))), calc_A + calc_B ) )) | CJ15: =CD15*CE15*CF15*CG15*CH15*CI15 | CK15: =CJ15 | CL15: =T15 * 2 / BS15 / BT15 | CM15: =CK15/CL15 | CN15: =CK15*CC15 | CP15: =CN15*BS15*BT15 | CQ15: =CP15/T15 | CR15: =100/CP15 | CS15: =100/CQ15 | CV15: =BL15/T15 | CW15: =100/CV15 | CY15: 通过磁阻牵引目标，实现非接触安装的电动扳手。 能让一般工人达到接近全自动机械的装配精度， 并且在械斗中也颇为趁手。 | DA15: =TEXTJOIN("、", TRUE, FILTER('武器技能'!B:B, '武器技能'!E:E = H15)) | DC15: 完成 | DD15: 完成
A16: MagneticWrench | B16: 磁阻扳手 | D16: =IF($A16="","","WPN"&VLOOKUP(E16,'引用数据库'!Z:AC,4,FALSE)&VLOOKUP(H16,'引用数据库'!N:P,3,FALSE)&VLOOKUP(I16,'引用数据库'!S:U,3,FALSE)&TEXT(F16,"00")) | E16: 劳旅 | F16: 1 | G16: =G15 | H16: =H15 | I16: =I15 | J16: =J15 | K16: =K15 | M16: =M15 | N16: 140 | O16: =O15 | P16: =P15 | Q16: =Q15 | R16: =R15 | S16: 0 | T16: =SUM(P16:S16) | U16: =2*T16/(15*(1+(5-BD16)*0.1)) | W16: N/A | X16: N/A | Y16: N/A | Z16: N/A | AD16: N/A | AE16: N/A | AJ16: =AJ15+0.1 | AK16: =AK15 | AL16: 0.2 | AM16: =IFS(AJ16 > 1.25, "S", AJ16 > 1, "A", AJ16 > 0.75, "B", AJ16 > 0.5, "C", AJ16 > 0.25, "D", AJ16 > 0, "E", TRUE, "-") | AN16: =IFS(AK16 > 1.25, "S", AK16 > 1, "A", AK16 > 0.75, "B", AK16 > 0.5, "C", AK16 > 0.25, "D", AK16 > 0, "E", TRUE, "-") | AO16: =IFS(AL16 > 1.25, "S", AL16 > 1, "A", AL16 > 0.75, "B", AL16 > 0.5, "C", AL16 > 0.25, "D", AL16 > 0, "E", TRUE, "-") | AP16: 10 | AQ16: 10 | AR16: 10 | AV16: =IF(SUM(AJ16:AL16)=0, 0, (1 + F16 * 0.1) * (0.75 + 0.25 * MAX(0, MIN(1, IF(MAX(AJ16:AL16)=0, 0, (3*MAX(AJ16:AL16)-SUM(AJ16:AL16)) / (2*MAX(AJ16:AL16))))))) | AW16: =MAX(AJ16:AL16) | AX16: =IF(AW16=0, "", AW16 / ((1 + 0.1*N(F16)))) | AY16: =IF(SUM(AJ16:AL16)=0, 0, (1 + F16 * 0.1) * (1 + ((SUM(AJ16:AL16) - MAX(AJ16:AL16)) / (2 * MAX(AJ16:AL16))) * (1/0.75 - 1))) | AZ16: =AJ16+AK16+AL16 | BA16: =IF(AZ16=0, "", AZ16 / ((1 + 0.1*N(F16))/0.75)) | BB16: 0.1 | BD16: =BD15 | BE16: =BE15 | BH16: =BH15 | BL16: =BL15 | BN16: N/A | BO16: N/A | BQ16: =BQ15 | BR16: =IFERROR(BQ16*100/CP16,"N/A") | BS16: 1 | BT16: 1 | BW16: =BW15 | BX16: =CP16/BW16 | BY16: =BW16/T16 | CA16: =CA15+20 | CB16: =CA16*BB16*(AP16*AJ16+AQ16*AK16+AR16*AL16) | CC16: =CA16+CB16 | CK16: =CK15 | CN16: =CK16*CC16 | CP16: =CN16*BS16*BT16 | CQ16: =CP16/T16 | CR16: =100/CP16 | CS16: =100/CQ16 | CT16: =CQ16-CQ15 | CU16: =(CQ16-CQ15)/CQ15 | CV16: =BL16/T16 | CW16: =100/CV16 | DC16: 完成 | DD16: 完成
A17: MagneticWrench | B17: 磁阻扳手 | D17: =IF($A17="","","WPN"&VLOOKUP(E17,'引用数据库'!Z:AC,4,FALSE)&VLOOKUP(H17,'引用数据库'!N:P,3,FALSE)&VLOOKUP(I17,'引用数据库'!S:U,3,FALSE)&TEXT(F17,"00")) | E17: 劳旅 | F17: 2 | G17: =G16 | H17: =H16 | I17: =I16 | J17: =J16 | K17: =K16 | M17: =M16 | N17: 140 | O17: =O16 | P17: =P16 | Q17: =Q16 | R17: =R16 | S17: 0 | T17: =SUM(P17:S17) | U17: =2*T17/(15*(1+(5-BD17)*0.1)) | W17: N/A | X17: N/A | Y17: N/A | Z17: N/A | AD17: N/A | AE17: N/A | AJ17: =AJ16+0.1 | AK17: =AK16 | AL17: =AL16 | AM17: =IFS(AJ17 > 1.25, "S", AJ17 > 1, "A", AJ17 > 0.75, "B", AJ17 > 0.5, "C", AJ17 > 0.25, "D", AJ17 > 0, "E", TRUE, "-") | AN17: =IFS(AK17 > 1.25, "S", AK17 > 1, "A", AK17 > 0.75, "B", AK17 > 0.5, "C", AK17 > 0.25, "D", AK17 > 0, "E", TRUE, "-") | AO17: =IFS(AL17 > 1.25, "S", AL17 > 1, "A", AL17 > 0.75, "B", AL17 > 0.5, "C", AL17 > 0.25, "D", AL17 > 0, "E", TRUE, "-") | AP17: 10 | AQ17: 10 | AR17: 10 | AV17: =IF(SUM(AJ17:AL17)=0, 0, (1 + F17 * 0.1) * (0.75 + 0.25 * MAX(0, MIN(1, IF(MAX(AJ17:AL17)=0, 0, (3*MAX(AJ17:AL17)-SUM(AJ17:AL17)) / (2*MAX(AJ17:AL17))))))) | AW17: =MAX(AJ17:AL17) | AX17: =IF(AW17=0, "", AW17 / ((1 + 0.1*N(F17)))) | AY17: =IF(SUM(AJ17:AL17)=0, 0, (1 + F17 * 0.1) * (1 + ((SUM(AJ17:AL17) - MAX(AJ17:AL17)) / (2 * MAX(AJ17:AL17))) * (1/0.75 - 1))) | AZ17: =AJ17+AK17+AL17 | BA17: =IF(AZ17=0, "", AZ17 / ((1 + 0.1*N(F17))/0.75)) | BB17: 0.1 | BD17: =BD16 | BE17: =BE16 | BH17: =BH16 | BL17: =BL16 | BN17: N/A | BO17: N/A | BQ17: =BQ16 | BR17: =IFERROR(BQ17*100/CP17,"N/A") | BS17: 1 | BT17: 1 | BW17: =BW16 | BX17: =CP17/BW17 | BY17: =BW17/T17 | CA17: =CA16+10 | CB17: =CA17*BB17*(AP17*AJ17+AQ17*AK17+AR17*AL17) | CC17: =CA17+CB17 | CK17: =CK16 | CN17: =CK17*CC17 | CP17: =CN17*BS17*BT17 | CQ17: =CP17/T17 | CR17: =100/CP17 | CS17: =100/CQ17 | CT17: =CQ17-CQ16 | CU17: =(CQ17-CQ16)/CQ16 | CV17: =BL17/T17 | CW17: =100/CV17 | DC17: 完成 | DD17: 完成
A18: MagneticWrench | B18: 磁阻扳手 | D18: =IF($A18="","","WPN"&VLOOKUP(E18,'引用数据库'!Z:AC,4,FALSE)&VLOOKUP(H18,'引用数据库'!N:P,3,FALSE)&VLOOKUP(I18,'引用数据库'!S:U,3,FALSE)&TEXT(F18,"00")) | E18: 劳旅 | F18: 3 | G18: =G17 | H18: =H17 | I18: =I17 | J18: =J17 | K18: =K17 | M18: =M17 | N18: 140 | O18: =O17 | P18: =P17 | Q18: =Q17 | R18: =R17 | S18: 0 | T18: =SUM(P18:S18) | U18: =2*T18/(15*(1+(5-BD18)*0.1)) | W18: N/A | X18: N/A | Y18: N/A | Z18: N/A | AD18: N/A | AE18: N/A | AJ18: =AJ17+0.1 | AK18: =AK17 | AL18: =AL17 | AM18: =IFS(AJ18 > 1.25, "S", AJ18 > 1, "A", AJ18 > 0.75, "B", AJ18 > 0.5, "C", AJ18 > 0.25, "D", AJ18 > 0, "E", TRUE, "-") | AN18: =IFS(AK18 > 1.25, "S", AK18 > 1, "A", AK18 > 0.75, "B", AK18 > 0.5, "C", AK18 > 0.25, "D", AK18 > 0, "E", TRUE, "-") | AO18: =IFS(AL18 > 1.25, "S", AL18 > 1, "A", AL18 > 0.75, "B", AL18 > 0.5, "C", AL18 > 0.25, "D", AL18 > 0, "E", TRUE, "-") | AP18: 10 | AQ18: 10 | AR18: 10 | AV18: =IF(SUM(AJ18:AL18)=0, 0, (1 + F18 * 0.1) * (0.75 + 0.25 * MAX(0, MIN(1, IF(MAX(AJ18:AL18)=0, 0, (3*MAX(AJ18:AL18)-SUM(AJ18:AL18)) / (2*MAX(AJ18:AL18))))))) | AW18: =MAX(AJ18:AL18) | AX18: =IF(AW18=0, "", AW18 / ((1 + 0.1*N(F18)))) | AY18: =IF(SUM(AJ18:AL18)=0, 0, (1 + F18 * 0.1) * (1 + ((SUM(AJ18:AL18) - MAX(AJ18:AL18)) / (2 * MAX(AJ18:AL18))) * (1/0.75 - 1))) | AZ18: =AJ18+AK18+AL18 | BA18: =IF(AZ18=0, "", AZ18 / ((1 + 0.1*N(F18))/0.75)) | BB18: 0.1 | BD18: =BD17 | BE18: =BE17 | BH18: =BH17 | BL18: =BL17 | BN18: N/A | BO18: N/A | BQ18: =BQ17 | BR18: =IFERROR(BQ18*100/CP18,"N/A") | BS18: 1 | BT18: 1 | BW18: =BW17 | BX18: =CP18/BW18 | BY18: =BW18/T18 | CA18: =CA17+10 | CB18: =CA18*BB18*(AP18*AJ18+AQ18*AK18+AR18*AL18) | CC18: =CA18+CB18 | CK18: =CK17 | CN18: =CK18*CC18 | CP18: =CN18*BS18*BT18 | CQ18: =CP18/T18 | CR18: =100/CP18 | CS18: =100/CQ18 | CT18: =CQ18-CQ17 | CU18: =(CQ18-CQ17)/CQ17 | CV18: =BL18/T18 | CW18: =100/CV18 | DC18: 完成 | DD18: 完成
A19: MagneticWrench | B19: 磁阻扳手 | D19: =IF($A19="","","WPN"&VLOOKUP(E19,'引用数据库'!Z:AC,4,FALSE)&VLOOKUP(H19,'引用数据库'!N:P,3,FALSE)&VLOOKUP(I19,'引用数据库'!S:U,3,FALSE)&TEXT(F19,"00")) | E19: 劳旅 | F19: 4 | G19: =G18 | H19: =H18 | I19: =I18 | J19: =J18 | K19: =K18 | M19: =M18 | N19: 140 | O19: =O18 | P19: =P18 | Q19: =Q18 | R19: =R18 | S19: 0 | T19: =SUM(P19:S19) | U19: =2*T19/(15*(1+(5-BD19)*0.1)) | W19: N/A | X19: N/A | Y19: N/A | Z19: N/A | AD19: N/A | AE19: N/A | AJ19: =AJ18+0.1 | AK19: =AK18 | AL19: =AL18 | AM19: =IFS(AJ19 > 1.25, "S", AJ19 > 1, "A", AJ19 > 0.75, "B", AJ19 > 0.5, "C", AJ19 > 0.25, "D", AJ19 > 0, "E", TRUE, "-") | AN19: =IFS(AK19 > 1.25, "S", AK19 > 1, "A", AK19 > 0.75, "B", AK19 > 0.5, "C", AK19 > 0.25, "D", AK19 > 0, "E", TRUE, "-") | AO19: =IFS(AL19 > 1.25, "S", AL19 > 1, "A", AL19 > 0.75, "B", AL19 > 0.5, "C", AL19 > 0.25, "D", AL19 > 0, "E", TRUE, "-") | AP19: 10 | AQ19: 10 | AR19: 10 | AV19: =IF(SUM(AJ19:AL19)=0, 0, (1 + F19 * 0.1) * (0.75 + 0.25 * MAX(0, MIN(1, IF(MAX(AJ19:AL19)=0, 0, (3*MAX(AJ19:AL19)-SUM(AJ19:AL19)) / (2*MAX(AJ19:AL19))))))) | AW19: =MAX(AJ19:AL19) | AX19: =IF(AW19=0, "", AW19 / ((1 + 0.1*N(F19)))) | AY19: =IF(SUM(AJ19:AL19)=0, 0, (1 + F19 * 0.1) * (1 + ((SUM(AJ19:AL19) - MAX(AJ19:AL19)) / (2 * MAX(AJ19:AL19))) * (1/0.75 - 1))) | AZ19: =AJ19+AK19+AL19 | BA19: =IF(AZ19=0, "", AZ19 / ((1 + 0.1*N(F19))/0.75)) | BB19: 0.1 | BD19: =BD18 | BE19: =BE18 | BH19: =BH18 | BL19: =BL18 | BN19: N/A | BO19: N/A | BQ19: =BQ18 | BR19: =IFERROR(BQ19*100/CP19,"N/A") | BS19: 1 | BT19: 1 | BW19: =BW18 | BX19: =CP19/BW19 | BY19: =BW19/T19 | CA19: =CA18+10 | CB19: =CA19*BB19*(AP19*AJ19+AQ19*AK19+AR19*AL19) | CC19: =CA19+CB19 | CK19: =CK18 | CN19: =CK19*CC19 | CP19: =CN19*BS19*BT19 | CQ19: =CP19/T19 | CR19: =100/CP19 | CS19: =100/CQ19 | CT19: =CQ19-CQ18 | CU19: =(CQ19-CQ18)/CQ18 | CV19: =BL19/T19 | CW19: =100/CV19 | DC19: 完成 | DD19: 完成
A20: MagneticWrench | B20: 磁阻扳手 | D20: =IF($A20="","","WPN"&VLOOKUP(E20,'引用数据库'!Z:AC,4,FALSE)&VLOOKUP(H20,'引用数据库'!N:P,3,FALSE)&VLOOKUP(I20,'引用数据库'!S:U,3,FALSE)&TEXT(F20,"00")) | E20: 劳旅 | F20: 5 | G20: =G19 | H20: =H19 | I20: =I19 | J20: =J19 | K20: =K19 | M20: =M19 | N20: 140 | O20: =O19 | P20: =P19 | Q20: =Q19 | R20: =R19 | S20: 0 | T20: =SUM(P20:S20) | U20: =2*T20/(15*(1+(5-BD20)*0.1)) | W20: N/A | X20: N/A | Y20: N/A | Z20: N/A | AD20: N/A | AE20: N/A | AJ20: =AJ19+0.1 | AK20: =AK19 | AL20: =AL19 | AM20: =IFS(AJ20 > 1.25, "S", AJ20 > 1, "A", AJ20 > 0.75, "B", AJ20 > 0.5, "C", AJ20 > 0.25, "D", AJ20 > 0, "E", TRUE, "-") | AN20: =IFS(AK20 > 1.25, "S", AK20 > 1, "A", AK20 > 0.75, "B", AK20 > 0.5, "C", AK20 > 0.25, "D", AK20 > 0, "E", TRUE, "-") | AO20: =IFS(AL20 > 1.25, "S", AL20 > 1, "A", AL20 > 0.75, "B", AL20 > 0.5, "C", AL20 > 0.25, "D", AL20 > 0, "E", TRUE, "-") | AP20: 10 | AQ20: 10 | AR20: 10 | AV20: =IF(SUM(AJ20:AL20)=0, 0, (1 + F20 * 0.1) * (0.75 + 0.25 * MAX(0, MIN(1, IF(MAX(AJ20:AL20)=0, 0, (3*MAX(AJ20:AL20)-SUM(AJ20:AL20)) / (2*MAX(AJ20:AL20))))))) | AW20: =MAX(AJ20:AL20) | AX20: =IF(AW20=0, "", AW20 / ((1 + 0.1*N(F20)))) | AY20: =IF(SUM(AJ20:AL20)=0, 0, (1 + F20 * 0.1) * (1 + ((SUM(AJ20:AL20) - MAX(AJ20:AL20)) / (2 * MAX(AJ20:AL20))) * (1/0.75 - 1))) | AZ20: =AJ20+AK20+AL20 | BA20: =IF(AZ20=0, "", AZ20 / ((1 + 0.1*N(F20))/0.75)) | BB20: 0.1 | BD20: =BD19 | BE20: =BE19 | BH20: =BH19 | BL20: =BL19 | BN20: N/A | BO20: N/A | BQ20: =BQ19 | BR20: =IFERROR(BQ20*100/CP20,"N/A") | BS20: 1 | BT20: 1 | BW20: =BW19 | BX20: =CP20/BW20 | BY20: =BW20/T20 | CA20: =CA19+10 | CB20: =CA20*BB20*(AP20*AJ20+AQ20*AK20+AR20*AL20) | CC20: =CA20+CB20 | CK20: =CK19 | CN20: =CK20*CC20 | CP20: =CN20*BS20*BT20 | CQ20: =CP20/T20 | CR20: =100/CP20 | CS20: =100/CQ20 | CT20: =CQ20-CQ19 | CU20: =(CQ20-CQ19)/CQ19 | CV20: =BL20/T20 | CW20: =100/CV20 | DC20: 完成 | DD20: 完成
A21: AR47 | B21: AR47 | D21: =IF($A21="","","WPN"&VLOOKUP(E21,'引用数据库'!Z:AC,4,FALSE)&VLOOKUP(H21,'引用数据库'!N:P,3,FALSE)&VLOOKUP(I21,'引用数据库'!S:U,3,FALSE)&TEXT(F21,"00")) | E21: 纪念碑 | F21: 0 | G21: 远程 | H21: 步枪 | I21: 动能 | J21: 自动 | K21: 1 | M21: =0.4 + (T21 / (T21 + 0.2)) * 0.4 | N21: 1400 | O21: N/A | P21: 0 | Q21: 0 | R21: 0.15 | S21: 0 | T21: 0.15 | U21: =2*T21/(15*(1+(5-BD21)*0.1)) | W21: 0 | X21: 12 | Y21: 0.05 | Z21: 0.2 | AA21: 0.5 | AB21: 5 | AC21: 1.5 | AD21: =(W21+AB21)*AC21 | AE21: =(X21+AB21)*AC21 | AJ21: 0.44 | AK21: 0.44 | AL21: 0.44 | AM21: =IFS(AJ21 > 1.25, "S", AJ21 > 1, "A", AJ21 > 0.75, "B", AJ21 > 0.5, "C", AJ21 > 0.25, "D", AJ21 > 0, "E", TRUE, "-") | AN21: =IFS(AK21 > 1.25, "S", AK21 > 1, "A", AK21 > 0.75, "B", AK21 > 0.5, "C", AK21 > 0.25, "D", AK21 > 0, "E", TRUE, "-") | AO21: =IFS(AL21 > 1.25, "S", AL21 > 1, "A", AL21 > 0.75, "B", AL21 > 0.5, "C", AL21 > 0.25, "D", AL21 > 0, "E", TRUE, "-") | AP21: 10 | AQ21: 10 | AR21: 10 | AV21: =IF(SUM(AJ21:AL21)=0, 0, (1 + F21 * 0.1) * (0.75 + 0.25 * MAX(0, MIN(1, IF(MAX(AJ21:AL21)=0, 0, (3*MAX(AJ21:AL21)-SUM(AJ21:AL21)) / (2*MAX(AJ21:AL21))))))) | AW21: =MAX(AJ21:AL21) | AX21: =IF(AW21=0, "", AW21 / ((1 + 0.1*N(F21)))) | AY21: =IF(SUM(AJ21:AL21)=0, 0, (1 + F21 * 0.1) * (1 + ((SUM(AJ21:AL21) - MAX(AJ21:AL21)) / (2 * MAX(AJ21:AL21))) * (1/0.75 - 1))) | AZ21: =AJ21+AK21+AL21 | BA21: =IF(AZ21=0, "", AZ21 / ((1 + 0.1*N(F21))/0.75)) | BB21: 0.1 | BD21: 2 | BE21: 1 | BF21: 2 | BG21: =T21*20*(16 * BF21) / (15 + 20 * BF21 - 3 * POWER(BF21, 2))/BT21/BS21 | BH21: =BG21 | BJ21: 2 | BK21: =T21*33*(16 * BJ21) / (15 + 20 * BJ21 - 3 * POWER(BJ21, 2))/BT21/BS21 | BL21: =BK21 | BN21: 30 | BO21: 2.5 | BP21: =ROUND(CP21/10,2) | BQ21: 0.5 | BR21: =IFERROR(BQ21*100/CP21,"N/A") | BS21: 1 | BT21: 1 | BV21: =CP21/1.5 | BW21: =ROUND(BV21) | BX21: =CP21/BW21 | BY21: =BW21/T21 | CA21: 10 | CB21: =CA21*BB21*(AP21*AJ21+AQ21*AK21+AR21*AL21) | CC21: =CA21+CB21 | CD21: =T21 * 2 / BS21 / BT21 * (0.9 + 0.2 * IF(G21="近战", EXP(-64 * (T21 - 0.75)^2), EXP(-400 * (T21 - 0.15)^2))) | CE21: =0.9 + 0.2 / (1 + (N21/600)^1) | CF21: =LET( k, K21, be, BS21, bf, BT21, m, N21, n, O21, v, X21, vEff, IF(ISNUMBER(v), v, 0), angle, IF( ISNUMBER(n), IF(n>0, n, IF(ISNUMBER(v), IF(v>0, v, 0), 0 ) ), IF(ISNUMBER(v), IF(v>0, v, 0), 0 ) ), T, IF(k=1, be * bf * 20 / MAX(vEff, 1), IF(k=2, (m/150)^2 * (angle/120), IF(k=3, be * (MIN(bf, 99)/99) * (m/1000), be * bf * (m/1000) * (n/200)^2 ))), b, 0.8, c, 1.2, r, (c-1)/(1-b), k_s, 1, b + (c-b) / (1 + r * EXP(-k_s*(1-T)))) | CG21: =IF(T21<=0,1, (0.9 + 0.2 / (1 + EXP(-0.8 * (5 - BD21)))) * (0.9 + 0.2 / (1 + EXP(-1 * (3.5 - BE21)))) * (0.9 + 0.2 / (1 + EXP(-0.6 * (20 - BS21*BH21/T21))))) | CH21: =IF(T21<=0, 1, 0.9 + 0.2 / (1 + EXP(0.1 * (BL21*BS21*BT21/T21 - 33)))) | CI21: =LET( x_val, X21, bq_val, BS21, Check_Fail, OR(NOT(ISNUMBER(x_val)), bq_val <= 1), IF(Check_Fail, 1, LET( Ratio, x_val / bq_val, calc_A, 2.5 / (1 + EXP(-0.23105 * (Ratio - 3))), calc_B, 2.5 / (1 + EXP(-0.008664 * (x_val - 20))), calc_A + calc_B ) )) | CJ21: =CD21*CE21*CF21*CG21*CH21*CI21 | CK21: 0.3 | CL21: =T21 * 2 / BS21 / BT21 | CM21: =CK21/CL21 | CN21: =CK21*CC21 | CP21: =CN21*BS21*BT21 | CQ21: =CP21/T21 | CR21: =100/CP21 | CS21: =100/CQ21 | CV21: =BL21/T21 | CW21: =100/CV21 | CY21: 结合了人类历史上最经典的两款武器设计， 制作而成的制式步枪，性能设计得非常平衡。 若企业未为武装雇员配发此装备， 不少人也会自行购入并按规定登记使用。 | DA21: =TEXTJOIN("、", TRUE, FILTER('武器技能'!B:B, '武器技能'!E:E = H21)) | DC21: 完成 | DD21: 完成
A22: AR47 | B22: AR47 | D22: =IF($A22="","","WPN"&VLOOKUP(E22,'引用数据库'!Z:AC,4,FALSE)&VLOOKUP(H22,'引用数据库'!N:P,3,FALSE)&VLOOKUP(I22,'引用数据库'!S:U,3,FALSE)&TEXT(F22,"00")) | E22: 纪念碑 | F22: 1 | G22: =G21 | H22: =H21 | I22: =I21 | J22: 自动 | K22: =K21 | M22: =M21 | N22: 1400 | O22: N/A | P22: 0 | Q22: 0 | R22: 0.15 | S22: 0 | T22: =SUM(P22:S22) | U22: =2*T22/(15*(1+(5-BD22)*0.1)) | W22: =W21 | X22: =X21 | Y22: =Y21 | Z22: =Z21 | AA22: =AA21 | AB22: =AB21 | AC22: =AC21 | AD22: =AD21 | AE22: =AE21 | AJ22: =AJ21+0.05 | AK22: =AK21+0.05 | AL22: =AL21+0.05 | AM22: =IFS(AJ22 > 1.25, "S", AJ22 > 1, "A", AJ22 > 0.75, "B", AJ22 > 0.5, "C", AJ22 > 0.25, "D", AJ22 > 0, "E", TRUE, "-") | AN22: =IFS(AK22 > 1.25, "S", AK22 > 1, "A", AK22 > 0.75, "B", AK22 > 0.5, "C", AK22 > 0.25, "D", AK22 > 0, "E", TRUE, "-") | AO22: =IFS(AL22 > 1.25, "S", AL22 > 1, "A", AL22 > 0.75, "B", AL22 > 0.5, "C", AL22 > 0.25, "D", AL22 > 0, "E", TRUE, "-") | AP22: 10 | AQ22: 10 | AR22: 10 | AV22: =IF(SUM(AJ22:AL22)=0, 0, (1 + F22 * 0.1) * (0.75 + 0.25 * MAX(0, MIN(1, IF(MAX(AJ22:AL22)=0, 0, (3*MAX(AJ22:AL22)-SUM(AJ22:AL22)) / (2*MAX(AJ22:AL22))))))) | AW22: =MAX(AJ22:AL22) | AX22: =IF(AW22=0, "", AW22 / ((1 + 0.1*N(F22)))) | AY22: =IF(SUM(AJ22:AL22)=0, 0, (1 + F22 * 0.1) * (1 + ((SUM(AJ22:AL22) - MAX(AJ22:AL22)) / (2 * MAX(AJ22:AL22))) * (1/0.75 - 1))) | AZ22: =AJ22+AK22+AL22 | BA22: =IF(AZ22=0, "", AZ22 / ((1 + 0.1*N(F22))/0.75)) | BB22: 0.1 | BD22: =BD21 | BE22: =BE21 | BH22: =BH21 | BL22: =BL21 | BN22: 30 | BO22: 2.5 | BQ22: =BQ21 | BR22: =IFERROR(BQ22*100/CP22,"N/A") | BS22: 1 | BT22: 1 | BW22: =BW21 | BX22: =CP22/BW22 | BY22: =BW22/T22 | CA22: =CA21+20 | CB22: =CA22*BB22*(AP22*AJ22+AQ22*AK22+AR22*AL22) | CC22: =CA22+CB22 | CK22: =CK21 | CN22: =CK22*CC22 | CP22: =CN22*BS22*BT22 | CQ22: =CP22/T22 | CR22: =100/CP22 | CS22: =100/CQ22 | CT22: =CQ22-CQ21 | CU22: =(CQ22-CQ21)/CQ21 | CV22: =BL22/T22 | CW22: =100/CV22 | DC22: 完成 | DD22: 完成
