Workbook

Sheet 过期资产
A1: Name | B1: Obj | C1: Type | D1: Direction | E1: Config 1 | F1: Config 2 | H1: 终点1 | I1: 终点2 | J1: 终点3 | L1: 比例尺寸 X | M1: 比例尺寸 Y | N1: 比例尺寸 Z | O1: ="独特 "&COUNTIF(O2:O98,"✅")+COUNTIF(O2:O98,"❓") | P1: ="代理✅ "&COUNTIF(P2:P98,"✅") | Q1: ="彻底✅ "&COUNTIF(Q2:Q98,"✅") | R1: 难度 | S1: 描述
A2: =B2 & "_" & C2 & IF(D2<>"", "_" & D2, "") & IF(E2<>"", "_" & E2, "") & IF(F2<>"", "_" & F2, "") &"_X"&L2&"_Y"&M2&"_Z"&N2&"_Rail" | B2: BP | C2: Bump | D2: D90 | E2: Borderless | R2: =(1+((L2*M2*N2)-1)*0.1) * ((IF(C2<>"", VLOOKUP(C2,'引用列表'!A:C,3,FALSE), "")) + (IF(D2<>"", VLOOKUP(D2,'引用列表'!E:G,3,FALSE), "")) + (IF(E2<>"", IFERROR(VLOOKUP(E2, '引用列表'!I:K, 3, FALSE), ""), 0)) + (IF(F2<>"", IFERROR(VLOOKUP(F2, '引用列表'!I:K, 3, FALSE), ""), 0))) | S2: =((IF(C2<>"", VLOOKUP(C2,'引用列表'!A:C,2,FALSE), "")) & (IF(D2<>"", VLOOKUP(D2,'引用列表'!E:G,2,FALSE), "")) & (IF(E2<>"", IFERROR("，"&VLOOKUP(E2, '引用列表'!I:K, 2, FALSE), ""), "")) & (IF(F2<>"", IFERROR("，"&VLOOKUP(F2, '引用列表'!I:K, 2, FALSE), ""), "")))
A3: =B3 & "_" & C3 & IF(D3<>"", "_" & D3, "") & IF(E3<>"", "_" & E3, "") & IF(F3<>"", "_" & F3, "") &"_X"&L3&"_Y"&M3&"_Z"&N3&"_Rail" | C3: Bump | D3: D90 | L3: 1 | M3: 1 | N3: 1 | R3: =(1+((L3*M3*N3)-1)*0.1) * ((IF(C3<>"", VLOOKUP(C3,'引用列表'!A:C,3,FALSE), "")) + (IF(D3<>"", VLOOKUP(D3,'引用列表'!E:G,3,FALSE), "")) + (IF(E3<>"", IFERROR(VLOOKUP(E3, '引用列表'!I:K, 3, FALSE), ""), 0)) + (IF(F3<>"", IFERROR(VLOOKUP(F3, '引用列表'!I:K, 3, FALSE), ""), 0))) | S3: =((IF(C3<>"", VLOOKUP(C3,'引用列表'!A:C,2,FALSE), "")) & (IF(D3<>"", VLOOKUP(D3,'引用列表'!E:G,2,FALSE), "")) & (IF(E3<>"", IFERROR("，"&VLOOKUP(E3, '引用列表'!I:K, 2, FALSE), ""), "")) & (IF(F3<>"", IFERROR("，"&VLOOKUP(F3, '引用列表'!I:K, 2, FALSE), ""), "")))
A4: =B4 & "_" & C4 & IF(D4<>"", "_" & D4, "") & IF(E4<>"", "_" & E4, "") & IF(F4<>"", "_" & F4, "") &"_X"&L4&"_Y"&M4&"_Z"&N4&"_Rail" | C4: Bump | D4: FD | L4: 2 | M4: 1 | N4: 2 | O4: 是 | P4: ✅ | R4: =(1+((L4*M4*N4)-1)*0.1) * ((IF(C4<>"", VLOOKUP(C4,'引用列表'!A:C,3,FALSE), "")) + (IF(D4<>"", VLOOKUP(D4,'引用列表'!E:G,3,FALSE), "")) + (IF(E4<>"", IFERROR(VLOOKUP(E4, '引用列表'!I:K, 3, FALSE), ""), 0)) + (IF(F4<>"", IFERROR(VLOOKUP(F4, '引用列表'!I:K, 3, FALSE), ""), 0))) | S4: =((IF(C4<>"", VLOOKUP(C4,'引用列表'!A:C,2,FALSE), "")) & (IF(D4<>"", VLOOKUP(D4,'引用列表'!E:G,2,FALSE), "")) & (IF(E4<>"", IFERROR("，"&VLOOKUP(E4, '引用列表'!I:K, 2, FALSE), ""), "")) & (IF(F4<>"", IFERROR("，"&VLOOKUP(F4, '引用列表'!I:K, 2, FALSE), ""), "")))
A5: =B5 & "_" & C5 & IF(D5<>"", "_" & D5, "") & IF(E5<>"", "_" & E5, "") & IF(F5<>"", "_" & F5, "") &"_X"&L5&"_Y"&M5&"_Z"&N5&"_Rail" | C5: Bump | D5: FU | L5: 2 | M5: 1 | N5: 2 | O5: 是 | P5: ✅ | R5: =(1+((L5*M5*N5)-1)*0.1) * ((IF(C5<>"", VLOOKUP(C5,'引用列表'!A:C,3,FALSE), "")) + (IF(D5<>"", VLOOKUP(D5,'引用列表'!E:G,3,FALSE), "")) + (IF(E5<>"", IFERROR(VLOOKUP(E5, '引用列表'!I:K, 3, FALSE), ""), 0)) + (IF(F5<>"", IFERROR(VLOOKUP(F5, '引用列表'!I:K, 3, FALSE), ""), 0))) | S5: =((IF(C5<>"", VLOOKUP(C5,'引用列表'!A:C,2,FALSE), "")) & (IF(D5<>"", VLOOKUP(D5,'引用列表'!E:G,2,FALSE), "")) & (IF(E5<>"", IFERROR("，"&VLOOKUP(E5, '引用列表'!I:K, 2, FALSE), ""), "")) & (IF(F5<>"", IFERROR("，"&VLOOKUP(F5, '引用列表'!I:K, 2, FALSE), ""), "")))
A6: =B6 & "_" & C6 & IF(D6<>"", "_" & D6, "") & IF(E6<>"", "_" & E6, "") & IF(F6<>"", "_" & F6, "") &"_X"&L6&"_Y"&M6&"_Z"&N6&"_Rail" | C6: Bump | D6: U90 | E6: Borderless_L | R6: =(1+((L6*M6*N6)-1)*0.1) * ((IF(C6<>"", VLOOKUP(C6,'引用列表'!A:C,3,FALSE), "")) + (IF(D6<>"", VLOOKUP(D6,'引用列表'!E:G,3,FALSE), "")) + (IF(E6<>"", IFERROR(VLOOKUP(E6, '引用列表'!I:K, 3, FALSE), ""), 0)) + (IF(F6<>"", IFERROR(VLOOKUP(F6, '引用列表'!I:K, 3, FALSE), ""), 0))) | S6: =((IF(C6<>"", VLOOKUP(C6,'引用列表'!A:C,2,FALSE), "")) & (IF(D6<>"", VLOOKUP(D6,'引用列表'!E:G,2,FALSE), "")) & (IF(E6<>"", IFERROR("，"&VLOOKUP(E6, '引用列表'!I:K, 2, FALSE), ""), "")) & (IF(F6<>"", IFERROR("，"&VLOOKUP(F6, '引用列表'!I:K, 2, FALSE), ""), "")))
A7: =B7 & "_" & C7 & IF(D7<>"", "_" & D7, "") & IF(E7<>"", "_" & E7, "") & IF(F7<>"", "_" & F7, "") &"_X"&L7&"_Y"&M7&"_Z"&N7&"_Rail" | C7: Bump | D7: U90 | L7: 1 | M7: 1 | N7: 1 | R7: =(1+((L7*M7*N7)-1)*0.1) * ((IF(C7<>"", VLOOKUP(C7,'引用列表'!A:C,3,FALSE), "")) + (IF(D7<>"", VLOOKUP(D7,'引用列表'!E:G,3,FALSE), "")) + (IF(E7<>"", IFERROR(VLOOKUP(E7, '引用列表'!I:K, 3, FALSE), ""), 0)) + (IF(F7<>"", IFERROR(VLOOKUP(F7, '引用列表'!I:K, 3, FALSE), ""), 0))) | S7: =((IF(C7<>"", VLOOKUP(C7,'引用列表'!A:C,2,FALSE), "")) & (IF(D7<>"", VLOOKUP(D7,'引用列表'!E:G,2,FALSE), "")) & (IF(E7<>"", IFERROR("，"&VLOOKUP(E7, '引用列表'!I:K, 2, FALSE), ""), "")) & (IF(F7<>"", IFERROR("，"&VLOOKUP(F7, '引用列表'!I:K, 2, FALSE), ""), "")))
A8: =B8 & "_" & C8 & IF(D8<>"", "_" & D8, "") & IF(E8<>"", "_" & E8, "") & IF(F8<>"", "_" & F8, "") &"_X"&L8&"_Y"&M8&"_Z"&N8&"_Rail" | C8: Curve | D8: D90 | E8: Borderless | F8: Caved | L8: 1 | M8: 1 | N8: 1 | R8: =(1+((L8*M8*N8)-1)*0.1) * ((IF(C8<>"", VLOOKUP(C8,'引用列表'!A:C,3,FALSE), "")) + (IF(D8<>"", VLOOKUP(D8,'引用列表'!E:G,3,FALSE), "")) + (IF(E8<>"", IFERROR(VLOOKUP(E8, '引用列表'!I:K, 3, FALSE), ""), 0)) + (IF(F8<>"", IFERROR(VLOOKUP(F8, '引用列表'!I:K, 3, FALSE), ""), 0))) | S8: =((IF(C8<>"", VLOOKUP(C8,'引用列表'!A:C,2,FALSE), "")) & (IF(D8<>"", VLOOKUP(D8,'引用列表'!E:G,2,FALSE), "")) & (IF(E8<>"", IFERROR("，"&VLOOKUP(E8, '引用列表'!I:K, 2, FALSE), ""), "")) & (IF(F8<>"", IFERROR("，"&VLOOKUP(F8, '引用列表'!I:K, 2, FALSE), ""), "")))
A9: =B9 & "_" & C9 & IF(D9<>"", "_" & D9, "") & IF(E9<>"", "_" & E9, "") & IF(F9<>"", "_" & F9, "") &"_X"&L9&"_Y"&M9&"_Z"&N9&"_Rail" | C9: Curve | D9: D90 | E9: Borderless_L | L9: 1 | M9: 1 | N9: 1 | R9: =(1+((L9*M9*N9)-1)*0.1) * ((IF(C9<>"", VLOOKUP(C9,'引用列表'!A:C,3,FALSE), "")) + (IF(D9<>"", VLOOKUP(D9,'引用列表'!E:G,3,FALSE), "")) + (IF(E9<>"", IFERROR(VLOOKUP(E9, '引用列表'!I:K, 3, FALSE), ""), 0)) + (IF(F9<>"", IFERROR(VLOOKUP(F9, '引用列表'!I:K, 3, FALSE), ""), 0))) | S9: =((IF(C9<>"", VLOOKUP(C9,'引用列表'!A:C,2,FALSE), "")) & (IF(D9<>"", VLOOKUP(D9,'引用列表'!E:G,2,FALSE), "")) & (IF(E9<>"", IFERROR("，"&VLOOKUP(E9, '引用列表'!I:K, 2, FALSE), ""), "")) & (IF(F9<>"", IFERROR("，"&VLOOKUP(F9, '引用列表'!I:K, 2, FALSE), ""), "")))
A10: =B10 & "_" & C10 & IF(D10<>"", "_" & D10, "") & IF(E10<>"", "_" & E10, "") & IF(F10<>"", "_" & F10, "") &"_X"&L10&"_Y"&M10&"_Z"&N10&"_Rail" | C10: Curve | D10: D90 | E10: Borderless_R | L10: 1 | M10: 1 | N10: 1 | R10: =(1+((L10*M10*N10)-1)*0.1) * ((IF(C10<>"", VLOOKUP(C10,'引用列表'!A:C,3,FALSE), "")) + (IF(D10<>"", VLOOKUP(D10,'引用列表'!E:G,3,FALSE), "")) + (IF(E10<>"", IFERROR(VLOOKUP(E10, '引用列表'!I:K, 3, FALSE), ""), 0)) + (IF(F10<>"", IFERROR(VLOOKUP(F10, '引用列表'!I:K, 3, FALSE), ""), 0))) | S10: =((IF(C10<>"", VLOOKUP(C10,'引用列表'!A:C,2,FALSE), "")) & (IF(D10<>"", VLOOKUP(D10,'引用列表'!E:G,2,FALSE), "")) & (IF(E10<>"", IFERROR("，"&VLOOKUP(E10, '引用列表'!I:K, 2, FALSE), ""), "")) & (IF(F10<>"", IFERROR("，"&VLOOKUP(F10, '引用列表'!I:K, 2, FALSE), ""), "")))
A11: =B11 & "_" & C11 & IF(D11<>"", "_" & D11, "") & IF(E11<>"", "_" & E11, "") & IF(F11<>"", "_" & F11, "") &"_X"&L11&"_Y"&M11&"_Z"&N11&"_Rail" | C11: Curve | D11: D90 | L11: 1 | M11: 1 | N11: 1 | O11: 是 | R11: =(1+((L11*M11*N11)-1)*0.1) * ((IF(C11<>"", VLOOKUP(C11,'引用列表'!A:C,3,FALSE), "")) + (IF(D11<>"", VLOOKUP(D11,'引用列表'!E:G,3,FALSE), "")) + (IF(E11<>"", IFERROR(VLOOKUP(E11, '引用列表'!I:K, 3, FALSE), ""), 0)) + (IF(F11<>"", IFERROR(VLOOKUP(F11, '引用列表'!I:K, 3, FALSE), ""), 0))) | S11: =((IF(C11<>"", VLOOKUP(C11,'引用列表'!A:C,2,FALSE), "")) & (IF(D11<>"", VLOOKUP(D11,'引用列表'!E:G,2,FALSE), "")) & (IF(E11<>"", IFERROR("，"&VLOOKUP(E11, '引用列表'!I:K, 2, FALSE), ""), "")) & (IF(F11<>"", IFERROR("，"&VLOOKUP(F11, '引用列表'!I:K, 2, FALSE), ""), "")))
A12: =B12 & "_" & C12 & IF(D12<>"", "_" & D12, "") & IF(E12<>"", "_" & E12, "") & IF(F12<>"", "_" & F12, "") &"_X"&L12&"_Y"&M12&"_Z"&N12&"_Rail" | C12: Curve | D12: L90 | E12: Borderless | F12: Caved | L12: 1 | M12: 1 | N12: 1 | P12: ✅ | R12: =(1+((L12*M12*N12)-1)*0.1) * ((IF(C12<>"", VLOOKUP(C12,'引用列表'!A:C,3,FALSE), "")) + (IF(D12<>"", VLOOKUP(D12,'引用列表'!E:G,3,FALSE), "")) + (IF(E12<>"", IFERROR(VLOOKUP(E12, '引用列表'!I:K, 3, FALSE), ""), 0)) + (IF(F12<>"", IFERROR(VLOOKUP(F12, '引用列表'!I:K, 3, FALSE), ""), 0))) | S12: =((IF(C12<>"", VLOOKUP(C12,'引用列表'!A:C,2,FALSE), "")) & (IF(D12<>"", VLOOKUP(D12,'引用列表'!E:G,2,FALSE), "")) & (IF(E12<>"", IFERROR("，"&VLOOKUP(E12, '引用列表'!I:K, 2, FALSE), ""), "")) & (IF(F12<>"", IFERROR("，"&VLOOKUP(F12, '引用列表'!I:K, 2, FALSE), ""), "")))
A13: =B13 & "_" & C13 & IF(D13<>"", "_" & D13, "") & IF(E13<>"", "_" & E13, "") & IF(F13<>"", "_" & F13, "") &"_X"&L13&"_Y"&M13&"_Z"&N13&"_Rail" | C13: Curve | D13: L90 | E13: Borderless_I | L13: 1 | M13: 1 | N13: 1 | P13: ✅ | R13: =(1+((L13*M13*N13)-1)*0.1) * ((IF(C13<>"", VLOOKUP(C13,'引用列表'!A:C,3,FALSE), "")) + (IF(D13<>"", VLOOKUP(D13,'引用列表'!E:G,3,FALSE), "")) + (IF(E13<>"", IFERROR(VLOOKUP(E13, '引用列表'!I:K, 3, FALSE), ""), 0)) + (IF(F13<>"", IFERROR(VLOOKUP(F13, '引用列表'!I:K, 3, FALSE), ""), 0))) | S13: =((IF(C13<>"", VLOOKUP(C13,'引用列表'!A:C,2,FALSE), "")) & (IF(D13<>"", VLOOKUP(D13,'引用列表'!E:G,2,FALSE), "")) & (IF(E13<>"", IFERROR("，"&VLOOKUP(E13, '引用列表'!I:K, 2, FALSE), ""), "")) & (IF(F13<>"", IFERROR("，"&VLOOKUP(F13, '引用列表'!I:K, 2, FALSE), ""), "")))
A14: =B14 & "_" & C14 & IF(D14<>"", "_" & D14, "") & IF(E14<>"", "_" & E14, "") & IF(F14<>"", "_" & F14, "") &"_X"&L14&"_Y"&M14&"_Z"&N14&"_Rail" | C14: Curve | D14: L90 | E14: Borderless_O | L14: 1 | M14: 1 | N14: 1 | P14: ✅ | R14: =(1+((L14*M14*N14)-1)*0.1) * ((IF(C14<>"", VLOOKUP(C14,'引用列表'!A:C,3,FALSE), "")) + (IF(D14<>"", VLOOKUP(D14,'引用列表'!E:G,3,FALSE), "")) + (IF(E14<>"", IFERROR(VLOOKUP(E14, '引用列表'!I:K, 3, FALSE), ""), 0)) + (IF(F14<>"", IFERROR(VLOOKUP(F14, '引用列表'!I:K, 3, FALSE), ""), 0))) | S14: =((IF(C14<>"", VLOOKUP(C14,'引用列表'!A:C,2,FALSE), "")) & (IF(D14<>"", VLOOKUP(D14,'引用列表'!E:G,2,FALSE), "")) & (IF(E14<>"", IFERROR("，"&VLOOKUP(E14, '引用列表'!I:K, 2, FALSE), ""), "")) & (IF(F14<>"", IFERROR("，"&VLOOKUP(F14, '引用列表'!I:K, 2, FALSE), ""), "")))
A15: =B15 & "_" & C15 & IF(D15<>"", "_" & D15, "") & IF(E15<>"", "_" & E15, "") & IF(F15<>"", "_" & F15, "") &"_X"&L15&"_Y"&M15&"_Z"&N15&"_Rail" | C15: Curve | D15: L90 | E15: Borderless_O | L15: 2 | M15: 2 | N15: 2 | O15: 镜像源 | R15: =(1+((L15*M15*N15)-1)*0.1) * ((IF(C15<>"", VLOOKUP(C15,'引用列表'!A:C,3,FALSE), "")) + (IF(D15<>"", VLOOKUP(D15,'引用列表'!E:G,3,FALSE), "")) + (IF(E15<>"", IFERROR(VLOOKUP(E15, '引用列表'!I:K, 3, FALSE), ""), 0)) + (IF(F15<>"", IFERROR(VLOOKUP(F15, '引用列表'!I:K, 3, FALSE), ""), 0))) | S15: =((IF(C15<>"", VLOOKUP(C15,'引用列表'!A:C,2,FALSE), "")) & (IF(D15<>"", VLOOKUP(D15,'引用列表'!E:G,2,FALSE), "")) & (IF(E15<>"", IFERROR("，"&VLOOKUP(E15, '引用列表'!I:K, 2, FALSE), ""), "")) & (IF(F15<>"", IFERROR("，"&VLOOKUP(F15, '引用列表'!I:K, 2, FALSE), ""), "")))
A16: =B16 & "_" & C16 & IF(D16<>"", "_" & D16, "") & IF(E16<>"", "_" & E16, "") & IF(F16<>"", "_" & F16, "") &"_X"&L16&"_Y"&M16&"_Z"&N16&"_Rail" | C16: Curve | D16: L90 | L16: 1 | M16: 1 | N16: 1 | O16: 镜像源 | P16: ✅ | R16: =(1+((L16*M16*N16)-1)*0.1) * ((IF(C16<>"", VLOOKUP(C16,'引用列表'!A:C,3,FALSE), "")) + (IF(D16<>"", VLOOKUP(D16,'引用列表'!E:G,3,FALSE), "")) + (IF(E16<>"", IFERROR(VLOOKUP(E16, '引用列表'!I:K, 3, FALSE), ""), 0)) + (IF(F16<>"", IFERROR(VLOOKUP(F16, '引用列表'!I:K, 3, FALSE), ""), 0))) | S16: =((IF(C16<>"", VLOOKUP(C16,'引用列表'!A:C,2,FALSE), "")) & (IF(D16<>"", VLOOKUP(D16,'引用列表'!E:G,2,FALSE), "")) & (IF(E16<>"", IFERROR("，"&VLOOKUP(E16, '引用列表'!I:K, 2, FALSE), ""), "")) & (IF(F16<>"", IFERROR("，"&VLOOKUP(F16, '引用列表'!I:K, 2, FALSE), ""), "")))
A17: =B17 & "_" & C17 & IF(D17<>"", "_" & D17, "") & IF(E17<>"", "_" & E17, "") & IF(F17<>"", "_" & F17, "") &"_X"&L17&"_Y"&M17&"_Z"&N17&"_Rail" | C17: Curve | D17: L90 | L17: 2 | M17: 2 | N17: 2 | O17: 镜像源 | R17: =(1+((L17*M17*N17)-1)*0.1) * ((IF(C17<>"", VLOOKUP(C17,'引用列表'!A:C,3,FALSE), "")) + (IF(D17<>"", VLOOKUP(D17,'引用列表'!E:G,3,FALSE), "")) + (IF(E17<>"", IFERROR(VLOOKUP(E17, '引用列表'!I:K, 3, FALSE), ""), 0)) + (IF(F17<>"", IFERROR(VLOOKUP(F17, '引用列表'!I:K, 3, FALSE), ""), 0))) | S17: =((IF(C17<>"", VLOOKUP(C17,'引用列表'!A:C,2,FALSE), "")) & (IF(D17<>"", VLOOKUP(D17,'引用列表'!E:G,2,FALSE), "")) & (IF(E17<>"", IFERROR("，"&VLOOKUP(E17, '引用列表'!I:K, 2, FALSE), ""), "")) & (IF(F17<>"", IFERROR("，"&VLOOKUP(F17, '引用列表'!I:K, 2, FALSE), ""), "")))
A18: =B18 & "_" & C18 & IF(D18<>"", "_" & D18, "") & IF(E18<>"", "_" & E18, "") & IF(F18<>"", "_" & F18, "") &"_X"&L18&"_Y"&M18&"_Z"&N18&"_Rail" | C18: Curve | D18: R90 | E18: Borderless | F18: Caved | L18: 1 | M18: 1 | N18: 1 | P18: ✅ | R18: =(1+((L18*M18*N18)-1)*0.1) * ((IF(C18<>"", VLOOKUP(C18,'引用列表'!A:C,3,FALSE), "")) + (IF(D18<>"", VLOOKUP(D18,'引用列表'!E:G,3,FALSE), "")) + (IF(E18<>"", IFERROR(VLOOKUP(E18, '引用列表'!I:K, 3, FALSE), ""), 0)) + (IF(F18<>"", IFERROR(VLOOKUP(F18, '引用列表'!I:K, 3, FALSE), ""), 0))) | S18: =((IF(C18<>"", VLOOKUP(C18,'引用列表'!A:C,2,FALSE), "")) & (IF(D18<>"", VLOOKUP(D18,'引用列表'!E:G,2,FALSE), "")) & (IF(E18<>"", IFERROR("，"&VLOOKUP(E18, '引用列表'!I:K, 2, FALSE), ""), "")) & (IF(F18<>"", IFERROR("，"&VLOOKUP(F18, '引用列表'!I:K, 2, FALSE), ""), "")))
A19: =B19 & "_" & C19 & IF(D19<>"", "_" & D19, "") & IF(E19<>"", "_" & E19, "") & IF(F19<>"", "_" & F19, "") &"_X"&L19&"_Y"&M19&"_Z"&N19&"_Rail" | C19: Curve | D19: R90 | E19: Borderless_I | L19: 1 | M19: 1 | N19: 1 | P19: ✅ | R19: =(1+((L19*M19*N19)-1)*0.1) * ((IF(C19<>"", VLOOKUP(C19,'引用列表'!A:C,3,FALSE), "")) + (IF(D19<>"", VLOOKUP(D19,'引用列表'!E:G,3,FALSE), "")) + (IF(E19<>"", IFERROR(VLOOKUP(E19, '引用列表'!I:K, 3, FALSE), ""), 0)) + (IF(F19<>"", IFERROR(VLOOKUP(F19, '引用列表'!I:K, 3, FALSE), ""), 0))) | S19: =((IF(C19<>"", VLOOKUP(C19,'引用列表'!A:C,2,FALSE), "")) & (IF(D19<>"", VLOOKUP(D19,'引用列表'!E:G,2,FALSE), "")) & (IF(E19<>"", IFERROR("，"&VLOOKUP(E19, '引用列表'!I:K, 2, FALSE), ""), "")) & (IF(F19<>"", IFERROR("，"&VLOOKUP(F19, '引用列表'!I:K, 2, FALSE), ""), "")))
A20: =B20 & "_" & C20 & IF(D20<>"", "_" & D20, "") & IF(E20<>"", "_" & E20, "") & IF(F20<>"", "_" & F20, "") &"_X"&L20&"_Y"&M20&"_Z"&N20&"_Rail" | C20: Curve | D20: R90 | E20: Borderless_O | L20: 1 | M20: 1 | N20: 1 | P20: ✅ | R20: =(1+((L20*M20*N20)-1)*0.1) * ((IF(C20<>"", VLOOKUP(C20,'引用列表'!A:C,3,FALSE), "")) + (IF(D20<>"", VLOOKUP(D20,'引用列表'!E:G,3,FALSE), "")) + (IF(E20<>"", IFERROR(VLOOKUP(E20, '引用列表'!I:K, 3, FALSE), ""), 0)) + (IF(F20<>"", IFERROR(VLOOKUP(F20, '引用列表'!I:K, 3, FALSE), ""), 0))) | S20: =((IF(C20<>"", VLOOKUP(C20,'引用列表'!A:C,2,FALSE), "")) & (IF(D20<>"", VLOOKUP(D20,'引用列表'!E:G,2,FALSE), "")) & (IF(E20<>"", IFERROR("，"&VLOOKUP(E20, '引用列表'!I:K, 2, FALSE), ""), "")) & (IF(F20<>"", IFERROR("，"&VLOOKUP(F20, '引用列表'!I:K, 2, FALSE), ""), "")))
A21: =B21 & "_" & C21 & IF(D21<>"", "_" & D21, "") & IF(E21<>"", "_" & E21, "") & IF(F21<>"", "_" & F21, "") &"_X"&L21&"_Y"&M21&"_Z"&N21&"_Rail" | C21: Curve | D21: R90 | L21: 1 | M21: 1 | N21: 1 | O21: 镜像子 | P21: ✅ | R21: =(1+((L21*M21*N21)-1)*0.1) * ((IF(C21<>"", VLOOKUP(C21,'引用列表'!A:C,3,FALSE), "")) + (IF(D21<>"", VLOOKUP(D21,'引用列表'!E:G,3,FALSE), "")) + (IF(E21<>"", IFERROR(VLOOKUP(E21, '引用列表'!I:K, 3, FALSE), ""), 0)) + (IF(F21<>"", IFERROR(VLOOKUP(F21, '引用列表'!I:K, 3, FALSE), ""), 0))) | S21: =((IF(C21<>"", VLOOKUP(C21,'引用列表'!A:C,2,FALSE), "")) & (IF(D21<>"", VLOOKUP(D21,'引用列表'!E:G,2,FALSE), "")) & (IF(E21<>"", IFERROR("，"&VLOOKUP(E21, '引用列表'!I:K, 2, FALSE), ""), "")) & (IF(F21<>"", IFERROR("，"&VLOOKUP(F21, '引用列表'!I:K, 2, FALSE), ""), "")))
A22: =B22 & "_" & C22 & IF(D22<>"", "_" & D22, "") & IF(E22<>"", "_" & E22, "") & IF(F22<>"", "_" & F22, "") &"_X"&L22&"_Y"&M22&"_Z"&N22&"_Rail"
A23: =B23 & "_" & C23 & IF(D23<>"", "_" & D23, "") & IF(E23<>"", "_" & E23, "") & IF(F23<>"", "_" & F23, "") &"_X"&L23&"_Y"&M23&"_Z"&N23&"_Rail" | C23: Curve | D23: T | E23: Borderless_T | L23: 1 | M23: 1 | N23: 1 | O23: 是 | R23: =(1+((L23*M23*N23)-1)*0.1) * ((IF(C23<>"", VLOOKUP(C23,'引用列表'!A:C,3,FALSE), "")) + (IF(D23<>"", VLOOKUP(D23,'引用列表'!E:G,3,FALSE), "")) + (IF(E23<>"", IFERROR(VLOOKUP(E23, '引用列表'!I:K, 3, FALSE), ""), 0)) + (IF(F23<>"", IFERROR(VLOOKUP(F23, '引用列表'!I:K, 3, FALSE), ""), 0))) | S23: =((IF(C23<>"", VLOOKUP(C23,'引用列表'!A:C,2,FALSE), "")) & (IF(D23<>"", VLOOKUP(D23,'引用列表'!E:G,2,FALSE), "")) & (IF(E23<>"", IFERROR("，"&VLOOKUP(E23, '引用列表'!I:K, 2, FALSE), ""), "")) & (IF(F23<>"", IFERROR("，"&VLOOKUP(F23, '引用列表'!I:K, 2, FALSE), ""), "")))
A24: =B24 & "_" & C24 & IF(D24<>"", "_" & D24, "") & IF(E24<>"", "_" & E24, "") & IF(F24<>"", "_" & F24, "") &"_X"&L24&"_Y"&M24&"_Z"&N24&"_Rail" | C24: Curve | D24: T | L24: 1 | M24: 1 | N24: 1 | O24: 是 | R24: =(1+((L24*M24*N24)-1)*0.1) * ((IF(C24<>"", VLOOKUP(C24,'引用列表'!A:C,3,FALSE), "")) + (IF(D24<>"", VLOOKUP(D24,'引用列表'!E:G,3,FALSE), "")) + (IF(E24<>"", IFERROR(VLOOKUP(E24, '引用列表'!I:K, 3, FALSE), ""), 0)) + (IF(F24<>"", IFERROR(VLOOKUP(F24, '引用列表'!I:K, 3, FALSE), ""), 0))) | S24: =((IF(C24<>"", VLOOKUP(C24,'引用列表'!A:C,2,FALSE), "")) & (IF(D24<>"", VLOOKUP(D24,'引用列表'!E:G,2,FALSE), "")) & (IF(E24<>"", IFERROR("，"&VLOOKUP(E24, '引用列表'!I:K, 2, FALSE), ""), "")) & (IF(F24<>"", IFERROR("，"&VLOOKUP(F24, '引用列表'!I:K, 2, FALSE), ""), "")))
A25: =B25 & "_" & C25 & IF(D25<>"", "_" & D25, "") & IF(E25<>"", "_" & E25, "") & IF(F25<>"", "_" & F25, "") &"_X"&L25&"_Y"&M25&"_Z"&N25&"_Rail" | C25: Curve | D25: U90 | E25: Borderless | F25: Caved | L25: 1 | M25: 1 | N25: 1 | R25: =(1+((L25*M25*N25)-1)*0.1) * ((IF(C25<>"", VLOOKUP(C25,'引用列表'!A:C,3,FALSE), "")) + (IF(D25<>"", VLOOKUP(D25,'引用列表'!E:G,3,FALSE), "")) + (IF(E25<>"", IFERROR(VLOOKUP(E25, '引用列表'!I:K, 3, FALSE), ""), 0)) + (IF(F25<>"", IFERROR(VLOOKUP(F25, '引用列表'!I:K, 3, FALSE), ""), 0))) | S25: =((IF(C25<>"", VLOOKUP(C25,'引用列表'!A:C,2,FALSE), "")) & (IF(D25<>"", VLOOKUP(D25,'引用列表'!E:G,2,FALSE), "")) & (IF(E25<>"", IFERROR("，"&VLOOKUP(E25, '引用列表'!I:K, 2, FALSE), ""), "")) & (IF(F25<>"", IFERROR("，"&VLOOKUP(F25, '引用列表'!I:K, 2, FALSE), ""), "")))
A26: =B26 & "_" & C26 & IF(D26<>"", "_" & D26, "") & IF(E26<>"", "_" & E26, "") & IF(F26<>"", "_" & F26, "") &"_X"&L26&"_Y"&M26&"_Z"&N26&"_Rail" | C26: Curve | D26: U90 | E26: Borderless | F26: Caved | L26: 3 | M26: 3 | N26: 3 | O26: 是 | P26: ✅ | R26: =(1+((L26*M26*N26)-1)*0.1) * ((IF(C26<>"", VLOOKUP(C26,'引用列表'!A:C,3,FALSE), "")) + (IF(D26<>"", VLOOKUP(D26,'引用列表'!E:G,3,FALSE), "")) + (IF(E26<>"", IFERROR(VLOOKUP(E26, '引用列表'!I:K, 3, FALSE), ""), 0)) + (IF(F26<>"", IFERROR(VLOOKUP(F26, '引用列表'!I:K, 3, FALSE), ""), 0))) | S26: =((IF(C26<>"", VLOOKUP(C26,'引用列表'!A:C,2,FALSE), "")) & (IF(D26<>"", VLOOKUP(D26,'引用列表'!E:G,2,FALSE), "")) & (IF(E26<>"", IFERROR("，"&VLOOKUP(E26, '引用列表'!I:K, 2, FALSE), ""), "")) & (IF(F26<>"", IFERROR("，"&VLOOKUP(F26, '引用列表'!I:K, 2, FALSE), ""), "")))
A27: =B27 & "_" & C27 & IF(D27<>"", "_" & D27, "") & IF(E27<>"", "_" & E27, "") & IF(F27<>"", "_" & F27, "") &"_X"&L27&"_Y"&M27&"_Z"&N27&"_Rail" | C27: Curve | D27: U90 | E27: Borderless | F27: Caved | L27: 4 | M27: 1 | N27: 4 | O27: 是 | R27: =(1+((L27*M27*N27)-1)*0.1) * ((IF(C27<>"", VLOOKUP(C27,'引用列表'!A:C,3,FALSE), "")) + (IF(D27<>"", VLOOKUP(D27,'引用列表'!E:G,3,FALSE), "")) + (IF(E27<>"", IFERROR(VLOOKUP(E27, '引用列表'!I:K, 3, FALSE), ""), 0)) + (IF(F27<>"", IFERROR(VLOOKUP(F27, '引用列表'!I:K, 3, FALSE), ""), 0))) | S27: =((IF(C27<>"", VLOOKUP(C27,'引用列表'!A:C,2,FALSE), "")) & (IF(D27<>"", VLOOKUP(D27,'引用列表'!E:G,2,FALSE), "")) & (IF(E27<>"", IFERROR("，"&VLOOKUP(E27, '引用列表'!I:K, 2, FALSE), ""), "")) & (IF(F27<>"", IFERROR("，"&VLOOKUP(F27, '引用列表'!I:K, 2, FALSE), ""), "")))
A28: =B28 & "_" & C28 & IF(D28<>"", "_" & D28, "") & IF(E28<>"", "_" & E28, "") & IF(F28<>"", "_" & F28, "") &"_X"&L28&"_Y"&M28&"_Z"&N28&"_Rail" | C28: Curve | D28: U90 | E28: Borderless_L | L28: 1 | M28: 1 | N28: 1 | R28: =(1+((L28*M28*N28)-1)*0.1) * ((IF(C28<>"", VLOOKUP(C28,'引用列表'!A:C,3,FALSE), "")) + (IF(D28<>"", VLOOKUP(D28,'引用列表'!E:G,3,FALSE), "")) + (IF(E28<>"", IFERROR(VLOOKUP(E28, '引用列表'!I:K, 3, FALSE), ""), 0)) + (IF(F28<>"", IFERROR(VLOOKUP(F28, '引用列表'!I:K, 3, FALSE), ""), 0))) | S28: =((IF(C28<>"", VLOOKUP(C28,'引用列表'!A:C,2,FALSE), "")) & (IF(D28<>"", VLOOKUP(D28,'引用列表'!E:G,2,FALSE), "")) & (IF(E28<>"", IFERROR("，"&VLOOKUP(E28, '引用列表'!I:K, 2, FALSE), ""), "")) & (IF(F28<>"", IFERROR("，"&VLOOKUP(F28, '引用列表'!I:K, 2, FALSE), ""), "")))
A29: =B29 & "_" & C29 & IF(D29<>"", "_" & D29, "") & IF(E29<>"", "_" & E29, "") & IF(F29<>"", "_" & F29, "") &"_X"&L29&"_Y"&M29&"_Z"&N29&"_Rail" | C29: Curve | D29: U90 | E29: Borderless_R | L29: 1 | M29: 1 | N29: 1 | R29: =(1+((L29*M29*N29)-1)*0.1) * ((IF(C29<>"", VLOOKUP(C29,'引用列表'!A:C,3,FALSE), "")) + (IF(D29<>"", VLOOKUP(D29,'引用列表'!E:G,3,FALSE), "")) + (IF(E29<>"", IFERROR(VLOOKUP(E29, '引用列表'!I:K, 3, FALSE), ""), 0)) + (IF(F29<>"", IFERROR(VLOOKUP(F29, '引用列表'!I:K, 3, FALSE), ""), 0))) | S29: =((IF(C29<>"", VLOOKUP(C29,'引用列表'!A:C,2,FALSE), "")) & (IF(D29<>"", VLOOKUP(D29,'引用列表'!E:G,2,FALSE), "")) & (IF(E29<>"", IFERROR("，"&VLOOKUP(E29, '引用列表'!I:K, 2, FALSE), ""), "")) & (IF(F29<>"", IFERROR("，"&VLOOKUP(F29, '引用列表'!I:K, 2, FALSE), ""), "")))
A30: =B30 & "_" & C30 & IF(D30<>"", "_" & D30, "") & IF(E30<>"", "_" & E30, "") & IF(F30<>"", "_" & F30, "") &"_X"&L30&"_Y"&M30&"_Z"&N30&"_Rail" | C30: Curve | D30: U90 | L30: 1 | M30: 1 | N30: 1 | O30: 是 | P30: 在做PROXY | R30: =(1+((L30*M30*N30)-1)*0.1) * ((IF(C30<>"", VLOOKUP(C30,'引用列表'!A:C,3,FALSE), "")) + (IF(D30<>"", VLOOKUP(D30,'引用列表'!E:G,3,FALSE), "")) + (IF(E30<>"", IFERROR(VLOOKUP(E30, '引用列表'!I:K, 3, FALSE), ""), 0)) + (IF(F30<>"", IFERROR(VLOOKUP(F30, '引用列表'!I:K, 3, FALSE), ""), 0))) | S30: =((IF(C30<>"", VLOOKUP(C30,'引用列表'!A:C,2,FALSE), "")) & (IF(D30<>"", VLOOKUP(D30,'引用列表'!E:G,2,FALSE), "")) & (IF(E30<>"", IFERROR("，"&VLOOKUP(E30, '引用列表'!I:K, 2, FALSE), ""), "")) & (IF(F30<>"", IFERROR("，"&VLOOKUP(F30, '引用列表'!I:K, 2, FALSE), ""), "")))
A31: =B31 & "_" & C31 & IF(D31<>"", "_" & D31, "") & IF(E31<>"", "_" & E31, "") & IF(F31<>"", "_" & F31, "") &"_X"&L31&"_Y"&M31&"_Z"&N31&"_Rail" | C31: End | D31: F | L31: 1 | M31: 1 | N31: 1 | O31: 是 | P31: 简单VOXEL | R31: =(1+((L31*M31*N31)-1)*0.1) * ((IF(C31<>"", VLOOKUP(C31,'引用列表'!A:C,3,FALSE), "")) + (IF(D31<>"", VLOOKUP(D31,'引用列表'!E:G,3,FALSE), "")) + (IF(E31<>"", IFERROR(VLOOKUP(E31, '引用列表'!I:K, 3, FALSE), ""), 0)) + (IF(F31<>"", IFERROR(VLOOKUP(F31, '引用列表'!I:K, 3, FALSE), ""), 0))) | S31: =((IF(C31<>"", VLOOKUP(C31,'引用列表'!A:C,2,FALSE), "")) & (IF(D31<>"", VLOOKUP(D31,'引用列表'!E:G,2,FALSE), "")) & (IF(E31<>"", IFERROR("，"&VLOOKUP(E31, '引用列表'!I:K, 2, FALSE), ""), "")) & (IF(F31<>"", IFERROR("，"&VLOOKUP(F31, '引用列表'!I:K, 2, FALSE), ""), "")))
A32: =B32 & "_" & C32 & IF(D32<>"", "_" & D32, "") & IF(E32<>"", "_" & E32, "") & IF(F32<>"", "_" & F32, "") &"_X"&L32&"_Y"&M32&"_Z"&N32&"_Rail" | C32: Start | D32: F | H32: (1,0,0), X, [0] | L32: 1 | M32: 1 | N32: 1 | O32: 是 | P32: 简单VOXEL | R32: =(1+((L32*M32*N32)-1)*0.1) * ((IF(C32<>"", VLOOKUP(C32,'引用列表'!A:C,3,FALSE), "")) + (IF(D32<>"", VLOOKUP(D32,'引用列表'!E:G,3,FALSE), "")) + (IF(E32<>"", IFERROR(VLOOKUP(E32, '引用列表'!I:K, 3, FALSE), ""), 0)) + (IF(F32<>"", IFERROR(VLOOKUP(F32, '引用列表'!I:K, 3, FALSE), ""), 0))) | S32: =((IF(C32<>"", VLOOKUP(C32,'引用列表'!A:C,2,FALSE), "")) & (IF(D32<>"", VLOOKUP(D32,'引用列表'!E:G,2,FALSE), "")) & (IF(E32<>"", IFERROR("，"&VLOOKUP(E32, '引用列表'!I:K, 2, FALSE), ""), "")) & (IF(F32<>"", IFERROR("，"&VLOOKUP(F32, '引用列表'!I:K, 2, FALSE), ""), "")))
A33: =B33 & "_" & C33 & IF(D33<>"", "_" & D33, "") & IF(E33<>"", "_" & E33, "") & IF(F33<>"", "_" & F33, "") &"_X"&L33&"_Y"&M33&"_Z"&N33&"_Rail" | C33: Straight | D33: D90 | E33: Borderless | F33: Caved | H33: 1 | I33: 1 | L33: 1 | M33: 1 | N33: 1 | O33: 镜像子 | P33: 不急 | R33: =(1+((L33*M33*N33)-1)*0.1) * ((IF(C33<>"", VLOOKUP(C33,'引用列表'!A:C,3,FALSE), "")) + (IF(D33<>"", VLOOKUP(D33,'引用列表'!E:G,3,FALSE), "")) + (IF(E33<>"", IFERROR(VLOOKUP(E33, '引用列表'!I:K, 3, FALSE), ""), 0)) + (IF(F33<>"", IFERROR(VLOOKUP(F33, '引用列表'!I:K, 3, FALSE), ""), 0))) | S33: =((IF(C33<>"", VLOOKUP(C33,'引用列表'!A:C,2,FALSE), "")) & (IF(D33<>"", VLOOKUP(D33,'引用列表'!E:G,2,FALSE), "")) & (IF(E33<>"", IFERROR("，"&VLOOKUP(E33, '引用列表'!I:K, 2, FALSE), ""), "")) & (IF(F33<>"", IFERROR("，"&VLOOKUP(F33, '引用列表'!I:K, 2, FALSE), ""), "")))
A34: =B34 & "_" & C34 & IF(D34<>"", "_" & D34, "") & IF(E34<>"", "_" & E34, "") & IF(F34<>"", "_" & F34, "") &"_X"&L34&"_Y"&M34&"_Z"&N34&"_Rail" | C34: Straight | D34: D90 | E34: Borderless_L | L34: 1 | M34: 1 | N34: 1 | R34: =(1+((L34*M34*N34)-1)*0.1) * ((IF(C34<>"", VLOOKUP(C34,'引用列表'!A:C,3,FALSE), "")) + (IF(D34<>"", VLOOKUP(D34,'引用列表'!E:G,3,FALSE), "")) + (IF(E34<>"", IFERROR(VLOOKUP(E34, '引用列表'!I:K, 3, FALSE), ""), 0)) + (IF(F34<>"", IFERROR(VLOOKUP(F34, '引用列表'!I:K, 3, FALSE), ""), 0))) | S34: =((IF(C34<>"", VLOOKUP(C34,'引用列表'!A:C,2,FALSE), "")) & (IF(D34<>"", VLOOKUP(D34,'引用列表'!E:G,2,FALSE), "")) & (IF(E34<>"", IFERROR("，"&VLOOKUP(E34, '引用列表'!I:K, 2, FALSE), ""), "")) & (IF(F34<>"", IFERROR("，"&VLOOKUP(F34, '引用列表'!I:K, 2, FALSE), ""), "")))
A35: =B35 & "_" & C35 & IF(D35<>"", "_" & D35, "") & IF(E35<>"", "_" & E35, "") & IF(F35<>"", "_" & F35, "") &"_X"&L35&"_Y"&M35&"_Z"&N35&"_Rail" | C35: Straight | D35: D90 | E35: Borderless_R | L35: 1 | M35: 1 | N35: 1 | R35: =(1+((L35*M35*N35)-1)*0.1) * ((IF(C35<>"", VLOOKUP(C35,'引用列表'!A:C,3,FALSE), "")) + (IF(D35<>"", VLOOKUP(D35,'引用列表'!E:G,3,FALSE), "")) + (IF(E35<>"", IFERROR(VLOOKUP(E35, '引用列表'!I:K, 3, FALSE), ""), 0)) + (IF(F35<>"", IFERROR(VLOOKUP(F35, '引用列表'!I:K, 3, FALSE), ""), 0))) | S35: =((IF(C35<>"", VLOOKUP(C35,'引用列表'!A:C,2,FALSE), "")) & (IF(D35<>"", VLOOKUP(D35,'引用列表'!E:G,2,FALSE), "")) & (IF(E35<>"", IFERROR("，"&VLOOKUP(E35, '引用列表'!I:K, 2, FALSE), ""), "")) & (IF(F35<>"", IFERROR("，"&VLOOKUP(F35, '引用列表'!I:K, 2, FALSE), ""), "")))
A36: =B36 & "_" & C36 & IF(D36<>"", "_" & D36, "") & IF(E36<>"", "_" & E36, "") & IF(F36<>"", "_" & F36, "") &"_X"&L36&"_Y"&M36&"_Z"&N36&"_Rail" | C36: Straight | D36: D90 | H36: 0,1,0,y | L36: 1 | M36: 1 | N36: 1 | O36: 是 | P36: 不急 | R36: =(1+((L36*M36*N36)-1)*0.1) * ((IF(C36<>"", VLOOKUP(C36,'引用列表'!A:C,3,FALSE), "")) + (IF(D36<>"", VLOOKUP(D36,'引用列表'!E:G,3,FALSE), "")) + (IF(E36<>"", IFERROR(VLOOKUP(E36, '引用列表'!I:K, 3, FALSE), ""), 0)) + (IF(F36<>"", IFERROR(VLOOKUP(F36, '引用列表'!I:K, 3, FALSE), ""), 0))) | S36: =((IF(C36<>"", VLOOKUP(C36,'引用列表'!A:C,2,FALSE), "")) & (IF(D36<>"", VLOOKUP(D36,'引用列表'!E:G,2,FALSE), "")) & (IF(E36<>"", IFERROR("，"&VLOOKUP(E36, '引用列表'!I:K, 2, FALSE), ""), "")) & (IF(F36<>"", IFERROR("，"&VLOOKUP(F36, '引用列表'!I:K, 2, FALSE), ""), "")))
A37: =B37 & "_" & C37 & IF(D37<>"", "_" & D37, "") & IF(E37<>"", "_" & E37, "") & IF(F37<>"", "_" & F37, "") &"_X"&L37&"_Y"&M37&"_Z"&N37&"_Rail" | C37: Straight | D37: F | E37: Borderless | F37: Caved | H37: (1,0,0), X, [0] | I37: (0,1,0), Y, [0] | J37: (0,-1,0), -Y, [0] | L37: 1 | M37: 1 | N37: 1 | O37: 是 | P37: ✅ | R37: =(1+((L37*M37*N37)-1)*0.1) * ((IF(C37<>"", VLOOKUP(C37,'引用列表'!A:C,3,FALSE), "")) + (IF(D37<>"", VLOOKUP(D37,'引用列表'!E:G,3,FALSE), "")) + (IF(E37<>"", IFERROR(VLOOKUP(E37, '引用列表'!I:K, 3, FALSE), ""), 0)) + (IF(F37<>"", IFERROR(VLOOKUP(F37, '引用列表'!I:K, 3, FALSE), ""), 0))) | S37: =((IF(C37<>"", VLOOKUP(C37,'引用列表'!A:C,2,FALSE), "")) & (IF(D37<>"", VLOOKUP(D37,'引用列表'!E:G,2,FALSE), "")) & (IF(E37<>"", IFERROR("，"&VLOOKUP(E37, '引用列表'!I:K, 2, FALSE), ""), "")) & (IF(F37<>"", IFERROR("，"&VLOOKUP(F37, '引用列表'!I:K, 2, FALSE), ""), "")))
A38: =B38 & "_" & C38 & IF(D38<>"", "_" & D38, "") & IF(E38<>"", "_" & E38, "") & IF(F38<>"", "_" & F38, "") &"_X"&L38&"_Y"&M38&"_Z"&N38&"_Rail" | C38: Straight | D38: F | E38: Borderless_L | F38: HoleInRail | L38: 1 | M38: 1 | N38: 1 | R38: =(1+((L38*M38*N38)-1)*0.1) * ((IF(C38<>"", VLOOKUP(C38,'引用列表'!A:C,3,FALSE), "")) + (IF(D38<>"", VLOOKUP(D38,'引用列表'!E:G,3,FALSE), "")) + (IF(E38<>"", IFERROR(VLOOKUP(E38, '引用列表'!I:K, 3, FALSE), ""), 0)) + (IF(F38<>"", IFERROR(VLOOKUP(F38, '引用列表'!I:K, 3, FALSE), ""), 0))) | S38: =((IF(C38<>"", VLOOKUP(C38,'引用列表'!A:C,2,FALSE), "")) & (IF(D38<>"", VLOOKUP(D38,'引用列表'!E:G,2,FALSE), "")) & (IF(E38<>"", IFERROR("，"&VLOOKUP(E38, '引用列表'!I:K, 2, FALSE), ""), "")) & (IF(F38<>"", IFERROR("，"&VLOOKUP(F38, '引用列表'!I:K, 2, FALSE), ""), "")))
A39: =B39 & "_" & C39 & IF(D39<>"", "_" & D39, "") & IF(E39<>"", "_" & E39, "") & IF(F39<>"", "_" & F39, "") &"_X"&L39&"_Y"&M39&"_Z"&N39&"_Rail" | C39: Straight | D39: F | E39: Borderless_L | H39: 1 | I39: 1 | L39: 1 | M39: 1 | N39: 1 | O39: 镜像源 | P39: ✅ | R39: =(1+((L39*M39*N39)-1)*0.1) * ((IF(C39<>"", VLOOKUP(C39,'引用列表'!A:C,3,FALSE), "")) + (IF(D39<>"", VLOOKUP(D39,'引用列表'!E:G,3,FALSE), "")) + (IF(E39<>"", IFERROR(VLOOKUP(E39, '引用列表'!I:K, 3, FALSE), ""), 0)) + (IF(F39<>"", IFERROR(VLOOKUP(F39, '引用列表'!I:K, 3, FALSE), ""), 0))) | S39: =((IF(C39<>"", VLOOKUP(C39,'引用列表'!A:C,2,FALSE), "")) & (IF(D39<>"", VLOOKUP(D39,'引用列表'!E:G,2,FALSE), "")) & (IF(E39<>"", IFERROR("，"&VLOOKUP(E39, '引用列表'!I:K, 2, FALSE), ""), "")) & (IF(F39<>"", IFERROR("，"&VLOOKUP(F39, '引用列表'!I:K, 2, FALSE), ""), "")))
A40: =B40 & "_" & C40 & IF(D40<>"", "_" & D40, "") & IF(E40<>"", "_" & E40, "") & IF(F40<>"", "_" & F40, "") &"_X"&L40&"_Y"&M40&"_Z"&N40&"_Rail" | C40: Straight | D40: F | E40: Borderless_R | F40: HoleInRail | L40: 1 | M40: 1 | N40: 1 | R40: =(1+((L40*M40*N40)-1)*0.1) * ((IF(C40<>"", VLOOKUP(C40,'引用列表'!A:C,3,FALSE), "")) + (IF(D40<>"", VLOOKUP(D40,'引用列表'!E:G,3,FALSE), "")) + (IF(E40<>"", IFERROR(VLOOKUP(E40, '引用列表'!I:K, 3, FALSE), ""), 0)) + (IF(F40<>"", IFERROR(VLOOKUP(F40, '引用列表'!I:K, 3, FALSE), ""), 0))) | S40: =((IF(C40<>"", VLOOKUP(C40,'引用列表'!A:C,2,FALSE), "")) & (IF(D40<>"", VLOOKUP(D40,'引用列表'!E:G,2,FALSE), "")) & (IF(E40<>"", IFERROR("，"&VLOOKUP(E40, '引用列表'!I:K, 2, FALSE), ""), "")) & (IF(F40<>"", IFERROR("，"&VLOOKUP(F40, '引用列表'!I:K, 2, FALSE), ""), "")))
...

Sheet 过期同步文件
A1: Row Name | B1: Mesh | C1: StartOpeningType | D1: EndOpeningType | E1: LeftOpeningType | F1: RightOpeningType | G1: StartStyleType | H1: EndStyleType | I1: LeftStyleType | J1: RightStyleType | K1: bEndOnly
A2: =IF(VoxelMeshDefinition!AE301="✅", IF(#REF!<>"", #REF!, ""),"") | B2: =IF(VoxelMeshDefinition!AE301="✅", "/Script/Engine.StaticMesh'/Game/Item/Mesh/Voxel/" & VoxelMeshDefinition!Q301 & "/" & VoxelMeshDefinition!H301 & "/" & VoxelMeshDefinition!E301 & "." & VoxelMeshDefinition!E301 & "'", "") | C2: =IF(VoxelMeshDefinition!AE301="✅", IF(VoxelMeshDefinition!T301<>"", VoxelMeshDefinition!T301, ""), "") | D2: =IF(VoxelMeshDefinition!AE301="✅", IF(VoxelMeshDefinition!U301<>"", VoxelMeshDefinition!U301, ""),"") | E2: =IF(VoxelMeshDefinition!AE301="✅", IF(VoxelMeshDefinition!V301<>"", VoxelMeshDefinition!V301, ""),"") | F2: =IF(VoxelMeshDefinition!AE301="✅", IF(VoxelMeshDefinition!W301<>"", VoxelMeshDefinition!W301, ""),"") | G2: =IF(VoxelMeshDefinition!AE301="✅", IF(VoxelMeshDefinition!X301<>"", VoxelMeshDefinition!X301, ""),"") | H2: =IF(VoxelMeshDefinition!AE301="✅", IF(VoxelMeshDefinition!Y301<>"", VoxelMeshDefinition!Y301, ""),"") | I2: =IF(VoxelMeshDefinition!AE301="✅", IF(VoxelMeshDefinition!Z301<>"", VoxelMeshDefinition!Z301, ""),"") | J2: =IF(VoxelMeshDefinition!AE301="✅", IF(VoxelMeshDefinition!AA301<>"", VoxelMeshDefinition!AA301, ""),"") | K2: =IF(VoxelMeshDefinition!AE301="✅", VLOOKUP(A2,VoxelMeshDefinition!S:AE,10,FALSE),"")
A3: =IF(#REF!="✅", IF(#REF!<>"", #REF!, ""),"") | B3: =IF(#REF!="✅", "/Script/Engine.StaticMesh'/Game/Item/Mesh/Voxel/" & #REF! & "/" & #REF! & "/" & #REF! & "." & #REF! & "'", "") | C3: =IF(#REF!="✅", IF(#REF!<>"", #REF!, ""), "") | D3: =IF(#REF!="✅", IF(#REF!<>"", #REF!, ""),"") | E3: =IF(#REF!="✅", IF(#REF!<>"", #REF!, ""),"") | F3: =IF(#REF!="✅", IF(#REF!<>"", #REF!, ""),"") | G3: =IF(#REF!="✅", IF(#REF!<>"", #REF!, ""),"") | H3: =IF(#REF!="✅", IF(#REF!<>"", #REF!, ""),"") | I3: =IF(#REF!="✅", IF(#REF!<>"", #REF!, ""),"") | J3: =IF(#REF!="✅", IF(#REF!<>"", #REF!, ""),"") | K3: =IF(#REF!="✅", VLOOKUP(A3,VoxelMeshDefinition!S:AE,10,FALSE),"")
A4: =IF(#REF!="✅", IF(#REF!<>"", #REF!, ""),"") | B4: =IF(#REF!="✅", "/Script/Engine.StaticMesh'/Game/Item/Mesh/Voxel/" & #REF! & "/" & #REF! & "/" & #REF! & "." & #REF! & "'", "") | C4: =IF(#REF!="✅", IF(#REF!<>"", #REF!, ""), "") | D4: =IF(#REF!="✅", IF(#REF!<>"", #REF!, ""),"") | E4: =IF(#REF!="✅", IF(#REF!<>"", #REF!, ""),"") | F4: =IF(#REF!="✅", IF(#REF!<>"", #REF!, ""),"") | G4: =IF(#REF!="✅", IF(#REF!<>"", #REF!, ""),"") | H4: =IF(#REF!="✅", IF(#REF!<>"", #REF!, ""),"") | I4: =IF(#REF!="✅", IF(#REF!<>"", #REF!, ""),"") | J4: =IF(#REF!="✅", IF(#REF!<>"", #REF!, ""),"") | K4: =IF(#REF!="✅", VLOOKUP(A4,VoxelMeshDefinition!S:AE,10,FALSE),"")
A5: =IF(#REF!="✅", IF(#REF!<>"", #REF!, ""),"") | B5: =IF(#REF!="✅", "/Script/Engine.StaticMesh'/Game/Item/Mesh/Voxel/" & #REF! & "/" & #REF! & "/" & #REF! & "." & #REF! & "'", "") | C5: =IF(#REF!="✅", IF(#REF!<>"", #REF!, ""), "") | D5: =IF(#REF!="✅", IF(#REF!<>"", #REF!, ""),"") | E5: =IF(#REF!="✅", IF(#REF!<>"", #REF!, ""),"") | F5: =IF(#REF!="✅", IF(#REF!<>"", #REF!, ""),"") | G5: =IF(#REF!="✅", IF(#REF!<>"", #REF!, ""),"") | H5: =IF(#REF!="✅", IF(#REF!<>"", #REF!, ""),"") | I5: =IF(#REF!="✅", IF(#REF!<>"", #REF!, ""),"") | J5: =IF(#REF!="✅", IF(#REF!<>"", #REF!, ""),"") | K5: =IF(#REF!="✅", VLOOKUP(A5,VoxelMeshDefinition!S:AE,10,FALSE),"")
A6: =IF(#REF!="✅", IF(#REF!<>"", #REF!, ""),"") | B6: =IF(#REF!="✅", "/Script/Engine.StaticMesh'/Game/Item/Mesh/Voxel/" & #REF! & "/" & #REF! & "/" & #REF! & "." & #REF! & "'", "") | C6: =IF(#REF!="✅", IF(#REF!<>"", #REF!, ""), "") | D6: =IF(#REF!="✅", IF(#REF!<>"", #REF!, ""),"") | E6: =IF(#REF!="✅", IF(#REF!<>"", #REF!, ""),"") | F6: =IF(#REF!="✅", IF(#REF!<>"", #REF!, ""),"") | G6: =IF(#REF!="✅", IF(#REF!<>"", #REF!, ""),"") | H6: =IF(#REF!="✅", IF(#REF!<>"", #REF!, ""),"") | I6: =IF(#REF!="✅", IF(#REF!<>"", #REF!, ""),"") | J6: =IF(#REF!="✅", IF(#REF!<>"", #REF!, ""),"") | K6: =IF(#REF!="✅", VLOOKUP(A6,VoxelMeshDefinition!S:AE,10,FALSE),"")
A7: =IF(#REF!="✅", IF(#REF!<>"", #REF!, ""),"") | B7: =IF(#REF!="✅", "/Script/Engine.StaticMesh'/Game/Item/Mesh/Voxel/" & #REF! & "/" & #REF! & "/" & #REF! & "." & #REF! & "'", "") | C7: =IF(#REF!="✅", IF(#REF!<>"", #REF!, ""), "") | D7: =IF(#REF!="✅", IF(#REF!<>"", #REF!, ""),"") | E7: =IF(#REF!="✅", IF(#REF!<>"", #REF!, ""),"") | F7: =IF(#REF!="✅", IF(#REF!<>"", #REF!, ""),"") | G7: =IF(#REF!="✅", IF(#REF!<>"", #REF!, ""),"") | H7: =IF(#REF!="✅", IF(#REF!<>"", #REF!, ""),"") | I7: =IF(#REF!="✅", IF(#REF!<>"", #REF!, ""),"") | J7: =IF(#REF!="✅", IF(#REF!<>"", #REF!, ""),"") | K7: =IF(#REF!="✅", VLOOKUP(A7,VoxelMeshDefinition!S:AE,10,FALSE),"")
A8: =IF(#REF!="✅", IF(#REF!<>"", #REF!, ""),"") | B8: =IF(#REF!="✅", "/Script/Engine.StaticMesh'/Game/Item/Mesh/Voxel/" & #REF! & "/" & #REF! & "/" & #REF! & "." & #REF! & "'", "") | C8: =IF(#REF!="✅", IF(#REF!<>"", #REF!, ""), "") | D8: =IF(#REF!="✅", IF(#REF!<>"", #REF!, ""),"") | E8: =IF(#REF!="✅", IF(#REF!<>"", #REF!, ""),"") | F8: =IF(#REF!="✅", IF(#REF!<>"", #REF!, ""),"") | G8: =IF(#REF!="✅", IF(#REF!<>"", #REF!, ""),"") | H8: =IF(#REF!="✅", IF(#REF!<>"", #REF!, ""),"") | I8: =IF(#REF!="✅", IF(#REF!<>"", #REF!, ""),"") | J8: =IF(#REF!="✅", IF(#REF!<>"", #REF!, ""),"") | K8: =IF(#REF!="✅", VLOOKUP(A8,VoxelMeshDefinition!S:AE,10,FALSE),"")
A9: =IF(#REF!="✅", IF(#REF!<>"", #REF!, ""),"") | B9: =IF(#REF!="✅", "/Script/Engine.StaticMesh'/Game/Item/Mesh/Voxel/" & #REF! & "/" & #REF! & "/" & #REF! & "." & #REF! & "'", "") | C9: =IF(#REF!="✅", IF(#REF!<>"", #REF!, ""), "") | D9: =IF(#REF!="✅", IF(#REF!<>"", #REF!, ""),"") | E9: =IF(#REF!="✅", IF(#REF!<>"", #REF!, ""),"") | F9: =IF(#REF!="✅", IF(#REF!<>"", #REF!, ""),"") | G9: =IF(#REF!="✅", IF(#REF!<>"", #REF!, ""),"") | H9: =IF(#REF!="✅", IF(#REF!<>"", #REF!, ""),"") | I9: =IF(#REF!="✅", IF(#REF!<>"", #REF!, ""),"") | J9: =IF(#REF!="✅", IF(#REF!<>"", #REF!, ""),"") | K9: =IF(#REF!="✅", VLOOKUP(A9,VoxelMeshDefinition!S:AE,10,FALSE),"")
A10: =IF(#REF!="✅", IF(#REF!<>"", #REF!, ""),"") | B10: =IF(#REF!="✅", "/Script/Engine.StaticMesh'/Game/Item/Mesh/Voxel/" & #REF! & "/" & #REF! & "/" & #REF! & "." & #REF! & "'", "") | C10: =IF(#REF!="✅", IF(#REF!<>"", #REF!, ""), "") | D10: =IF(#REF!="✅", IF(#REF!<>"", #REF!, ""),"") | E10: =IF(#REF!="✅", IF(#REF!<>"", #REF!, ""),"") | F10: =IF(#REF!="✅", IF(#REF!<>"", #REF!, ""),"") | G10: =IF(#REF!="✅", IF(#REF!<>"", #REF!, ""),"") | H10: =IF(#REF!="✅", IF(#REF!<>"", #REF!, ""),"") | I10: =IF(#REF!="✅", IF(#REF!<>"", #REF!, ""),"") | J10: =IF(#REF!="✅", IF(#REF!<>"", #REF!, ""),"") | K10: =IF(#REF!="✅", VLOOKUP(A10,VoxelMeshDefinition!S:AE,10,FALSE),"")
A11: =IF(#REF!="✅", IF(#REF!<>"", #REF!, ""),"") | B11: =IF(#REF!="✅", "/Script/Engine.StaticMesh'/Game/Item/Mesh/Voxel/" & #REF! & "/" & #REF! & "/" & #REF! & "." & #REF! & "'", "") | C11: =IF(#REF!="✅", IF(#REF!<>"", #REF!, ""), "") | D11: =IF(#REF!="✅", IF(#REF!<>"", #REF!, ""),"") | E11: =IF(#REF!="✅", IF(#REF!<>"", #REF!, ""),"") | F11: =IF(#REF!="✅", IF(#REF!<>"", #REF!, ""),"") | G11: =IF(#REF!="✅", IF(#REF!<>"", #REF!, ""),"") | H11: =IF(#REF!="✅", IF(#REF!<>"", #REF!, ""),"") | I11: =IF(#REF!="✅", IF(#REF!<>"", #REF!, ""),"") | J11: =IF(#REF!="✅", IF(#REF!<>"", #REF!, ""),"") | K11: =IF(#REF!="✅", VLOOKUP(A11,VoxelMeshDefinition!S:AE,10,FALSE),"")
A12: =IF(VoxelMeshDefinition!AE250="✅", IF(#REF!<>"", #REF!, ""),"") | B12: =IF(VoxelMeshDefinition!AE250="✅", "/Script/Engine.StaticMesh'/Game/Item/Mesh/Voxel/" & VoxelMeshDefinition!Q250 & "/" & VoxelMeshDefinition!H250 & "/" & VoxelMeshDefinition!E250 & "." & VoxelMeshDefinition!E250 & "'", "") | C12: =IF(VoxelMeshDefinition!AE250="✅", IF(VoxelMeshDefinition!T250<>"", VoxelMeshDefinition!T250, ""), "") | D12: =IF(VoxelMeshDefinition!AE250="✅", IF(VoxelMeshDefinition!U250<>"", VoxelMeshDefinition!U250, ""),"") | E12: =IF(VoxelMeshDefinition!AE250="✅", IF(VoxelMeshDefinition!V250<>"", VoxelMeshDefinition!V250, ""),"") | F12: =IF(VoxelMeshDefinition!AE250="✅", IF(VoxelMeshDefinition!W250<>"", VoxelMeshDefinition!W250, ""),"") | G12: =IF(VoxelMeshDefinition!AE250="✅", IF(VoxelMeshDefinition!X250<>"", VoxelMeshDefinition!X250, ""),"") | H12: =IF(VoxelMeshDefinition!AE250="✅", IF(VoxelMeshDefinition!Y250<>"", VoxelMeshDefinition!Y250, ""),"") | I12: =IF(VoxelMeshDefinition!AE250="✅", IF(VoxelMeshDefinition!Z250<>"", VoxelMeshDefinition!Z250, ""),"") | J12: =IF(VoxelMeshDefinition!AE250="✅", IF(VoxelMeshDefinition!AA250<>"", VoxelMeshDefinition!AA250, ""),"") | K12: =IF(VoxelMeshDefinition!AE250="✅", VLOOKUP(A12,VoxelMeshDefinition!S:AE,10,FALSE),"")
A13: =IF(VoxelMeshDefinition!AE251="✅", IF(#REF!<>"", #REF!, ""),"") | B13: =IF(VoxelMeshDefinition!AE251="✅", "/Script/Engine.StaticMesh'/Game/Item/Mesh/Voxel/" & VoxelMeshDefinition!Q251 & "/" & VoxelMeshDefinition!H251 & "/" & VoxelMeshDefinition!E251 & "." & VoxelMeshDefinition!E251 & "'", "") | C13: =IF(VoxelMeshDefinition!AE251="✅", IF(VoxelMeshDefinition!T251<>"", VoxelMeshDefinition!T251, ""), "") | D13: =IF(VoxelMeshDefinition!AE251="✅", IF(VoxelMeshDefinition!U251<>"", VoxelMeshDefinition!U251, ""),"") | E13: =IF(VoxelMeshDefinition!AE251="✅", IF(VoxelMeshDefinition!V251<>"", VoxelMeshDefinition!V251, ""),"") | F13: =IF(VoxelMeshDefinition!AE251="✅", IF(VoxelMeshDefinition!W251<>"", VoxelMeshDefinition!W251, ""),"") | G13: =IF(VoxelMeshDefinition!AE251="✅", IF(VoxelMeshDefinition!X251<>"", VoxelMeshDefinition!X251, ""),"") | H13: =IF(VoxelMeshDefinition!AE251="✅", IF(VoxelMeshDefinition!Y251<>"", VoxelMeshDefinition!Y251, ""),"") | I13: =IF(VoxelMeshDefinition!AE251="✅", IF(VoxelMeshDefinition!Z251<>"", VoxelMeshDefinition!Z251, ""),"") | J13: =IF(VoxelMeshDefinition!AE251="✅", IF(VoxelMeshDefinition!AA251<>"", VoxelMeshDefinition!AA251, ""),"") | K13: =IF(VoxelMeshDefinition!AE251="✅", VLOOKUP(A13,VoxelMeshDefinition!S:AE,10,FALSE),"")
A14: =IF(VoxelMeshDefinition!AE252="✅", IF(#REF!<>"", #REF!, ""),"") | B14: =IF(VoxelMeshDefinition!AE252="✅", "/Script/Engine.StaticMesh'/Game/Item/Mesh/Voxel/" & VoxelMeshDefinition!Q252 & "/" & VoxelMeshDefinition!H252 & "/" & VoxelMeshDefinition!E252 & "." & VoxelMeshDefinition!E252 & "'", "") | C14: =IF(VoxelMeshDefinition!AE252="✅", IF(VoxelMeshDefinition!T252<>"", VoxelMeshDefinition!T252, ""), "") | D14: =IF(VoxelMeshDefinition!AE252="✅", IF(VoxelMeshDefinition!U252<>"", VoxelMeshDefinition!U252, ""),"") | E14: =IF(VoxelMeshDefinition!AE252="✅", IF(VoxelMeshDefinition!V252<>"", VoxelMeshDefinition!V252, ""),"") | F14: =IF(VoxelMeshDefinition!AE252="✅", IF(VoxelMeshDefinition!W252<>"", VoxelMeshDefinition!W252, ""),"") | G14: =IF(VoxelMeshDefinition!AE252="✅", IF(VoxelMeshDefinition!X252<>"", VoxelMeshDefinition!X252, ""),"") | H14: =IF(VoxelMeshDefinition!AE252="✅", IF(VoxelMeshDefinition!Y252<>"", VoxelMeshDefinition!Y252, ""),"") | I14: =IF(VoxelMeshDefinition!AE252="✅", IF(VoxelMeshDefinition!Z252<>"", VoxelMeshDefinition!Z252, ""),"") | J14: =IF(VoxelMeshDefinition!AE252="✅", IF(VoxelMeshDefinition!AA252<>"", VoxelMeshDefinition!AA252, ""),"") | K14: =IF(VoxelMeshDefinition!AE252="✅", VLOOKUP(A14,VoxelMeshDefinition!S:AE,10,FALSE),"")
A15: =IF(VoxelMeshDefinition!AE121="✅", IF(#REF!<>"", #REF!, ""),"") | B15: =IF(VoxelMeshDefinition!AE121="✅", "/Script/Engine.StaticMesh'/Game/Item/Mesh/Voxel/" & VoxelMeshDefinition!Q121 & "/" & VoxelMeshDefinition!H121 & "/" & VoxelMeshDefinition!E121 & "." & VoxelMeshDefinition!E121 & "'", "") | C15: =IF(VoxelMeshDefinition!AE121="✅", IF(VoxelMeshDefinition!T121<>"", VoxelMeshDefinition!T121, ""), "") | D15: =IF(VoxelMeshDefinition!AE121="✅", IF(VoxelMeshDefinition!U121<>"", VoxelMeshDefinition!U121, ""),"") | E15: =IF(VoxelMeshDefinition!AE121="✅", IF(VoxelMeshDefinition!V121<>"", VoxelMeshDefinition!V121, ""),"") | F15: =IF(VoxelMeshDefinition!AE121="✅", IF(VoxelMeshDefinition!W121<>"", VoxelMeshDefinition!W121, ""),"") | G15: =IF(VoxelMeshDefinition!AE121="✅", IF(VoxelMeshDefinition!X121<>"", VoxelMeshDefinition!X121, ""),"") | H15: =IF(VoxelMeshDefinition!AE121="✅", IF(VoxelMeshDefinition!Y121<>"", VoxelMeshDefinition!Y121, ""),"") | I15: =IF(VoxelMeshDefinition!AE121="✅", IF(VoxelMeshDefinition!Z121<>"", VoxelMeshDefinition!Z121, ""),"") | J15: =IF(VoxelMeshDefinition!AE121="✅", IF(VoxelMeshDefinition!AA121<>"", VoxelMeshDefinition!AA121, ""),"") | K15: =IF(VoxelMeshDefinition!AE121="✅", VLOOKUP(A15,VoxelMeshDefinition!S:AE,10,FALSE),"")
A16: =IF(VoxelMeshDefinition!AE122="✅", IF(#REF!<>"", #REF!, ""),"") | B16: =IF(VoxelMeshDefinition!AE122="✅", "/Script/Engine.StaticMesh'/Game/Item/Mesh/Voxel/" & VoxelMeshDefinition!Q122 & "/" & VoxelMeshDefinition!H122 & "/" & VoxelMeshDefinition!E122 & "." & VoxelMeshDefinition!E122 & "'", "") | C16: =IF(VoxelMeshDefinition!AE122="✅", IF(VoxelMeshDefinition!T122<>"", VoxelMeshDefinition!T122, ""), "") | D16: =IF(VoxelMeshDefinition!AE122="✅", IF(VoxelMeshDefinition!U122<>"", VoxelMeshDefinition!U122, ""),"") | E16: =IF(VoxelMeshDefinition!AE122="✅", IF(VoxelMeshDefinition!V122<>"", VoxelMeshDefinition!V122, ""),"") | F16: =IF(VoxelMeshDefinition!AE122="✅", IF(VoxelMeshDefinition!W122<>"", VoxelMeshDefinition!W122, ""),"") | G16: =IF(VoxelMeshDefinition!AE122="✅", IF(VoxelMeshDefinition!X122<>"", VoxelMeshDefinition!X122, ""),"") | H16: =IF(VoxelMeshDefinition!AE122="✅", IF(VoxelMeshDefinition!Y122<>"", VoxelMeshDefinition!Y122, ""),"") | I16: =IF(VoxelMeshDefinition!AE122="✅", IF(VoxelMeshDefinition!Z122<>"", VoxelMeshDefinition!Z122, ""),"") | J16: =IF(VoxelMeshDefinition!AE122="✅", IF(VoxelMeshDefinition!AA122<>"", VoxelMeshDefinition!AA122, ""),"") | K16: =IF(VoxelMeshDefinition!AE122="✅", VLOOKUP(A16,VoxelMeshDefinition!S:AE,10,FALSE),"")
A17: =IF(VoxelMeshDefinition!AE123="✅", IF(#REF!<>"", #REF!, ""),"") | B17: =IF(VoxelMeshDefinition!AE123="✅", "/Script/Engine.StaticMesh'/Game/Item/Mesh/Voxel/" & VoxelMeshDefinition!Q123 & "/" & VoxelMeshDefinition!H123 & "/" & VoxelMeshDefinition!E123 & "." & VoxelMeshDefinition!E123 & "'", "") | C17: =IF(VoxelMeshDefinition!AE123="✅", IF(VoxelMeshDefinition!T123<>"", VoxelMeshDefinition!T123, ""), "") | D17: =IF(VoxelMeshDefinition!AE123="✅", IF(VoxelMeshDefinition!U123<>"", VoxelMeshDefinition!U123, ""),"") | E17: =IF(VoxelMeshDefinition!AE123="✅", IF(VoxelMeshDefinition!V123<>"", VoxelMeshDefinition!V123, ""),"") | F17: =IF(VoxelMeshDefinition!AE123="✅", IF(VoxelMeshDefinition!W123<>"", VoxelMeshDefinition!W123, ""),"") | G17: =IF(VoxelMeshDefinition!AE123="✅", IF(VoxelMeshDefinition!X123<>"", VoxelMeshDefinition!X123, ""),"") | H17: =IF(VoxelMeshDefinition!AE123="✅", IF(VoxelMeshDefinition!Y123<>"", VoxelMeshDefinition!Y123, ""),"") | I17: =IF(VoxelMeshDefinition!AE123="✅", IF(VoxelMeshDefinition!Z123<>"", VoxelMeshDefinition!Z123, ""),"") | J17: =IF(VoxelMeshDefinition!AE123="✅", IF(VoxelMeshDefinition!AA123<>"", VoxelMeshDefinition!AA123, ""),"") | K17: =IF(VoxelMeshDefinition!AE123="✅", VLOOKUP(A17,VoxelMeshDefinition!S:AE,10,FALSE),"")
A18: =IF(VoxelMeshDefinition!AE124="✅", IF(#REF!<>"", #REF!, ""),"") | B18: =IF(VoxelMeshDefinition!AE124="✅", "/Script/Engine.StaticMesh'/Game/Item/Mesh/Voxel/" & VoxelMeshDefinition!Q124 & "/" & VoxelMeshDefinition!H124 & "/" & VoxelMeshDefinition!E124 & "." & VoxelMeshDefinition!E124 & "'", "") | C18: =IF(VoxelMeshDefinition!AE124="✅", IF(VoxelMeshDefinition!T124<>"", VoxelMeshDefinition!T124, ""), "") | D18: =IF(VoxelMeshDefinition!AE124="✅", IF(VoxelMeshDefinition!U124<>"", VoxelMeshDefinition!U124, ""),"") | E18: =IF(VoxelMeshDefinition!AE124="✅", IF(VoxelMeshDefinition!V124<>"", VoxelMeshDefinition!V124, ""),"") | F18: =IF(VoxelMeshDefinition!AE124="✅", IF(VoxelMeshDefinition!W124<>"", VoxelMeshDefinition!W124, ""),"") | G18: =IF(VoxelMeshDefinition!AE124="✅", IF(VoxelMeshDefinition!X124<>"", VoxelMeshDefinition!X124, ""),"") | H18: =IF(VoxelMeshDefinition!AE124="✅", IF(VoxelMeshDefinition!Y124<>"", VoxelMeshDefinition!Y124, ""),"") | I18: =IF(VoxelMeshDefinition!AE124="✅", IF(VoxelMeshDefinition!Z124<>"", VoxelMeshDefinition!Z124, ""),"") | J18: =IF(VoxelMeshDefinition!AE124="✅", IF(VoxelMeshDefinition!AA124<>"", VoxelMeshDefinition!AA124, ""),"") | K18: =IF(VoxelMeshDefinition!AE124="✅", VLOOKUP(A18,VoxelMeshDefinition!S:AE,10,FALSE),"")
A19: =IF(VoxelMeshDefinition!AE125="✅", IF(#REF!<>"", #REF!, ""),"") | B19: =IF(VoxelMeshDefinition!AE125="✅", "/Script/Engine.StaticMesh'/Game/Item/Mesh/Voxel/" & VoxelMeshDefinition!Q125 & "/" & VoxelMeshDefinition!H125 & "/" & VoxelMeshDefinition!E125 & "." & VoxelMeshDefinition!E125 & "'", "") | C19: =IF(VoxelMeshDefinition!AE125="✅", IF(VoxelMeshDefinition!T125<>"", VoxelMeshDefinition!T125, ""), "") | D19: =IF(VoxelMeshDefinition!AE125="✅", IF(VoxelMeshDefinition!U125<>"", VoxelMeshDefinition!U125, ""),"") | E19: =IF(VoxelMeshDefinition!AE125="✅", IF(VoxelMeshDefinition!V125<>"", VoxelMeshDefinition!V125, ""),"") | F19: =IF(VoxelMeshDefinition!AE125="✅", IF(VoxelMeshDefinition!W125<>"", VoxelMeshDefinition!W125, ""),"") | G19: =IF(VoxelMeshDefinition!AE125="✅", IF(VoxelMeshDefinition!X125<>"", VoxelMeshDefinition!X125, ""),"") | H19: =IF(VoxelMeshDefinition!AE125="✅", IF(VoxelMeshDefinition!Y125<>"", VoxelMeshDefinition!Y125, ""),"") | I19: =IF(VoxelMeshDefinition!AE125="✅", IF(VoxelMeshDefinition!Z125<>"", VoxelMeshDefinition!Z125, ""),"") | J19: =IF(VoxelMeshDefinition!AE125="✅", IF(VoxelMeshDefinition!AA125<>"", VoxelMeshDefinition!AA125, ""),"") | K19: =IF(VoxelMeshDefinition!AE125="✅", VLOOKUP(A19,VoxelMeshDefinition!S:AE,10,FALSE),"")
A20: =IF(VoxelMeshDefinition!AE128="✅", IF(#REF!<>"", #REF!, ""),"") | B20: =IF(VoxelMeshDefinition!AE128="✅", "/Script/Engine.StaticMesh'/Game/Item/Mesh/Voxel/" & VoxelMeshDefinition!Q128 & "/" & VoxelMeshDefinition!H128 & "/" & VoxelMeshDefinition!E128 & "." & VoxelMeshDefinition!E128 & "'", "") | C20: =IF(VoxelMeshDefinition!AE128="✅", IF(VoxelMeshDefinition!T128<>"", VoxelMeshDefinition!T128, ""), "") | D20: =IF(VoxelMeshDefinition!AE128="✅", IF(VoxelMeshDefinition!U128<>"", VoxelMeshDefinition!U128, ""),"") | E20: =IF(VoxelMeshDefinition!AE128="✅", IF(VoxelMeshDefinition!V128<>"", VoxelMeshDefinition!V128, ""),"") | F20: =IF(VoxelMeshDefinition!AE128="✅", IF(VoxelMeshDefinition!W128<>"", VoxelMeshDefinition!W128, ""),"") | G20: =IF(VoxelMeshDefinition!AE128="✅", IF(VoxelMeshDefinition!X128<>"", VoxelMeshDefinition!X128, ""),"") | H20: =IF(VoxelMeshDefinition!AE128="✅", IF(VoxelMeshDefinition!Y128<>"", VoxelMeshDefinition!Y128, ""),"") | I20: =IF(VoxelMeshDefinition!AE128="✅", IF(VoxelMeshDefinition!Z128<>"", VoxelMeshDefinition!Z128, ""),"") | J20: =IF(VoxelMeshDefinition!AE128="✅", IF(VoxelMeshDefinition!AA128<>"", VoxelMeshDefinition!AA128, ""),"") | K20: =IF(VoxelMeshDefinition!AE128="✅", VLOOKUP(A20,VoxelMeshDefinition!S:AE,10,FALSE),"")
A21: =IF(VoxelMeshDefinition!AE129="✅", IF(#REF!<>"", #REF!, ""),"") | B21: =IF(VoxelMeshDefinition!AE129="✅", "/Script/Engine.StaticMesh'/Game/Item/Mesh/Voxel/" & VoxelMeshDefinition!Q129 & "/" & VoxelMeshDefinition!H129 & "/" & VoxelMeshDefinition!E129 & "." & VoxelMeshDefinition!E129 & "'", "") | C21: =IF(VoxelMeshDefinition!AE129="✅", IF(VoxelMeshDefinition!T129<>"", VoxelMeshDefinition!T129, ""), "") | D21: =IF(VoxelMeshDefinition!AE129="✅", IF(VoxelMeshDefinition!U129<>"", VoxelMeshDefinition!U129, ""),"") | E21: =IF(VoxelMeshDefinition!AE129="✅", IF(VoxelMeshDefinition!V129<>"", VoxelMeshDefinition!V129, ""),"") | F21: =IF(VoxelMeshDefinition!AE129="✅", IF(VoxelMeshDefinition!W129<>"", VoxelMeshDefinition!W129, ""),"") | G21: =IF(VoxelMeshDefinition!AE129="✅", IF(VoxelMeshDefinition!X129<>"", VoxelMeshDefinition!X129, ""),"") | H21: =IF(VoxelMeshDefinition!AE129="✅", IF(VoxelMeshDefinition!Y129<>"", VoxelMeshDefinition!Y129, ""),"") | I21: =IF(VoxelMeshDefinition!AE129="✅", IF(VoxelMeshDefinition!Z129<>"", VoxelMeshDefinition!Z129, ""),"") | J21: =IF(VoxelMeshDefinition!AE129="✅", IF(VoxelMeshDefinition!AA129<>"", VoxelMeshDefinition!AA129, ""),"") | K21: =IF(VoxelMeshDefinition!AE129="✅", VLOOKUP(A21,VoxelMeshDefinition!S:AE,10,FALSE),"")
A22: =IF(VoxelMeshDefinition!AE130="✅", IF(#REF!<>"", #REF!, ""),"") | B22: =IF(VoxelMeshDefinition!AE130="✅", "/Script/Engine.StaticMesh'/Game/Item/Mesh/Voxel/" & VoxelMeshDefinition!Q130 & "/" & VoxelMeshDefinition!H130 & "/" & VoxelMeshDefinition!E130 & "." & VoxelMeshDefinition!E130 & "'", "") | C22: =IF(VoxelMeshDefinition!AE130="✅", IF(VoxelMeshDefinition!T130<>"", VoxelMeshDefinition!T130, ""), "") | D22: =IF(VoxelMeshDefinition!AE130="✅", IF(VoxelMeshDefinition!U130<>"", VoxelMeshDefinition!U130, ""),"") | E22: =IF(VoxelMeshDefinition!AE130="✅", IF(VoxelMeshDefinition!V130<>"", VoxelMeshDefinition!V130, ""),"") | F22: =IF(VoxelMeshDefinition!AE130="✅", IF(VoxelMeshDefinition!W130<>"", VoxelMeshDefinition!W130, ""),"") | G22: =IF(VoxelMeshDefinition!AE130="✅", IF(VoxelMeshDefinition!X130<>"", VoxelMeshDefinition!X130, ""),"") | H22: =IF(VoxelMeshDefinition!AE130="✅", IF(VoxelMeshDefinition!Y130<>"", VoxelMeshDefinition!Y130, ""),"") | I22: =IF(VoxelMeshDefinition!AE130="✅", IF(VoxelMeshDefinition!Z130<>"", VoxelMeshDefinition!Z130, ""),"") | J22: =IF(VoxelMeshDefinition!AE130="✅", IF(VoxelMeshDefinition!AA130<>"", VoxelMeshDefinition!AA130, ""),"") | K22: =IF(VoxelMeshDefinition!AE130="✅", VLOOKUP(A22,VoxelMeshDefinition!S:AE,10,FALSE),"")
A23: =IF(VoxelMeshDefinition!AE131="✅", IF(#REF!<>"", #REF!, ""),"") | B23: =IF(VoxelMeshDefinition!AE131="✅", "/Script/Engine.StaticMesh'/Game/Item/Mesh/Voxel/" & VoxelMeshDefinition!Q131 & "/" & VoxelMeshDefinition!H131 & "/" & VoxelMeshDefinition!E131 & "." & VoxelMeshDefinition!E131 & "'", "") | C23: =IF(VoxelMeshDefinition!AE131="✅", IF(VoxelMeshDefinition!T131<>"", VoxelMeshDefinition!T131, ""), "") | D23: =IF(VoxelMeshDefinition!AE131="✅", IF(VoxelMeshDefinition!U131<>"", VoxelMeshDefinition!U131, ""),"") | E23: =IF(VoxelMeshDefinition!AE131="✅", IF(VoxelMeshDefinition!V131<>"", VoxelMeshDefinition!V131, ""),"") | F23: =IF(VoxelMeshDefinition!AE131="✅", IF(VoxelMeshDefinition!W131<>"", VoxelMeshDefinition!W131, ""),"") | G23: =IF(VoxelMeshDefinition!AE131="✅", IF(VoxelMeshDefinition!X131<>"", VoxelMeshDefinition!X131, ""),"") | H23: =IF(VoxelMeshDefinition!AE131="✅", IF(VoxelMeshDefinition!Y131<>"", VoxelMeshDefinition!Y131, ""),"") | I23: =IF(VoxelMeshDefinition!AE131="✅", IF(VoxelMeshDefinition!Z131<>"", VoxelMeshDefinition!Z131, ""),"") | J23: =IF(VoxelMeshDefinition!AE131="✅", IF(VoxelMeshDefinition!AA131<>"", VoxelMeshDefinition!AA131, ""),"") | K23: =IF(VoxelMeshDefinition!AE131="✅", VLOOKUP(A23,VoxelMeshDefinition!S:AE,10,FALSE),"")
A24: =IF(VoxelMeshDefinition!AE132="✅", IF(#REF!<>"", #REF!, ""),"") | B24: =IF(VoxelMeshDefinition!AE132="✅", "/Script/Engine.StaticMesh'/Game/Item/Mesh/Voxel/" & VoxelMeshDefinition!Q132 & "/" & VoxelMeshDefinition!H132 & "/" & VoxelMeshDefinition!E132 & "." & VoxelMeshDefinition!E132 & "'", "") | C24: =IF(VoxelMeshDefinition!AE132="✅", IF(VoxelMeshDefinition!T132<>"", VoxelMeshDefinition!T132, ""), "") | D24: =IF(VoxelMeshDefinition!AE132="✅", IF(VoxelMeshDefinition!U132<>"", VoxelMeshDefinition!U132, ""),"") | E24: =IF(VoxelMeshDefinition!AE132="✅", IF(VoxelMeshDefinition!V132<>"", VoxelMeshDefinition!V132, ""),"") | F24: =IF(VoxelMeshDefinition!AE132="✅", IF(VoxelMeshDefinition!W132<>"", VoxelMeshDefinition!W132, ""),"") | G24: =IF(VoxelMeshDefinition!AE132="✅", IF(VoxelMeshDefinition!X132<>"", VoxelMeshDefinition!X132, ""),"") | H24: =IF(VoxelMeshDefinition!AE132="✅", IF(VoxelMeshDefinition!Y132<>"", VoxelMeshDefinition!Y132, ""),"") | I24: =IF(VoxelMeshDefinition!AE132="✅", IF(VoxelMeshDefinition!Z132<>"", VoxelMeshDefinition!Z132, ""),"") | J24: =IF(VoxelMeshDefinition!AE132="✅", IF(VoxelMeshDefinition!AA132<>"", VoxelMeshDefinition!AA132, ""),"") | K24: =IF(VoxelMeshDefinition!AE132="✅", VLOOKUP(A24,VoxelMeshDefinition!S:AE,10,FALSE),"")
A25: =IF(VoxelMeshDefinition!AE91="✅", IF(#REF!<>"", #REF!, ""),"") | B25: =IF(VoxelMeshDefinition!AE91="✅", "/Script/Engine.StaticMesh'/Game/Item/Mesh/Voxel/" & VoxelMeshDefinition!Q91 & "/" & VoxelMeshDefinition!H91 & "/" & VoxelMeshDefinition!E91 & "." & VoxelMeshDefinition!E91 & "'", "") | C25: =IF(VoxelMeshDefinition!AE91="✅", IF(VoxelMeshDefinition!T91<>"", VoxelMeshDefinition!T91, ""), "") | D25: =IF(VoxelMeshDefinition!AE91="✅", IF(VoxelMeshDefinition!U91<>"", VoxelMeshDefinition!U91, ""),"") | E25: =IF(VoxelMeshDefinition!AE91="✅", IF(VoxelMeshDefinition!V91<>"", VoxelMeshDefinition!V91, ""),"") | F25: =IF(VoxelMeshDefinition!AE91="✅", IF(VoxelMeshDefinition!W91<>"", VoxelMeshDefinition!W91, ""),"") | G25: =IF(VoxelMeshDefinition!AE91="✅", IF(VoxelMeshDefinition!X91<>"", VoxelMeshDefinition!X91, ""),"") | H25: =IF(VoxelMeshDefinition!AE91="✅", IF(VoxelMeshDefinition!Y91<>"", VoxelMeshDefinition!Y91, ""),"") | I25: =IF(VoxelMeshDefinition!AE91="✅", IF(VoxelMeshDefinition!Z91<>"", VoxelMeshDefinition!Z91, ""),"") | J25: =IF(VoxelMeshDefinition!AE91="✅", IF(VoxelMeshDefinition!AA91<>"", VoxelMeshDefinition!AA91, ""),"") | K25: =IF(VoxelMeshDefinition!AE91="✅", VLOOKUP(A25,VoxelMeshDefinition!S:AE,10,FALSE),"")
A26: =IF(VoxelMeshDefinition!AE92="✅", IF(#REF!<>"", #REF!, ""),"") | B26: =IF(VoxelMeshDefinition!AE92="✅", "/Script/Engine.StaticMesh'/Game/Item/Mesh/Voxel/" & VoxelMeshDefinition!Q92 & "/" & VoxelMeshDefinition!H92 & "/" & VoxelMeshDefinition!E92 & "." & VoxelMeshDefinition!E92 & "'", "") | C26: =IF(VoxelMeshDefinition!AE92="✅", IF(VoxelMeshDefinition!T92<>"", VoxelMeshDefinition!T92, ""), "") | D26: =IF(VoxelMeshDefinition!AE92="✅", IF(VoxelMeshDefinition!U92<>"", VoxelMeshDefinition!U92, ""),"") | E26: =IF(VoxelMeshDefinition!AE92="✅", IF(VoxelMeshDefinition!V92<>"", VoxelMeshDefinition!V92, ""),"") | F26: =IF(VoxelMeshDefinition!AE92="✅", IF(VoxelMeshDefinition!W92<>"", VoxelMeshDefinition!W92, ""),"") | G26: =IF(VoxelMeshDefinition!AE92="✅", IF(VoxelMeshDefinition!X92<>"", VoxelMeshDefinition!X92, ""),"") | H26: =IF(VoxelMeshDefinition!AE92="✅", IF(VoxelMeshDefinition!Y92<>"", VoxelMeshDefinition!Y92, ""),"") | I26: =IF(VoxelMeshDefinition!AE92="✅", IF(VoxelMeshDefinition!Z92<>"", VoxelMeshDefinition!Z92, ""),"") | J26: =IF(VoxelMeshDefinition!AE92="✅", IF(VoxelMeshDefinition!AA92<>"", VoxelMeshDefinition!AA92, ""),"") | K26: =IF(VoxelMeshDefinition!AE92="✅", VLOOKUP(A26,VoxelMeshDefinition!S:AE,10,FALSE),"")
A27: =IF(VoxelMeshDefinition!AE93="✅", IF(#REF!<>"", #REF!, ""),"") | B27: =IF(VoxelMeshDefinition!AE93="✅", "/Script/Engine.StaticMesh'/Game/Item/Mesh/Voxel/" & VoxelMeshDefinition!Q93 & "/" & VoxelMeshDefinition!H93 & "/" & VoxelMeshDefinition!E93 & "." & VoxelMeshDefinition!E93 & "'", "") | C27: =IF(VoxelMeshDefinition!AE93="✅", IF(VoxelMeshDefinition!T93<>"", VoxelMeshDefinition!T93, ""), "") | D27: =IF(VoxelMeshDefinition!AE93="✅", IF(VoxelMeshDefinition!U93<>"", VoxelMeshDefinition!U93, ""),"") | E27: =IF(VoxelMeshDefinition!AE93="✅", IF(VoxelMeshDefinition!V93<>"", VoxelMeshDefinition!V93, ""),"") | F27: =IF(VoxelMeshDefinition!AE93="✅", IF(VoxelMeshDefinition!W93<>"", VoxelMeshDefinition!W93, ""),"") | G27: =IF(VoxelMeshDefinition!AE93="✅", IF(VoxelMeshDefinition!X93<>"", VoxelMeshDefinition!X93, ""),"") | H27: =IF(VoxelMeshDefinition!AE93="✅", IF(VoxelMeshDefinition!Y93<>"", VoxelMeshDefinition!Y93, ""),"") | I27: =IF(VoxelMeshDefinition!AE93="✅", IF(VoxelMeshDefinition!Z93<>"", VoxelMeshDefinition!Z93, ""),"") | J27: =IF(VoxelMeshDefinition!AE93="✅", IF(VoxelMeshDefinition!AA93<>"", VoxelMeshDefinition!AA93, ""),"") | K27: =IF(VoxelMeshDefinition!AE93="✅", VLOOKUP(A27,VoxelMeshDefinition!S:AE,10,FALSE),"")
A28: =IF(VoxelMeshDefinition!AE95="✅", IF(#REF!<>"", #REF!, ""),"") | B28: =IF(VoxelMeshDefinition!AE95="✅", "/Script/Engine.StaticMesh'/Game/Item/Mesh/Voxel/" & VoxelMeshDefinition!Q95 & "/" & VoxelMeshDefinition!H95 & "/" & VoxelMeshDefinition!E95 & "." & VoxelMeshDefinition!E95 & "'", "") | C28: =IF(VoxelMeshDefinition!AE95="✅", IF(VoxelMeshDefinition!T95<>"", VoxelMeshDefinition!T95, ""), "") | D28: =IF(VoxelMeshDefinition!AE95="✅", IF(VoxelMeshDefinition!U95<>"", VoxelMeshDefinition!U95, ""),"") | E28: =IF(VoxelMeshDefinition!AE95="✅", IF(VoxelMeshDefinition!V95<>"", VoxelMeshDefinition!V95, ""),"") | F28: =IF(VoxelMeshDefinition!AE95="✅", IF(VoxelMeshDefinition!W95<>"", VoxelMeshDefinition!W95, ""),"") | G28: =IF(VoxelMeshDefinition!AE95="✅", IF(VoxelMeshDefinition!X95<>"", VoxelMeshDefinition!X95, ""),"") | H28: =IF(VoxelMeshDefinition!AE95="✅", IF(VoxelMeshDefinition!Y95<>"", VoxelMeshDefinition!Y95, ""),"") | I28: =IF(VoxelMeshDefinition!AE95="✅", IF(VoxelMeshDefinition!Z95<>"", VoxelMeshDefinition!Z95, ""),"") | J28: =IF(VoxelMeshDefinition!AE95="✅", IF(VoxelMeshDefinition!AA95<>"", VoxelMeshDefinition!AA95, ""),"") | K28: =IF(VoxelMeshDefinition!AE95="✅", VLOOKUP(A28,VoxelMeshDefinition!S:AE,10,FALSE),"")
A29: =IF(VoxelMeshDefinition!AE248="✅", IF(#REF!<>"", #REF!, ""),"") | B29: =IF(VoxelMeshDefinition!AE248="✅", "/Script/Engine.StaticMesh'/Game/Item/Mesh/Voxel/" & VoxelMeshDefinition!Q248 & "/" & VoxelMeshDefinition!H248 & "/" & VoxelMeshDefinition!E248 & "." & VoxelMeshDefinition!E248 & "'", "") | C29: =IF(VoxelMeshDefinition!AE248="✅", IF(VoxelMeshDefinition!T248<>"", VoxelMeshDefinition!T248, ""), "") | D29: =IF(VoxelMeshDefinition!AE248="✅", IF(VoxelMeshDefinition!U248<>"", VoxelMeshDefinition!U248, ""),"") | E29: =IF(VoxelMeshDefinition!AE248="✅", IF(VoxelMeshDefinition!V248<>"", VoxelMeshDefinition!V248, ""),"") | F29: =IF(VoxelMeshDefinition!AE248="✅", IF(VoxelMeshDefinition!W248<>"", VoxelMeshDefinition!W248, ""),"") | G29: =IF(VoxelMeshDefinition!AE248="✅", IF(VoxelMeshDefinition!X248<>"", VoxelMeshDefinition!X248, ""),"") | H29: =IF(VoxelMeshDefinition!AE248="✅", IF(VoxelMeshDefinition!Y248<>"", VoxelMeshDefinition!Y248, ""),"") | I29: =IF(VoxelMeshDefinition!AE248="✅", IF(VoxelMeshDefinition!Z248<>"", VoxelMeshDefinition!Z248, ""),"") | J29: =IF(VoxelMeshDefinition!AE248="✅", IF(VoxelMeshDefinition!AA248<>"", VoxelMeshDefinition!AA248, ""),"") | K29: =IF(VoxelMeshDefinition!AE248="✅", VLOOKUP(A29,VoxelMeshDefinition!S:AE,10,FALSE),"")
