Workbook

Sheet 引用数据库
A1: Party | B1: 阵营 | C1: 模型资产命名 | D1: 模型资产描述 | E1: 模型注释A命名 | F1: 模型注释A描述 | G1: 模型注释B命名 | H1: 模型注释B描述
A2: Generic | B2: 通用 | C2: Wall | D2: 墙壁 | E2: Single | F2: 单体 | G2: Side | H2: 侧边
A3: Prototype | B3: 白模 | C3: Window | D3: 带窗墙壁 | E3: Small | F3: 小型 | G3: Center | H3: 中央
A4: Monument | B4: 纪念碑 | C4: Floor | D4: 地板 | E4: Mid | F4: 中型 | G4: HalfThick | H4: 半厚
A5: WildWatch | B5: 野望 | C5: Door | D5: 门 | E5: Big | F5: 大型 | G5: Left | H5: 左侧
A6: Labor | B6: 劳旅 | C6: DoorFrame | D6: 门框 | E6: Large | F6: 巨型 | G6: Right | H6: 右侧
A7: SynPu | B7: 新浦会 | C7: DoorWall | D7: 带门洞墙壁 | E7: Square | F7: 矩形 | G7: SingleFace | H7: 单面
A8: LockHeader | B8: 洛克海德 | C8: Arch | D8: 拱门 | E8: Triangle | F8: 三角形 | G8: DoubleFace | H8: 双面
B9: 寰宇 | C9: Deco | D9: 装饰 | E9: LevelControl | F9: 关卡切换 | G9: InDoor | H9: 室内
B10: 东海工业 | C10: Block | D10: 障碍 | E10: Escape | F10: 逃生 | G10: OutDoor | H10: 室外
B11: 耶利哥 | C11: Lift | D11: 电梯 | E11: Normal | F11: 普通 | G11: BulletProof | H11: 不可破坏
B12: 律动智能 | C12: Balcony | D12: 阳台 | E12: AmmoVEM | F12: 子弹
B13: 致远生物 | C13: Reward | D13: 奖励 | E13: WeaponPrinter | F13: 武器
C14: SectionGate | D14: 区域门 | E14: Low | F14: 矮
C15: Pillar | D15: 支柱 | E15: High | F15: 高
E16: SuperHigh | F16: 超高
E17: Diagonal | F17: 斜对角
E18: Center | F18: 中央
E19: Side | F19: 侧面
E20: Corner | F20: 角落
E21: Long | F21: 长条

Sheet 模型资产表
E1: 蓝图 | F1: 模型 | G1: 材质命名 | H1: 贴图命名 | I1: 阵营 | J1: 对象类型 | K1: 注释 A | L1: 注释 B | M1: 注释 C | N1: 注释 D | O1: 序号 E | P1: UE-X | Q1: UE-X | R1: UE-Z | S1: BP | T1: SM | U1: 原点位置
A2: Labor | E2: =IF(I2="","", "BP_" & I2 & IF(J2<>"", "_" & J2, "") & IF(K2<>"", "_" & K2, "") & IF(L2<>"", "_" & L2, "") & IF(M2<>"", "_" & M2, "") & IF(P2<>"", "_X" & P2, "") & IF(Q2<>"", "_Y" & Q2, "") & IF(R2<>"", "_Z" & R2, "") & IF(N2<>"", "_" & N2, "") & IF(O2<>"", "_" & O2, "")) | F2: =IF(I2="","", "SM_" & I2 & IF(J2<>"", "_" & J2, "") & IF(K2<>"", "_" & K2, "") & IF(L2<>"", "_" & L2, "") & IF(M2<>"", "_" & M2, "") & IF(P2<>"", "_X" & P2, "") & IF(Q2<>"", "_Y" & Q2, "") & IF(R2<>"", "_Z" & R2, "") & IF(N2<>"", "_" & N2, "") & IF(O2<>"", "_" & O2, ""))
B3: Interactable
C4: Balcony
C5: Door
E6: =IF(I6="","", "BP_" & I6 & IF(J6<>"", "_" & J6, "") & IF(K6<>"", "_" & K6, "") & IF(L6<>"", "_" & L6, "") & IF(M6<>"", "_" & M6, "") & IF(P6<>"", "_X" & P6, "") & IF(Q6<>"", "_Y" & Q6, "") & IF(R6<>"", "_Z" & R6, "") & IF(N6<>"", "_" & N6, "") & IF(O6<>"", "_" & O6, "")) | I6: Labor | J6: Door | O6: 001 | P6: 110 | Q6: 35 | R6: 250
F7: =IF(I7="","", "SM_" & I7 & IF(J7<>"", "_" & J7, "") & IF(K7<>"", "_" & K7, "") & IF(L7<>"", "_" & L7, "") & IF(M7<>"", "_" & M7, "") & IF(P7<>"", "_X" & P7, "") & IF(Q7<>"", "_Y" & Q7, "") & IF(R7<>"", "_Z" & R7, "") & IF(N7<>"", "_" & N7, "") & IF(O7<>"", "_" & O7, "")) | I7: Labor | J7: Door | L7: Single | O7: 001 | P7: 110 | Q7: 35 | R7: 250 | S7: DONE | T7: DONE
F8: =IF(I8="","", "SM_" & I8 & IF(J8<>"", "_" & J8, "") & IF(K8<>"", "_" & K8, "") & IF(L8<>"", "_" & L8, "") & IF(M8<>"", "_" & M8, "") & IF(P8<>"", "_X" & P8, "") & IF(Q8<>"", "_Y" & Q8, "") & IF(R8<>"", "_Z" & R8, "") & IF(N8<>"", "_" & N8, "") & IF(O8<>"", "_" & O8, "")) | I8: Labor | J8: DoorFrame | O8: 001 | P8: 110 | Q8: 50 | R8: 250 | S8: DONE | T8: DONE
E9: =IF(I9="","", "BP_" & I9 & IF(J9<>"", "_" & J9, "") & IF(K9<>"", "_" & K9, "") & IF(L9<>"", "_" & L9, "") & IF(M9<>"", "_" & M9, "") & IF(P9<>"", "_X" & P9, "") & IF(Q9<>"", "_Y" & Q9, "") & IF(R9<>"", "_Z" & R9, "") & IF(N9<>"", "_" & N9, "") & IF(O9<>"", "_" & O9, "")) | I9: Labor | J9: Door | K9: Lift | O9: 001 | P9: 150 | Q9: 30 | R9: 250
F10: =IF(I10="","", "SM_" & I10 & IF(J10<>"", "_" & J10, "") & IF(K10<>"", "_" & K10, "") & IF(L10<>"", "_" & L10, "") & IF(M10<>"", "_" & M10, "") & IF(P10<>"", "_X" & P10, "") & IF(Q10<>"", "_Y" & Q10, "") & IF(R10<>"", "_Z" & R10, "") & IF(N10<>"", "_" & N10, "") & IF(O10<>"", "_" & O10, "")) | I10: Labor | J10: DoorFrame | K10: Lift | O10: 001 | P10: 150 | Q10: 50 | R10: 250 | S10: DONE | T10: DONE
F11: =IF(I11="","", "SM_" & I11 & IF(J11<>"", "_" & J11, "") & IF(K11<>"", "_" & K11, "") & IF(L11<>"", "_" & L11, "") & IF(M11<>"", "_" & M11, "") & IF(P11<>"", "_X" & P11, "") & IF(Q11<>"", "_Y" & Q11, "") & IF(R11<>"", "_Z" & R11, "") & IF(N11<>"", "_" & N11, "") & IF(O11<>"", "_" & O11, "")) | I11: Labor | J11: Door | K11: Lift | L11: Left | O11: 001 | P11: 150 | Q11: 30 | R11: 250 | S11: DONE | T11: DONE
F12: =IF(I12="","", "SM_" & I12 & IF(J12<>"", "_" & J12, "") & IF(K12<>"", "_" & K12, "") & IF(L12<>"", "_" & L12, "") & IF(M12<>"", "_" & M12, "") & IF(P12<>"", "_X" & P12, "") & IF(Q12<>"", "_Y" & Q12, "") & IF(R12<>"", "_Z" & R12, "") & IF(N12<>"", "_" & N12, "") & IF(O12<>"", "_" & O12, "")) | I12: Labor | J12: Door | K12: Lift | L12: Right | O12: 001 | P12: 150 | Q12: 30 | R12: 250 | S12: DONE | T12: DONE
E13: =IF(I13="","", "BP_" & I13 & IF(J13<>"", "_" & J13, "") & IF(K13<>"", "_" & K13, "") & IF(L13<>"", "_" & L13, "") & IF(M13<>"", "_" & M13, "") & IF(P13<>"", "_X" & P13, "") & IF(Q13<>"", "_Y" & Q13, "") & IF(R13<>"", "_Z" & R13, "") & IF(N13<>"", "_" & N13, "") & IF(O13<>"", "_" & O13, "")) | I13: Labor | J13: Door | K13: Section | O13: 001 | P13: 150 | Q13: 30 | R13: 250
F14: =IF(I14="","", "SM_" & I14 & IF(J14<>"", "_" & J14, "") & IF(K14<>"", "_" & K14, "") & IF(L14<>"", "_" & L14, "") & IF(M14<>"", "_" & M14, "") & IF(P14<>"", "_X" & P14, "") & IF(Q14<>"", "_Y" & Q14, "") & IF(R14<>"", "_Z" & R14, "") & IF(N14<>"", "_" & N14, "") & IF(O14<>"", "_" & O14, "")) | I14: Labor | J14: DoorFrame | K14: Section | O14: 001 | P14: 150 | Q14: 50 | R14: 250 | S14: DONE | T14: DONE
F15: =IF(I15="","", "SM_" & I15 & IF(J15<>"", "_" & J15, "") & IF(K15<>"", "_" & K15, "") & IF(L15<>"", "_" & L15, "") & IF(M15<>"", "_" & M15, "") & IF(P15<>"", "_X" & P15, "") & IF(Q15<>"", "_Y" & Q15, "") & IF(R15<>"", "_Z" & R15, "") & IF(N15<>"", "_" & N15, "") & IF(O15<>"", "_" & O15, "")) | I15: Labor | J15: DoorFrame | K15: SectionSaddle | O15: 001 | P15: 150 | Q15: 50 | R15: 250 | S15: DONE | T15: DONE
F16: =IF(I16="","", "SM_" & I16 & IF(J16<>"", "_" & J16, "") & IF(K16<>"", "_" & K16, "") & IF(L16<>"", "_" & L16, "") & IF(M16<>"", "_" & M16, "") & IF(P16<>"", "_X" & P16, "") & IF(Q16<>"", "_Y" & Q16, "") & IF(R16<>"", "_Z" & R16, "") & IF(N16<>"", "_" & N16, "") & IF(O16<>"", "_" & O16, "")) | I16: Labor | J16: Door | K16: Section | L16: Up | O16: 001 | P16: 150 | Q16: 30 | R16: 250 | S16: DONE | T16: DONE
F17: =IF(I17="","", "SM_" & I17 & IF(J17<>"", "_" & J17, "") & IF(K17<>"", "_" & K17, "") & IF(L17<>"", "_" & L17, "") & IF(M17<>"", "_" & M17, "") & IF(P17<>"", "_X" & P17, "") & IF(Q17<>"", "_Y" & Q17, "") & IF(R17<>"", "_Z" & R17, "") & IF(N17<>"", "_" & N17, "") & IF(O17<>"", "_" & O17, "")) | I17: Labor | J17: Door | K17: Section | L17: Down | O17: 001 | P17: 150 | Q17: 30 | R17: 250 | S17: DONE | T17: DONE
E18: =IF(I18="","", "BP_" & I18 & IF(J18<>"", "_" & J18, "") & IF(K18<>"", "_" & K18, "") & IF(L18<>"", "_" & L18, "") & IF(M18<>"", "_" & M18, "") & IF(P18<>"", "_X" & P18, "") & IF(Q18<>"", "_Y" & Q18, "") & IF(R18<>"", "_Z" & R18, "") & IF(N18<>"", "_" & N18, "") & IF(O18<>"", "_" & O18, "")) | I18: Labor | J18: Door | O18: 001 | P18: 200 | Q18: 35 | R18: 250
F19: =IF(I19="","", "SM_" & I19 & IF(J19<>"", "_" & J19, "") & IF(K19<>"", "_" & K19, "") & IF(L19<>"", "_" & L19, "") & IF(M19<>"", "_" & M19, "") & IF(P19<>"", "_X" & P19, "") & IF(Q19<>"", "_Y" & Q19, "") & IF(R19<>"", "_Z" & R19, "") & IF(N19<>"", "_" & N19, "") & IF(O19<>"", "_" & O19, "")) | I19: Labor | J19: DoorFrame | O19: 001 | P19: 200 | Q19: 50 | R19: 250 | S19: DONE | T19: DONE
F20: =IF(I20="","", "SM_" & I20 & IF(J20<>"", "_" & J20, "") & IF(K20<>"", "_" & K20, "") & IF(L20<>"", "_" & L20, "") & IF(M20<>"", "_" & M20, "") & IF(P20<>"", "_X" & P20, "") & IF(Q20<>"", "_Y" & Q20, "") & IF(R20<>"", "_Z" & R20, "") & IF(N20<>"", "_" & N20, "") & IF(O20<>"", "_" & O20, "")) | I20: Labor | J20: Door | L20: Left | O20: 001 | P20: 200 | Q20: 35 | R20: 250 | S20: DONE | T20: DONE
F21: =IF(I21="","", "SM_" & I21 & IF(J21<>"", "_" & J21, "") & IF(K21<>"", "_" & K21, "") & IF(L21<>"", "_" & L21, "") & IF(M21<>"", "_" & M21, "") & IF(P21<>"", "_X" & P21, "") & IF(Q21<>"", "_Y" & Q21, "") & IF(R21<>"", "_Z" & R21, "") & IF(N21<>"", "_" & N21, "") & IF(O21<>"", "_" & O21, "")) | I21: Labor | J21: Door | L21: Right | O21: 001 | P21: 200 | Q21: 35 | R21: 250 | S21: DONE | T21: DONE
E22: =IF(I22="","", "BP_" & I22 & IF(J22<>"", "_" & J22, "") & IF(K22<>"", "_" & K22, "") & IF(L22<>"", "_" & L22, "") & IF(M22<>"", "_" & M22, "") & IF(P22<>"", "_X" & P22, "") & IF(Q22<>"", "_Y" & Q22, "") & IF(R22<>"", "_Z" & R22, "") & IF(N22<>"", "_" & N22, "") & IF(O22<>"", "_" & O22, "")) | I22: Labor | J22: Door | O22: 001 | P22: 300 | Q22: 35 | R22: 250
F23: =IF(I23="","", "SM_" & I23 & IF(J23<>"", "_" & J23, "") & IF(K23<>"", "_" & K23, "") & IF(L23<>"", "_" & L23, "") & IF(M23<>"", "_" & M23, "") & IF(P23<>"", "_X" & P23, "") & IF(Q23<>"", "_Y" & Q23, "") & IF(R23<>"", "_Z" & R23, "") & IF(N23<>"", "_" & N23, "") & IF(O23<>"", "_" & O23, "")) | I23: Labor | J23: DoorFrame | O23: 001 | P23: 300 | Q23: 50 | R23: 250 | S23: DONE | T23: DONE
F24: =IF(I24="","", "SM_" & I24 & IF(J24<>"", "_" & J24, "") & IF(K24<>"", "_" & K24, "") & IF(L24<>"", "_" & L24, "") & IF(M24<>"", "_" & M24, "") & IF(P24<>"", "_X" & P24, "") & IF(Q24<>"", "_Y" & Q24, "") & IF(R24<>"", "_Z" & R24, "") & IF(N24<>"", "_" & N24, "") & IF(O24<>"", "_" & O24, "")) | I24: Labor | J24: Door | L24: Left | O24: 001 | P24: 300 | Q24: 35 | R24: 250 | S24: DONE | T24: DONE
F25: =IF(I25="","", "SM_" & I25 & IF(J25<>"", "_" & J25, "") & IF(K25<>"", "_" & K25, "") & IF(L25<>"", "_" & L25, "") & IF(M25<>"", "_" & M25, "") & IF(P25<>"", "_X" & P25, "") & IF(Q25<>"", "_Y" & Q25, "") & IF(R25<>"", "_Z" & R25, "") & IF(N25<>"", "_" & N25, "") & IF(O25<>"", "_" & O25, "")) | I25: Labor | J25: Door | L25: Right | O25: 001 | P25: 300 | Q25: 35 | R25: 250 | S25: DONE | T25: DONE
E26: =IF(I26="","", "BP_" & I26 & IF(J26<>"", "_" & J26, "") & IF(K26<>"", "_" & K26, "") & IF(L26<>"", "_" & L26, "") & IF(M26<>"", "_" & M26, "") & IF(P26<>"", "_X" & P26, "") & IF(Q26<>"", "_Y" & Q26, "") & IF(R26<>"", "_Z" & R26, "") & IF(N26<>"", "_" & N26, "") & IF(O26<>"", "_" & O26, "")) | I26: Labor | J26: Door | O26: 001 | P26: 400 | Q26: 35 | R26: 250
F27: =IF(I27="","", "SM_" & I27 & IF(J27<>"", "_" & J27, "") & IF(K27<>"", "_" & K27, "") & IF(L27<>"", "_" & L27, "") & IF(M27<>"", "_" & M27, "") & IF(P27<>"", "_X" & P27, "") & IF(Q27<>"", "_Y" & Q27, "") & IF(R27<>"", "_Z" & R27, "") & IF(N27<>"", "_" & N27, "") & IF(O27<>"", "_" & O27, "")) | I27: Labor | J27: DoorFrame | O27: 001 | P27: 400 | Q27: 50 | R27: 250 | S27: DONE | T27: DONE
F28: =IF(I28="","", "SM_" & I28 & IF(J28<>"", "_" & J28, "") & IF(K28<>"", "_" & K28, "") & IF(L28<>"", "_" & L28, "") & IF(M28<>"", "_" & M28, "") & IF(P28<>"", "_X" & P28, "") & IF(Q28<>"", "_Y" & Q28, "") & IF(R28<>"", "_Z" & R28, "") & IF(N28<>"", "_" & N28, "") & IF(O28<>"", "_" & O28, "")) | I28: Labor | J28: Door | L28: Single | O28: 001 | P28: 400 | Q28: 35 | R28: 250 | S28: DONE | T28: DONE
E29: =IF(I29="","", "BP_" & I29 & IF(J29<>"", "_" & J29, "") & IF(K29<>"", "_" & K29, "") & IF(L29<>"", "_" & L29, "") & IF(M29<>"", "_" & M29, "") & IF(P29<>"", "_X" & P29, "") & IF(Q29<>"", "_Y" & Q29, "") & IF(R29<>"", "_Z" & R29, "") & IF(N29<>"", "_" & N29, "") & IF(O29<>"", "_" & O29, "")) | I29: Labor | J29: Door | O29: 001 | P29: 500 | Q29: 35 | R29: 250
F30: =IF(I30="","", "SM_" & I30 & IF(J30<>"", "_" & J30, "") & IF(K30<>"", "_" & K30, "") & IF(L30<>"", "_" & L30, "") & IF(M30<>"", "_" & M30, "") & IF(P30<>"", "_X" & P30, "") & IF(Q30<>"", "_Y" & Q30, "") & IF(R30<>"", "_Z" & R30, "") & IF(N30<>"", "_" & N30, "") & IF(O30<>"", "_" & O30, "")) | I30: Labor | J30: Door | L30: Single | O30: 001 | P30: 500 | Q30: 30 | R30: 250 | S30: DONE | T30: DONE
F31: =IF(I31="","", "SM_" & I31 & IF(J31<>"", "_" & J31, "") & IF(K31<>"", "_" & K31, "") & IF(L31<>"", "_" & L31, "") & IF(M31<>"", "_" & M31, "") & IF(P31<>"", "_X" & P31, "") & IF(Q31<>"", "_Y" & Q31, "") & IF(R31<>"", "_Z" & R31, "") & IF(N31<>"", "_" & N31, "") & IF(O31<>"", "_" & O31, "")) | I31: Labor | J31: DoorFrame | O31: 001 | P31: 500 | Q31: 50 | R31: 250 | S31: DONE | T31: DONE
B32: Structure
C33: Floor
D34: Center
E35: =IF(I35="","", "BP_" & I35 & IF(J35<>"", "_" & J35, "") & IF(K35<>"", "_" & K35, "") & IF(L35<>"", "_" & L35, "") & IF(M35<>"", "_" & M35, "") & IF(P35<>"", "_X" & P35, "") & IF(Q35<>"", "_Y" & Q35, "") & IF(R35<>"", "_Z" & R35, "") & IF(N35<>"", "_" & N35, "") & IF(O35<>"", "_" & O35, "")) | F35: =IF(I35="","", "SM_" & I35 & IF(J35<>"", "_" & J35, "") & IF(K35<>"", "_" & K35, "") & IF(L35<>"", "_" & L35, "") & IF(M35<>"", "_" & M35, "") & IF(P35<>"", "_X" & P35, "") & IF(Q35<>"", "_Y" & Q35, "") & IF(R35<>"", "_Z" & R35, "") & IF(N35<>"", "_" & N35, "") & IF(O35<>"", "_" & O35, "")) | I35: Labor | J35: Floor | K35: Center | L35: Blank | N35: A | O35: 001 | P35: 100 | Q35: 100 | R35: 20 | S35: ✅ | T35: ✅
E36: =IF(I36="","", "BP_" & I36 & IF(J36<>"", "_" & J36, "") & IF(K36<>"", "_" & K36, "") & IF(L36<>"", "_" & L36, "") & IF(M36<>"", "_" & M36, "") & IF(P36<>"", "_X" & P36, "") & IF(Q36<>"", "_Y" & Q36, "") & IF(R36<>"", "_Z" & R36, "") & IF(N36<>"", "_" & N36, "") & IF(O36<>"", "_" & O36, "")) | F36: =IF(I36="","", "SM_" & I36 & IF(J36<>"", "_" & J36, "") & IF(K36<>"", "_" & K36, "") & IF(L36<>"", "_" & L36, "") & IF(M36<>"", "_" & M36, "") & IF(P36<>"", "_X" & P36, "") & IF(Q36<>"", "_Y" & Q36, "") & IF(R36<>"", "_Z" & R36, "") & IF(N36<>"", "_" & N36, "") & IF(O36<>"", "_" & O36, "")) | I36: Labor | J36: Floor | K36: Center | L36: Forward | N36: A | O36: 001 | P36: 100 | Q36: 100 | R36: 20 | S36: ✅ | T36: ✅
E37: =IF(I37="","", "BP_" & I37 & IF(J37<>"", "_" & J37, "") & IF(K37<>"", "_" & K37, "") & IF(L37<>"", "_" & L37, "") & IF(M37<>"", "_" & M37, "") & IF(P37<>"", "_X" & P37, "") & IF(Q37<>"", "_Y" & Q37, "") & IF(R37<>"", "_Z" & R37, "") & IF(N37<>"", "_" & N37, "") & IF(O37<>"", "_" & O37, "")) | F37: =IF(I37="","", "SM_" & I37 & IF(J37<>"", "_" & J37, "") & IF(K37<>"", "_" & K37, "") & IF(L37<>"", "_" & L37, "") & IF(M37<>"", "_" & M37, "") & IF(P37<>"", "_X" & P37, "") & IF(Q37<>"", "_Y" & Q37, "") & IF(R37<>"", "_Z" & R37, "") & IF(N37<>"", "_" & N37, "") & IF(O37<>"", "_" & O37, "")) | I37: Labor | J37: Floor | K37: Center | L37: Forward | N37: A | O37: 002 | P37: 100 | Q37: 100 | R37: 20 | S37: ✅ | T37: ✅
E38: =IF(I38="","", "BP_" & I38 & IF(J38<>"", "_" & J38, "") & IF(K38<>"", "_" & K38, "") & IF(L38<>"", "_" & L38, "") & IF(M38<>"", "_" & M38, "") & IF(P38<>"", "_X" & P38, "") & IF(Q38<>"", "_Y" & Q38, "") & IF(R38<>"", "_Z" & R38, "") & IF(N38<>"", "_" & N38, "") & IF(O38<>"", "_" & O38, "")) | F38: =IF(I38="","", "SM_" & I38 & IF(J38<>"", "_" & J38, "") & IF(K38<>"", "_" & K38, "") & IF(L38<>"", "_" & L38, "") & IF(M38<>"", "_" & M38, "") & IF(P38<>"", "_X" & P38, "") & IF(Q38<>"", "_Y" & Q38, "") & IF(R38<>"", "_Z" & R38, "") & IF(N38<>"", "_" & N38, "") & IF(O38<>"", "_" & O38, "")) | I38: Labor | J38: Floor | K38: Center | L38: Forward | N38: A | O38: 003 | P38: 100 | Q38: 100 | R38: 20 | S38: ✅ | T38: ✅
E39: =IF(I39="","", "BP_" & I39 & IF(J39<>"", "_" & J39, "") & IF(K39<>"", "_" & K39, "") & IF(L39<>"", "_" & L39, "") & IF(M39<>"", "_" & M39, "") & IF(P39<>"", "_X" & P39, "") & IF(Q39<>"", "_Y" & Q39, "") & IF(R39<>"", "_Z" & R39, "") & IF(N39<>"", "_" & N39, "") & IF(O39<>"", "_" & O39, "")) | F39: =IF(I39="","", "SM_" & I39 & IF(J39<>"", "_" & J39, "") & IF(K39<>"", "_" & K39, "") & IF(L39<>"", "_" & L39, "") & IF(M39<>"", "_" & M39, "") & IF(P39<>"", "_X" & P39, "") & IF(Q39<>"", "_Y" & Q39, "") & IF(R39<>"", "_Z" & R39, "") & IF(N39<>"", "_" & N39, "") & IF(O39<>"", "_" & O39, "")) | I39: Labor | J39: Floor | K39: Center | L39: Forward | N39: A | O39: 004 | P39: 100 | Q39: 100 | R39: 20 | S39: ✅ | T39: ✅
E40: =IF(I40="","", "BP_" & I40 & IF(J40<>"", "_" & J40, "") & IF(K40<>"", "_" & K40, "") & IF(L40<>"", "_" & L40, "") & IF(M40<>"", "_" & M40, "") & IF(P40<>"", "_X" & P40, "") & IF(Q40<>"", "_Y" & Q40, "") & IF(R40<>"", "_Z" & R40, "") & IF(N40<>"", "_" & N40, "") & IF(O40<>"", "_" & O40, "")) | F40: =IF(I40="","", "SM_" & I40 & IF(J40<>"", "_" & J40, "") & IF(K40<>"", "_" & K40, "") & IF(L40<>"", "_" & L40, "") & IF(M40<>"", "_" & M40, "") & IF(P40<>"", "_X" & P40, "") & IF(Q40<>"", "_Y" & Q40, "") & IF(R40<>"", "_Z" & R40, "") & IF(N40<>"", "_" & N40, "") & IF(O40<>"", "_" & O40, "")) | I40: Labor | J40: Floor | K40: Center | L40: Turn | N40: A | O40: 001 | P40: 100 | Q40: 100 | R40: 20 | S40: ✅ | T40: ✅
...

Sheet 关卡程序命名
B1: MapName | C1: EnemyMapName | D1: RewardMapName | F1: MapRef | G1: EnemyRef | H1: RewardRef | I1: SectionID | J1: MapType | K1: StartFacing | M1: Party | N1: EndFacing | O1: Allowed Level | P1: Variant | Q1: Section To | R1: Section From | S1: 进度 | T1: 组合 | V1: 总概率 | W1: Initial | X1: 1 | Y1: 2 | Z1: 3 | AA1: 4 | AB1: 5 | AC1: 6 | AD1: 7 | AE1: 8 | AF1: 9 | AG1: 10
B2: {="_"} | C2: {="_"} | D2: {="_"} | F2: {=B2:B1000&M2:M1000&I2:I1000&S2:S1000=""&""&"/Game/Levels/Maps/"&"/SubLevel/"&"_"&"/"&"."} | G2: {=C2:C1000&M2:M1000&I2:I1000&S2:S1000=""&""&"/Script/Engine.World'/Game/Levels/Maps/"&"/SubLevel/"&"_"&"/"&"."&"'"} | H2: {=D2:D1000&M2:M1000&I2:I1000&S2:S1000=""&""&"/Script/Engine.World'/Game/Levels/Maps/"&"/SubLevel/"&"_"&"/"&"."&"'"} | I2: S01 | J2: 1_Initial | K2: 0_Initial | M2: Labor | N2: 3_NagY | O2: 1 | P2: 01 | S2: DONE | T2: {=""} | V2: =IF(SUM(X2:AG2)=0, 0, SUM(X2:AG2) / SUM($X$2:$AG$1012)) | X2: =IF(AND($S2="DONE", ISNUMBER(FIND(","&X$1&",", ","&SUBSTITUTE($O2," ","")&","))), 1/SUMPRODUCT(--ISNUMBER(FIND(","&X$1&",", ","&SUBSTITUTE($O$2:$O$1012," ","")&",")), --($S$2:$S$1012="DONE")), 0) | Y2: =IF(AND($S2="DONE", ISNUMBER(FIND(","&Y$1&",", ","&SUBSTITUTE($O2," ","")&","))), 1/SUMPRODUCT(--ISNUMBER(FIND(","&Y$1&",", ","&SUBSTITUTE($O$2:$O$1012," ","")&",")), --($S$2:$S$1012="DONE")), 0) | Z2: =IF(AND($S2="DONE", ISNUMBER(FIND(","&Z$1&",", ","&SUBSTITUTE($O2," ","")&","))), 1/SUMPRODUCT(--ISNUMBER(FIND(","&Z$1&",", ","&SUBSTITUTE($O$2:$O$1012," ","")&",")), --($S$2:$S$1012="DONE")), 0) | AA2: =IF(AND($S2="DONE", ISNUMBER(FIND(","&AA$1&",", ","&SUBSTITUTE($O2," ","")&","))), 1/SUMPRODUCT(--ISNUMBER(FIND(","&AA$1&",", ","&SUBSTITUTE($O$2:$O$1012," ","")&",")), --($S$2:$S$1012="DONE")), 0) | AB2: =IF(AND($S2="DONE", ISNUMBER(FIND(","&AB$1&",", ","&SUBSTITUTE($O2," ","")&","))), 1/SUMPRODUCT(--ISNUMBER(FIND(","&AB$1&",", ","&SUBSTITUTE($O$2:$O$1012," ","")&",")), --($S$2:$S$1012="DONE")), 0) | AC2: =IF(AND($S2="DONE", ISNUMBER(FIND(","&AC$1&",", ","&SUBSTITUTE($O2," ","")&","))), 1/SUMPRODUCT(--ISNUMBER(FIND(","&AC$1&",", ","&SUBSTITUTE($O$2:$O$1012," ","")&",")), --($S$2:$S$1012="DONE")), 0) | AD2: =IF(AND($S2="DONE", ISNUMBER(FIND(","&AD$1&",", ","&SUBSTITUTE($O2," ","")&","))), 1/SUMPRODUCT(--ISNUMBER(FIND(","&AD$1&",", ","&SUBSTITUTE($O$2:$O$1012," ","")&",")), --($S$2:$S$1012="DONE")), 0) | AE2: =IF(AND($S2="DONE", ISNUMBER(FIND(","&AE$1&",", ","&SUBSTITUTE($O2," ","")&","))), 1/SUMPRODUCT(--ISNUMBER(FIND(","&AE$1&",", ","&SUBSTITUTE($O$2:$O$1012," ","")&",")), --($S$2:$S$1012="DONE")), 0) | ... AG2: =IF(AND($S2="DONE", ISNUMBER(FIND(","&AG$1&",", ","&SUBSTITUTE($O2," ","")&","))), 1/SUMPRODUCT(--ISNUMBER(FIND(","&AG$1&",", ","&SUBSTITUTE($O$2:$O$1012," ","")&",")), --($S$2:$S$1012="DONE")), 0)
B3: L_Labor_Initial_PosY_S01_01 | C3: L_Labor_Initial_PosY_S01_01_Enemy | D3: L_Labor_Initial_PosY_S01_01_Reward | F3: /Game/Levels/Maps/Labor/SubLevel/Labor_S01/L_Labor_Initial_PosY_S01_01.L_Labor_Initial_PosY_S01_01 | G3: /Script/Engine.World'/Game/Levels/Maps/Labor/SubLevel/Labor_S01/L_Labor_Initial_PosY_S01_01_Enemy.L_Labor_Initial_PosY_S01_01_Enemy' | H3: /Script/Engine.World'/Game/Levels/Maps/Labor/SubLevel/Labor_S01/L_Labor_Initial_PosY_S01_01_Reward.L_Labor_Initial_PosY_S01_01_Reward' | I3: S01 | J3: 1_Initial | K3: 0_Initial | M3: Labor | N3: 2_PosY | O3: 1 | P3: 01 | S3: NEED FIX | V3: =IF(SUM(X3:AG3)=0, 0, SUM(X3:AG3) / SUM($X$2:$AG$1012)) | X3: =IF(AND($S3="DONE", ISNUMBER(FIND(","&X$1&",", ","&SUBSTITUTE($O3," ","")&","))), 1/SUMPRODUCT(--ISNUMBER(FIND(","&X$1&",", ","&SUBSTITUTE($O$2:$O$1012," ","")&",")), --($S$2:$S$1012="DONE")), 0) | Y3: =IF(AND($S3="DONE", ISNUMBER(FIND(","&Y$1&",", ","&SUBSTITUTE($O3," ","")&","))), 1/SUMPRODUCT(--ISNUMBER(FIND(","&Y$1&",", ","&SUBSTITUTE($O$2:$O$1012," ","")&",")), --($S$2:$S$1012="DONE")), 0) | Z3: =IF(AND($S3="DONE", ISNUMBER(FIND(","&Z$1&",", ","&SUBSTITUTE($O3," ","")&","))), 1/SUMPRODUCT(--ISNUMBER(FIND(","&Z$1&",", ","&SUBSTITUTE($O$2:$O$1012," ","")&",")), --($S$2:$S$1012="DONE")), 0) | AA3: =IF(AND($S3="DONE", ISNUMBER(FIND(","&AA$1&",", ","&SUBSTITUTE($O3," ","")&","))), 1/SUMPRODUCT(--ISNUMBER(FIND(","&AA$1&",", ","&SUBSTITUTE($O$2:$O$1012," ","")&",")), --($S$2:$S$1012="DONE")), 0) | AB3: =IF(AND($S3="DONE", ISNUMBER(FIND(","&AB$1&",", ","&SUBSTITUTE($O3," ","")&","))), 1/SUMPRODUCT(--ISNUMBER(FIND(","&AB$1&",", ","&SUBSTITUTE($O$2:$O$1012," ","")&",")), --($S$2:$S$1012="DONE")), 0) | AC3: =IF(AND($S3="DONE", ISNUMBER(FIND(","&AC$1&",", ","&SUBSTITUTE($O3," ","")&","))), 1/SUMPRODUCT(--ISNUMBER(FIND(","&AC$1&",", ","&SUBSTITUTE($O$2:$O$1012," ","")&",")), --($S$2:$S$1012="DONE")), 0) | AD3: =IF(AND($S3="DONE", ISNUMBER(FIND(","&AD$1&",", ","&SUBSTITUTE($O3," ","")&","))), 1/SUMPRODUCT(--ISNUMBER(FIND(","&AD$1&",", ","&SUBSTITUTE($O$2:$O$1012," ","")&",")), --($S$2:$S$1012="DONE")), 0) | AE3: =IF(AND($S3="DONE", ISNUMBER(FIND(","&AE$1&",", ","&SUBSTITUTE($O3," ","")&","))), 1/SUMPRODUCT(--ISNUMBER(FIND(","&AE$1&",", ","&SUBSTITUTE($O$2:$O$1012," ","")&",")), --($S$2:$S$1012="DONE")), 0) | ... AG3: =IF(AND($S3="DONE", ISNUMBER(FIND(","&AG$1&",", ","&SUBSTITUTE($O3," ","")&","))), 1/SUMPRODUCT(--ISNUMBER(FIND(","&AG$1&",", ","&SUBSTITUTE($O$2:$O$1012," ","")&",")), --($S$2:$S$1012="DONE")), 0)
B4: L_Labor_Initial_NagX_S01_01 | C4: L_Labor_Initial_NagX_S01_01_Enemy | D4: L_Labor_Initial_NagX_S01_01_Reward | F4: /Game/Levels/Maps/Labor/SubLevel/Labor_S01/L_Labor_Initial_NagX_S01_01.L_Labor_Initial_NagX_S01_01 | G4: /Script/Engine.World'/Game/Levels/Maps/Labor/SubLevel/Labor_S01/L_Labor_Initial_NagX_S01_01_Enemy.L_Labor_Initial_NagX_S01_01_Enemy' | H4: /Script/Engine.World'/Game/Levels/Maps/Labor/SubLevel/Labor_S01/L_Labor_Initial_NagX_S01_01_Reward.L_Labor_Initial_NagX_S01_01_Reward' | I4: S01 | J4: 1_Initial | K4: 0_Initial | M4: Labor | N4: 1_NagX | O4: 1 | P4: 01 | S4: NEED FIX | V4: =IF(SUM(X4:AG4)=0, 0, SUM(X4:AG4) / SUM($X$2:$AG$1012)) | X4: =IF(AND($S4="DONE", ISNUMBER(FIND(","&X$1&",", ","&SUBSTITUTE($O4," ","")&","))), 1/SUMPRODUCT(--ISNUMBER(FIND(","&X$1&",", ","&SUBSTITUTE($O$2:$O$1012," ","")&",")), --($S$2:$S$1012="DONE")), 0) | Y4: =IF(AND($S4="DONE", ISNUMBER(FIND(","&Y$1&",", ","&SUBSTITUTE($O4," ","")&","))), 1/SUMPRODUCT(--ISNUMBER(FIND(","&Y$1&",", ","&SUBSTITUTE($O$2:$O$1012," ","")&",")), --($S$2:$S$1012="DONE")), 0) | Z4: =IF(AND($S4="DONE", ISNUMBER(FIND(","&Z$1&",", ","&SUBSTITUTE($O4," ","")&","))), 1/SUMPRODUCT(--ISNUMBER(FIND(","&Z$1&",", ","&SUBSTITUTE($O$2:$O$1012," ","")&",")), --($S$2:$S$1012="DONE")), 0) | AA4: =IF(AND($S4="DONE", ISNUMBER(FIND(","&AA$1&",", ","&SUBSTITUTE($O4," ","")&","))), 1/SUMPRODUCT(--ISNUMBER(FIND(","&AA$1&",", ","&SUBSTITUTE($O$2:$O$1012," ","")&",")), --($S$2:$S$1012="DONE")), 0) | AB4: =IF(AND($S4="DONE", ISNUMBER(FIND(","&AB$1&",", ","&SUBSTITUTE($O4," ","")&","))), 1/SUMPRODUCT(--ISNUMBER(FIND(","&AB$1&",", ","&SUBSTITUTE($O$2:$O$1012," ","")&",")), --($S$2:$S$1012="DONE")), 0) | AC4: =IF(AND($S4="DONE", ISNUMBER(FIND(","&AC$1&",", ","&SUBSTITUTE($O4," ","")&","))), 1/SUMPRODUCT(--ISNUMBER(FIND(","&AC$1&",", ","&SUBSTITUTE($O$2:$O$1012," ","")&",")), --($S$2:$S$1012="DONE")), 0) | AD4: =IF(AND($S4="DONE", ISNUMBER(FIND(","&AD$1&",", ","&SUBSTITUTE($O4," ","")&","))), 1/SUMPRODUCT(--ISNUMBER(FIND(","&AD$1&",", ","&SUBSTITUTE($O$2:$O$1012," ","")&",")), --($S$2:$S$1012="DONE")), 0) | AE4: =IF(AND($S4="DONE", ISNUMBER(FIND(","&AE$1&",", ","&SUBSTITUTE($O4," ","")&","))), 1/SUMPRODUCT(--ISNUMBER(FIND(","&AE$1&",", ","&SUBSTITUTE($O$2:$O$1012," ","")&",")), --($S$2:$S$1012="DONE")), 0) | ... AG4: =IF(AND($S4="DONE", ISNUMBER(FIND(","&AG$1&",", ","&SUBSTITUTE($O4," ","")&","))), 1/SUMPRODUCT(--ISNUMBER(FIND(","&AG$1&",", ","&SUBSTITUTE($O$2:$O$1012," ","")&",")), --($S$2:$S$1012="DONE")), 0)
B5: L_Labor_Initial_NagY_S01_01 | C5: L_Labor_Initial_NagY_S01_01_Enemy | D5: L_Labor_Initial_NagY_S01_01_Reward | F5: /Game/Levels/Maps/Labor/SubLevel/Labor_S01/L_Labor_Initial_NagY_S01_01.L_Labor_Initial_NagY_S01_01 | G5: /Script/Engine.World'/Game/Levels/Maps/Labor/SubLevel/Labor_S01/L_Labor_Initial_NagY_S01_01_Enemy.L_Labor_Initial_NagY_S01_01_Enemy' | H5: /Script/Engine.World'/Game/Levels/Maps/Labor/SubLevel/Labor_S01/L_Labor_Initial_NagY_S01_01_Reward.L_Labor_Initial_NagY_S01_01_Reward' | I5: S01 | J5: 1_Initial | K5: 0_Initial | M5: Labor | N5: 3_NagY | O5: 1 | P5: 01 | S5: NEED FIX | V5: =IF(SUM(X5:AG5)=0, 0, SUM(X5:AG5) / SUM($X$2:$AG$1012)) | X5: =IF(AND($S5="DONE", ISNUMBER(FIND(","&X$1&",", ","&SUBSTITUTE($O5," ","")&","))), 1/SUMPRODUCT(--ISNUMBER(FIND(","&X$1&",", ","&SUBSTITUTE($O$2:$O$1012," ","")&",")), --($S$2:$S$1012="DONE")), 0) | Y5: =IF(AND($S5="DONE", ISNUMBER(FIND(","&Y$1&",", ","&SUBSTITUTE($O5," ","")&","))), 1/SUMPRODUCT(--ISNUMBER(FIND(","&Y$1&",", ","&SUBSTITUTE($O$2:$O$1012," ","")&",")), --($S$2:$S$1012="DONE")), 0) | Z5: =IF(AND($S5="DONE", ISNUMBER(FIND(","&Z$1&",", ","&SUBSTITUTE($O5," ","")&","))), 1/SUMPRODUCT(--ISNUMBER(FIND(","&Z$1&",", ","&SUBSTITUTE($O$2:$O$1012," ","")&",")), --($S$2:$S$1012="DONE")), 0) | AA5: =IF(AND($S5="DONE", ISNUMBER(FIND(","&AA$1&",", ","&SUBSTITUTE($O5," ","")&","))), 1/SUMPRODUCT(--ISNUMBER(FIND(","&AA$1&",", ","&SUBSTITUTE($O$2:$O$1012," ","")&",")), --($S$2:$S$1012="DONE")), 0) | AB5: =IF(AND($S5="DONE", ISNUMBER(FIND(","&AB$1&",", ","&SUBSTITUTE($O5," ","")&","))), 1/SUMPRODUCT(--ISNUMBER(FIND(","&AB$1&",", ","&SUBSTITUTE($O$2:$O$1012," ","")&",")), --($S$2:$S$1012="DONE")), 0) | AC5: =IF(AND($S5="DONE", ISNUMBER(FIND(","&AC$1&",", ","&SUBSTITUTE($O5," ","")&","))), 1/SUMPRODUCT(--ISNUMBER(FIND(","&AC$1&",", ","&SUBSTITUTE($O$2:$O$1012," ","")&",")), --($S$2:$S$1012="DONE")), 0) | AD5: =IF(AND($S5="DONE", ISNUMBER(FIND(","&AD$1&",", ","&SUBSTITUTE($O5," ","")&","))), 1/SUMPRODUCT(--ISNUMBER(FIND(","&AD$1&",", ","&SUBSTITUTE($O$2:$O$1012," ","")&",")), --($S$2:$S$1012="DONE")), 0) | AE5: =IF(AND($S5="DONE", ISNUMBER(FIND(","&AE$1&",", ","&SUBSTITUTE($O5," ","")&","))), 1/SUMPRODUCT(--ISNUMBER(FIND(","&AE$1&",", ","&SUBSTITUTE($O$2:$O$1012," ","")&",")), --($S$2:$S$1012="DONE")), 0) | ... AG5: =IF(AND($S5="DONE", ISNUMBER(FIND(","&AG$1&",", ","&SUBSTITUTE($O5," ","")&","))), 1/SUMPRODUCT(--ISNUMBER(FIND(","&AG$1&",", ","&SUBSTITUTE($O$2:$O$1012," ","")&",")), --($S$2:$S$1012="DONE")), 0)
B6: L_Labor_PosX_NagY_S01_01 | C6: L_Labor_PosX_NagY_S01_01_Enemy | D6: L_Labor_PosX_NagY_S01_01_Reward | F6: /Game/Levels/Maps/Labor/SubLevel/Labor_S01/L_Labor_PosX_NagY_S01_01.L_Labor_PosX_NagY_S01_01 | G6: /Script/Engine.World'/Game/Levels/Maps/Labor/SubLevel/Labor_S01/L_Labor_PosX_NagY_S01_01_Enemy.L_Labor_PosX_NagY_S01_01_Enemy' | H6: /Script/Engine.World'/Game/Levels/Maps/Labor/SubLevel/Labor_S01/L_Labor_PosX_NagY_S01_01_Reward.L_Labor_PosX_NagY_S01_01_Reward' | I6: S01 | J6: 0_Regular | K6: 0_PosX | M6: Labor | N6: 3_NagY | O6: 1,2,3,4,5,6,7,8 | P6: 01 | S6: DONE | T6: PosXNagY | V6: =IF(SUM(X6:AG6)=0, 0, SUM(X6:AG6) / SUM($X$2:$AG$1012)) | X6: =IF(AND($S6="DONE", ISNUMBER(FIND(","&X$1&",", ","&SUBSTITUTE($O6," ","")&","))), 1/SUMPRODUCT(--ISNUMBER(FIND(","&X$1&",", ","&SUBSTITUTE($O$2:$O$1012," ","")&",")), --($S$2:$S$1012="DONE")), 0) | Y6: =IF(AND($S6="DONE", ISNUMBER(FIND(","&Y$1&",", ","&SUBSTITUTE($O6," ","")&","))), 1/SUMPRODUCT(--ISNUMBER(FIND(","&Y$1&",", ","&SUBSTITUTE($O$2:$O$1012," ","")&",")), --($S$2:$S$1012="DONE")), 0) | Z6: =IF(AND($S6="DONE", ISNUMBER(FIND(","&Z$1&",", ","&SUBSTITUTE($O6," ","")&","))), 1/SUMPRODUCT(--ISNUMBER(FIND(","&Z$1&",", ","&SUBSTITUTE($O$2:$O$1012," ","")&",")), --($S$2:$S$1012="DONE")), 0) | AA6: =IF(AND($S6="DONE", ISNUMBER(FIND(","&AA$1&",", ","&SUBSTITUTE($O6," ","")&","))), 1/SUMPRODUCT(--ISNUMBER(FIND(","&AA$1&",", ","&SUBSTITUTE($O$2:$O$1012," ","")&",")), --($S$2:$S$1012="DONE")), 0) | AB6: =IF(AND($S6="DONE", ISNUMBER(FIND(","&AB$1&",", ","&SUBSTITUTE($O6," ","")&","))), 1/SUMPRODUCT(--ISNUMBER(FIND(","&AB$1&",", ","&SUBSTITUTE($O$2:$O$1012," ","")&",")), --($S$2:$S$1012="DONE")), 0) | AC6: =IF(AND($S6="DONE", ISNUMBER(FIND(","&AC$1&",", ","&SUBSTITUTE($O6," ","")&","))), 1/SUMPRODUCT(--ISNUMBER(FIND(","&AC$1&",", ","&SUBSTITUTE($O$2:$O$1012," ","")&",")), --($S$2:$S$1012="DONE")), 0) | AD6: =IF(AND($S6="DONE", ISNUMBER(FIND(","&AD$1&",", ","&SUBSTITUTE($O6," ","")&","))), 1/SUMPRODUCT(--ISNUMBER(FIND(","&AD$1&",", ","&SUBSTITUTE($O$2:$O$1012," ","")&",")), --($S$2:$S$1012="DONE")), 0) | AE6: =IF(AND($S6="DONE", ISNUMBER(FIND(","&AE$1&",", ","&SUBSTITUTE($O6," ","")&","))), 1/SUMPRODUCT(--ISNUMBER(FIND(","&AE$1&",", ","&SUBSTITUTE($O$2:$O$1012," ","")&",")), --($S$2:$S$1012="DONE")), 0) | ... AG6: =IF(AND($S6="DONE", ISNUMBER(FIND(","&AG$1&",", ","&SUBSTITUTE($O6," ","")&","))), 1/SUMPRODUCT(--ISNUMBER(FIND(","&AG$1&",", ","&SUBSTITUTE($O$2:$O$1012," ","")&",")), --($S$2:$S$1012="DONE")), 0)
B7: L_Labor_PosY_NagY_S02_01 | C7: L_Labor_PosY_NagY_S02_01_Enemy | D7: L_Labor_PosY_NagY_S02_01_Reward | F7: /Game/Levels/Maps/Labor/SubLevel/Labor_S02/L_Labor_PosY_NagY_S02_01.L_Labor_PosY_NagY_S02_01 | G7: /Script/Engine.World'/Game/Levels/Maps/Labor/SubLevel/Labor_S02/L_Labor_PosY_NagY_S02_01_Enemy.L_Labor_PosY_NagY_S02_01_Enemy' | H7: /Script/Engine.World'/Game/Levels/Maps/Labor/SubLevel/Labor_S02/L_Labor_PosY_NagY_S02_01_Reward.L_Labor_PosY_NagY_S02_01_Reward' | I7: S02 | J7: 0_Regular | K7: 2_PosY | M7: Labor | N7: 3_NagY | O7: 1,2,3,4,5,6,7,8 | P7: 01 | S7: DONE | T7: PosYNagY | V7: =IF(SUM(X7:AG7)=0, 0, SUM(X7:AG7) / SUM($X$2:$AG$1012)) | X7: =IF(AND($S7="DONE", ISNUMBER(FIND(","&X$1&",", ","&SUBSTITUTE($O7," ","")&","))), 1/SUMPRODUCT(--ISNUMBER(FIND(","&X$1&",", ","&SUBSTITUTE($O$2:$O$1012," ","")&",")), --($S$2:$S$1012="DONE")), 0) | Y7: =IF(AND($S7="DONE", ISNUMBER(FIND(","&Y$1&",", ","&SUBSTITUTE($O7," ","")&","))), 1/SUMPRODUCT(--ISNUMBER(FIND(","&Y$1&",", ","&SUBSTITUTE($O$2:$O$1012," ","")&",")), --($S$2:$S$1012="DONE")), 0) | Z7: =IF(AND($S7="DONE", ISNUMBER(FIND(","&Z$1&",", ","&SUBSTITUTE($O7," ","")&","))), 1/SUMPRODUCT(--ISNUMBER(FIND(","&Z$1&",", ","&SUBSTITUTE($O$2:$O$1012," ","")&",")), --($S$2:$S$1012="DONE")), 0) | AA7: =IF(AND($S7="DONE", ISNUMBER(FIND(","&AA$1&",", ","&SUBSTITUTE($O7," ","")&","))), 1/SUMPRODUCT(--ISNUMBER(FIND(","&AA$1&",", ","&SUBSTITUTE($O$2:$O$1012," ","")&",")), --($S$2:$S$1012="DONE")), 0) | AB7: =IF(AND($S7="DONE", ISNUMBER(FIND(","&AB$1&",", ","&SUBSTITUTE($O7," ","")&","))), 1/SUMPRODUCT(--ISNUMBER(FIND(","&AB$1&",", ","&SUBSTITUTE($O$2:$O$1012," ","")&",")), --($S$2:$S$1012="DONE")), 0) | AC7: =IF(AND($S7="DONE", ISNUMBER(FIND(","&AC$1&",", ","&SUBSTITUTE($O7," ","")&","))), 1/SUMPRODUCT(--ISNUMBER(FIND(","&AC$1&",", ","&SUBSTITUTE($O$2:$O$1012," ","")&",")), --($S$2:$S$1012="DONE")), 0) | AD7: =IF(AND($S7="DONE", ISNUMBER(FIND(","&AD$1&",", ","&SUBSTITUTE($O7," ","")&","))), 1/SUMPRODUCT(--ISNUMBER(FIND(","&AD$1&",", ","&SUBSTITUTE($O$2:$O$1012," ","")&",")), --($S$2:$S$1012="DONE")), 0) | AE7: =IF(AND($S7="DONE", ISNUMBER(FIND(","&AE$1&",", ","&SUBSTITUTE($O7," ","")&","))), 1/SUMPRODUCT(--ISNUMBER(FIND(","&AE$1&",", ","&SUBSTITUTE($O$2:$O$1012," ","")&",")), --($S$2:$S$1012="DONE")), 0) | ... AG7: =IF(AND($S7="DONE", ISNUMBER(FIND(","&AG$1&",", ","&SUBSTITUTE($O7," ","")&","))), 1/SUMPRODUCT(--ISNUMBER(FIND(","&AG$1&",", ","&SUBSTITUTE($O$2:$O$1012," ","")&",")), --($S$2:$S$1012="DONE")), 0)
B8: L_Labor_PosX_NagX_S03_01 | C8: L_Labor_PosX_NagX_S03_01_Enemy | D8: L_Labor_PosX_NagX_S03_01_Reward | F8: /Game/Levels/Maps/Labor/SubLevel/Labor_S03/L_Labor_PosX_NagX_S03_01.L_Labor_PosX_NagX_S03_01 | G8: /Script/Engine.World'/Game/Levels/Maps/Labor/SubLevel/Labor_S03/L_Labor_PosX_NagX_S03_01_Enemy.L_Labor_PosX_NagX_S03_01_Enemy' | H8: /Script/Engine.World'/Game/Levels/Maps/Labor/SubLevel/Labor_S03/L_Labor_PosX_NagX_S03_01_Reward.L_Labor_PosX_NagX_S03_01_Reward' | I8: S03 | J8: 0_Regular | K8: 0_PosX | M8: Labor | N8: 1_NagX | O8: 1,2,3,4,5,6,7,8 | P8: 01 | S8: DONE | T8: PosXNagX | V8: =IF(SUM(X8:AG8)=0, 0, SUM(X8:AG8) / SUM($X$2:$AG$1012)) | X8: =IF(AND($S8="DONE", ISNUMBER(FIND(","&X$1&",", ","&SUBSTITUTE($O8," ","")&","))), 1/SUMPRODUCT(--ISNUMBER(FIND(","&X$1&",", ","&SUBSTITUTE($O$2:$O$1012," ","")&",")), --($S$2:$S$1012="DONE")), 0) | Y8: =IF(AND($S8="DONE", ISNUMBER(FIND(","&Y$1&",", ","&SUBSTITUTE($O8," ","")&","))), 1/SUMPRODUCT(--ISNUMBER(FIND(","&Y$1&",", ","&SUBSTITUTE($O$2:$O$1012," ","")&",")), --($S$2:$S$1012="DONE")), 0) | Z8: =IF(AND($S8="DONE", ISNUMBER(FIND(","&Z$1&",", ","&SUBSTITUTE($O8," ","")&","))), 1/SUMPRODUCT(--ISNUMBER(FIND(","&Z$1&",", ","&SUBSTITUTE($O$2:$O$1012," ","")&",")), --($S$2:$S$1012="DONE")), 0) | AA8: =IF(AND($S8="DONE", ISNUMBER(FIND(","&AA$1&",", ","&SUBSTITUTE($O8," ","")&","))), 1/SUMPRODUCT(--ISNUMBER(FIND(","&AA$1&",", ","&SUBSTITUTE($O$2:$O$1012," ","")&",")), --($S$2:$S$1012="DONE")), 0) | AB8: =IF(AND($S8="DONE", ISNUMBER(FIND(","&AB$1&",", ","&SUBSTITUTE($O8," ","")&","))), 1/SUMPRODUCT(--ISNUMBER(FIND(","&AB$1&",", ","&SUBSTITUTE($O$2:$O$1012," ","")&",")), --($S$2:$S$1012="DONE")), 0) | AC8: =IF(AND($S8="DONE", ISNUMBER(FIND(","&AC$1&",", ","&SUBSTITUTE($O8," ","")&","))), 1/SUMPRODUCT(--ISNUMBER(FIND(","&AC$1&",", ","&SUBSTITUTE($O$2:$O$1012," ","")&",")), --($S$2:$S$1012="DONE")), 0) | AD8: =IF(AND($S8="DONE", ISNUMBER(FIND(","&AD$1&",", ","&SUBSTITUTE($O8," ","")&","))), 1/SUMPRODUCT(--ISNUMBER(FIND(","&AD$1&",", ","&SUBSTITUTE($O$2:$O$1012," ","")&",")), --($S$2:$S$1012="DONE")), 0) | AE8: =IF(AND($S8="DONE", ISNUMBER(FIND(","&AE$1&",", ","&SUBSTITUTE($O8," ","")&","))), 1/SUMPRODUCT(--ISNUMBER(FIND(","&AE$1&",", ","&SUBSTITUTE($O$2:$O$1012," ","")&",")), --($S$2:$S$1012="DONE")), 0) | ... AG8: =IF(AND($S8="DONE", ISNUMBER(FIND(","&AG$1&",", ","&SUBSTITUTE($O8," ","")&","))), 1/SUMPRODUCT(--ISNUMBER(FIND(","&AG$1&",", ","&SUBSTITUTE($O$2:$O$1012," ","")&",")), --($S$2:$S$1012="DONE")), 0)
B9: L_Labor_PosY_PosY_S04_01 | C9: L_Labor_PosY_PosY_S04_01_Enemy | D9: L_Labor_PosY_PosY_S04_01_Reward | F9: /Game/Levels/Maps/Labor/SubLevel/Labor_S04/L_Labor_PosY_PosY_S04_01.L_Labor_PosY_PosY_S04_01 | G9: /Script/Engine.World'/Game/Levels/Maps/Labor/SubLevel/Labor_S04/L_Labor_PosY_PosY_S04_01_Enemy.L_Labor_PosY_PosY_S04_01_Enemy' | H9: /Script/Engine.World'/Game/Levels/Maps/Labor/SubLevel/Labor_S04/L_Labor_PosY_PosY_S04_01_Reward.L_Labor_PosY_PosY_S04_01_Reward' | I9: S04 | J9: 0_Regular | K9: 2_PosY | M9: Labor | N9: 2_PosY | O9: 1,2,3,4,5,6,7,8 | P9: 01 | S9: DONE | T9: PosYPosY | V9: =IF(SUM(X9:AG9)=0, 0, SUM(X9:AG9) / SUM($X$2:$AG$1012)) | X9: =IF(AND($S9="DONE", ISNUMBER(FIND(","&X$1&",", ","&SUBSTITUTE($O9," ","")&","))), 1/SUMPRODUCT(--ISNUMBER(FIND(","&X$1&",", ","&SUBSTITUTE($O$2:$O$1012," ","")&",")), --($S$2:$S$1012="DONE")), 0) | Y9: =IF(AND($S9="DONE", ISNUMBER(FIND(","&Y$1&",", ","&SUBSTITUTE($O9," ","")&","))), 1/SUMPRODUCT(--ISNUMBER(FIND(","&Y$1&",", ","&SUBSTITUTE($O$2:$O$1012," ","")&",")), --($S$2:$S$1012="DONE")), 0) | Z9: =IF(AND($S9="DONE", ISNUMBER(FIND(","&Z$1&",", ","&SUBSTITUTE($O9," ","")&","))), 1/SUMPRODUCT(--ISNUMBER(FIND(","&Z$1&",", ","&SUBSTITUTE($O$2:$O$1012," ","")&",")), --($S$2:$S$1012="DONE")), 0) | AA9: =IF(AND($S9="DONE", ISNUMBER(FIND(","&AA$1&",", ","&SUBSTITUTE($O9," ","")&","))), 1/SUMPRODUCT(--ISNUMBER(FIND(","&AA$1&",", ","&SUBSTITUTE($O$2:$O$1012," ","")&",")), --($S$2:$S$1012="DONE")), 0) | AB9: =IF(AND($S9="DONE", ISNUMBER(FIND(","&AB$1&",", ","&SUBSTITUTE($O9," ","")&","))), 1/SUMPRODUCT(--ISNUMBER(FIND(","&AB$1&",", ","&SUBSTITUTE($O$2:$O$1012," ","")&",")), --($S$2:$S$1012="DONE")), 0) | AC9: =IF(AND($S9="DONE", ISNUMBER(FIND(","&AC$1&",", ","&SUBSTITUTE($O9," ","")&","))), 1/SUMPRODUCT(--ISNUMBER(FIND(","&AC$1&",", ","&SUBSTITUTE($O$2:$O$1012," ","")&",")), --($S$2:$S$1012="DONE")), 0) | AD9: =IF(AND($S9="DONE", ISNUMBER(FIND(","&AD$1&",", ","&SUBSTITUTE($O9," ","")&","))), 1/SUMPRODUCT(--ISNUMBER(FIND(","&AD$1&",", ","&SUBSTITUTE($O$2:$O$1012," ","")&",")), --($S$2:$S$1012="DONE")), 0) | AE9: =IF(AND($S9="DONE", ISNUMBER(FIND(","&AE$1&",", ","&SUBSTITUTE($O9," ","")&","))), 1/SUMPRODUCT(--ISNUMBER(FIND(","&AE$1&",", ","&SUBSTITUTE($O$2:$O$1012," ","")&",")), --($S$2:$S$1012="DONE")), 0) | ... AG9: =IF(AND($S9="DONE", ISNUMBER(FIND(","&AG$1&",", ","&SUBSTITUTE($O9," ","")&","))), 1/SUMPRODUCT(--ISNUMBER(FIND(","&AG$1&",", ","&SUBSTITUTE($O$2:$O$1012," ","")&",")), --($S$2:$S$1012="DONE")), 0)
B10: L_Labor_NagY_PosY_S05_01 | C10: L_Labor_NagY_PosY_S05_01_Enemy | D10: L_Labor_NagY_PosY_S05_01_Reward | F10: /Game/Levels/Maps/Labor/SubLevel/Labor_S05/L_Labor_NagY_PosY_S05_01.L_Labor_NagY_PosY_S05_01 | G10: /Script/Engine.World'/Game/Levels/Maps/Labor/SubLevel/Labor_S05/L_Labor_NagY_PosY_S05_01_Enemy.L_Labor_NagY_PosY_S05_01_Enemy' | H10: /Script/Engine.World'/Game/Levels/Maps/Labor/SubLevel/Labor_S05/L_Labor_NagY_PosY_S05_01_Reward.L_Labor_NagY_PosY_S05_01_Reward' | I10: S05 | J10: 0_Regular | K10: 3_NagY | M10: Labor | N10: 2_PosY | O10: 1,2,3,4,5,6,7,8 | P10: 01 | S10: DONE | T10: NagYPosY | V10: =IF(SUM(X10:AG10)=0, 0, SUM(X10:AG10) / SUM($X$2:$AG$1012)) | X10: =IF(AND($S10="DONE", ISNUMBER(FIND(","&X$1&",", ","&SUBSTITUTE($O10," ","")&","))), 1/SUMPRODUCT(--ISNUMBER(FIND(","&X$1&",", ","&SUBSTITUTE($O$2:$O$1012," ","")&",")), --($S$2:$S$1012="DONE")), 0) | Y10: =IF(AND($S10="DONE", ISNUMBER(FIND(","&Y$1&",", ","&SUBSTITUTE($O10," ","")&","))), 1/SUMPRODUCT(--ISNUMBER(FIND(","&Y$1&",", ","&SUBSTITUTE($O$2:$O$1012," ","")&",")), --($S$2:$S$1012="DONE")), 0) | Z10: =IF(AND($S10="DONE", ISNUMBER(FIND(","&Z$1&",", ","&SUBSTITUTE($O10," ","")&","))), 1/SUMPRODUCT(--ISNUMBER(FIND(","&Z$1&",", ","&SUBSTITUTE($O$2:$O$1012," ","")&",")), --($S$2:$S$1012="DONE")), 0) | AA10: =IF(AND($S10="DONE", ISNUMBER(FIND(","&AA$1&",", ","&SUBSTITUTE($O10," ","")&","))), 1/SUMPRODUCT(--ISNUMBER(FIND(","&AA$1&",", ","&SUBSTITUTE($O$2:$O$1012," ","")&",")), --($S$2:$S$1012="DONE")), 0) | AB10: =IF(AND($S10="DONE", ISNUMBER(FIND(","&AB$1&",", ","&SUBSTITUTE($O10," ","")&","))), 1/SUMPRODUCT(--ISNUMBER(FIND(","&AB$1&",", ","&SUBSTITUTE($O$2:$O$1012," ","")&",")), --($S$2:$S$1012="DONE")), 0) | AC10: =IF(AND($S10="DONE", ISNUMBER(FIND(","&AC$1&",", ","&SUBSTITUTE($O10," ","")&","))), 1/SUMPRODUCT(--ISNUMBER(FIND(","&AC$1&",", ","&SUBSTITUTE($O$2:$O$1012," ","")&",")), --($S$2:$S$1012="DONE")), 0) | AD10: =IF(AND($S10="DONE", ISNUMBER(FIND(","&AD$1&",", ","&SUBSTITUTE($O10," ","")&","))), 1/SUMPRODUCT(--ISNUMBER(FIND(","&AD$1&",", ","&SUBSTITUTE($O$2:$O$1012," ","")&",")), --($S$2:$S$1012="DONE")), 0) | AE10: =IF(AND($S10="DONE", ISNUMBER(FIND(","&AE$1&",", ","&SUBSTITUTE($O10," ","")&","))), 1/SUMPRODUCT(--ISNUMBER(FIND(","&AE$1&",", ","&SUBSTITUTE($O$2:$O$1012," ","")&",")), --($S$2:$S$1012="DONE")), 0) | ... AG10: =IF(AND($S10="DONE", ISNUMBER(FIND(","&AG$1&",", ","&SUBSTITUTE($O10," ","")&","))), 1/SUMPRODUCT(--ISNUMBER(FIND(","&AG$1&",", ","&SUBSTITUTE($O$2:$O$1012," ","")&",")), --($S$2:$S$1012="DONE")), 0)
B11: L_Labor_PosX_NagX_S06_01 | C11: L_Labor_PosX_NagX_S06_01_Enemy | D11: L_Labor_PosX_NagX_S06_01_Reward | F11: /Game/Levels/Maps/Labor/SubLevel/Labor_S06/L_Labor_PosX_NagX_S06_01.L_Labor_PosX_NagX_S06_01 | G11: /Script/Engine.World'/Game/Levels/Maps/Labor/SubLevel/Labor_S06/L_Labor_PosX_NagX_S06_01_Enemy.L_Labor_PosX_NagX_S06_01_Enemy' | H11: /Script/Engine.World'/Game/Levels/Maps/Labor/SubLevel/Labor_S06/L_Labor_PosX_NagX_S06_01_Reward.L_Labor_PosX_NagX_S06_01_Reward' | I11: S06 | J11: 0_Regular | K11: 0_PosX | M11: Labor | N11: 1_NagX | O11: 1,2,3,4,5,6,7,8 | P11: 01 | S11: DONE | T11: PosXNagX | V11: =IF(SUM(X11:AG11)=0, 0, SUM(X11:AG11) / SUM($X$2:$AG$1012)) | X11: =IF(AND($S11="DONE", ISNUMBER(FIND(","&X$1&",", ","&SUBSTITUTE($O11," ","")&","))), 1/SUMPRODUCT(--ISNUMBER(FIND(","&X$1&",", ","&SUBSTITUTE($O$2:$O$1012," ","")&",")), --($S$2:$S$1012="DONE")), 0) | Y11: =IF(AND($S11="DONE", ISNUMBER(FIND(","&Y$1&",", ","&SUBSTITUTE($O11," ","")&","))), 1/SUMPRODUCT(--ISNUMBER(FIND(","&Y$1&",", ","&SUBSTITUTE($O$2:$O$1012," ","")&",")), --($S$2:$S$1012="DONE")), 0) | Z11: =IF(AND($S11="DONE", ISNUMBER(FIND(","&Z$1&",", ","&SUBSTITUTE($O11," ","")&","))), 1/SUMPRODUCT(--ISNUMBER(FIND(","&Z$1&",", ","&SUBSTITUTE($O$2:$O$1012," ","")&",")), --($S$2:$S$1012="DONE")), 0) | AA11: =IF(AND($S11="DONE", ISNUMBER(FIND(","&AA$1&",", ","&SUBSTITUTE($O11," ","")&","))), 1/SUMPRODUCT(--ISNUMBER(FIND(","&AA$1&",", ","&SUBSTITUTE($O$2:$O$1012," ","")&",")), --($S$2:$S$1012="DONE")), 0) | AB11: =IF(AND($S11="DONE", ISNUMBER(FIND(","&AB$1&",", ","&SUBSTITUTE($O11," ","")&","))), 1/SUMPRODUCT(--ISNUMBER(FIND(","&AB$1&",", ","&SUBSTITUTE($O$2:$O$1012," ","")&",")), --($S$2:$S$1012="DONE")), 0) | AC11: =IF(AND($S11="DONE", ISNUMBER(FIND(","&AC$1&",", ","&SUBSTITUTE($O11," ","")&","))), 1/SUMPRODUCT(--ISNUMBER(FIND(","&AC$1&",", ","&SUBSTITUTE($O$2:$O$1012," ","")&",")), --($S$2:$S$1012="DONE")), 0) | AD11: =IF(AND($S11="DONE", ISNUMBER(FIND(","&AD$1&",", ","&SUBSTITUTE($O11," ","")&","))), 1/SUMPRODUCT(--ISNUMBER(FIND(","&AD$1&",", ","&SUBSTITUTE($O$2:$O$1012," ","")&",")), --($S$2:$S$1012="DONE")), 0) | AE11: =IF(AND($S11="DONE", ISNUMBER(FIND(","&AE$1&",", ","&SUBSTITUTE($O11," ","")&","))), 1/SUMPRODUCT(--ISNUMBER(FIND(","&AE$1&",", ","&SUBSTITUTE($O$2:$O$1012," ","")&",")), --($S$2:$S$1012="DONE")), 0) | ... AG11: =IF(AND($S11="DONE", ISNUMBER(FIND(","&AG$1&",", ","&SUBSTITUTE($O11," ","")&","))), 1/SUMPRODUCT(--ISNUMBER(FIND(","&AG$1&",", ","&SUBSTITUTE($O$2:$O$1012," ","")&",")), --($S$2:$S$1012="DONE")), 0)
B12: L_Labor_PosX_PosY_S07_01 | C12: L_Labor_PosX_PosY_S07_01_Enemy | D12: L_Labor_PosX_PosY_S07_01_Reward | F12: /Game/Levels/Maps/Labor/SubLevel/Labor_S07/L_Labor_PosX_PosY_S07_01.L_Labor_PosX_PosY_S07_01 | G12: /Script/Engine.World'/Game/Levels/Maps/Labor/SubLevel/Labor_S07/L_Labor_PosX_PosY_S07_01_Enemy.L_Labor_PosX_PosY_S07_01_Enemy' | H12: /Script/Engine.World'/Game/Levels/Maps/Labor/SubLevel/Labor_S07/L_Labor_PosX_PosY_S07_01_Reward.L_Labor_PosX_PosY_S07_01_Reward' | I12: S07 | J12: 0_Regular | K12: 0_PosX | M12: Labor | N12: 2_PosY | O12: 1,2,3,4,5,6,7,8 | P12: 01 | S12: DONE | T12: PosXPosY | V12: =IF(SUM(X12:AG12)=0, 0, SUM(X12:AG12) / SUM($X$2:$AG$1012)) | X12: =IF(AND($S12="DONE", ISNUMBER(FIND(","&X$1&",", ","&SUBSTITUTE($O12," ","")&","))), 1/SUMPRODUCT(--ISNUMBER(FIND(","&X$1&",", ","&SUBSTITUTE($O$2:$O$1012," ","")&",")), --($S$2:$S$1012="DONE")), 0) | Y12: =IF(AND($S12="DONE", ISNUMBER(FIND(","&Y$1&",", ","&SUBSTITUTE($O12," ","")&","))), 1/SUMPRODUCT(--ISNUMBER(FIND(","&Y$1&",", ","&SUBSTITUTE($O$2:$O$1012," ","")&",")), --($S$2:$S$1012="DONE")), 0) | Z12: =IF(AND($S12="DONE", ISNUMBER(FIND(","&Z$1&",", ","&SUBSTITUTE($O12," ","")&","))), 1/SUMPRODUCT(--ISNUMBER(FIND(","&Z$1&",", ","&SUBSTITUTE($O$2:$O$1012," ","")&",")), --($S$2:$S$1012="DONE")), 0) | AA12: =IF(AND($S12="DONE", ISNUMBER(FIND(","&AA$1&",", ","&SUBSTITUTE($O12," ","")&","))), 1/SUMPRODUCT(--ISNUMBER(FIND(","&AA$1&",", ","&SUBSTITUTE($O$2:$O$1012," ","")&",")), --($S$2:$S$1012="DONE")), 0) | AB12: =IF(AND($S12="DONE", ISNUMBER(FIND(","&AB$1&",", ","&SUBSTITUTE($O12," ","")&","))), 1/SUMPRODUCT(--ISNUMBER(FIND(","&AB$1&",", ","&SUBSTITUTE($O$2:$O$1012," ","")&",")), --($S$2:$S$1012="DONE")), 0) | AC12: =IF(AND($S12="DONE", ISNUMBER(FIND(","&AC$1&",", ","&SUBSTITUTE($O12," ","")&","))), 1/SUMPRODUCT(--ISNUMBER(FIND(","&AC$1&",", ","&SUBSTITUTE($O$2:$O$1012," ","")&",")), --($S$2:$S$1012="DONE")), 0) | AD12: =IF(AND($S12="DONE", ISNUMBER(FIND(","&AD$1&",", ","&SUBSTITUTE($O12," ","")&","))), 1/SUMPRODUCT(--ISNUMBER(FIND(","&AD$1&",", ","&SUBSTITUTE($O$2:$O$1012," ","")&",")), --($S$2:$S$1012="DONE")), 0) | AE12: =IF(AND($S12="DONE", ISNUMBER(FIND(","&AE$1&",", ","&SUBSTITUTE($O12," ","")&","))), 1/SUMPRODUCT(--ISNUMBER(FIND(","&AE$1&",", ","&SUBSTITUTE($O$2:$O$1012," ","")&",")), --($S$2:$S$1012="DONE")), 0) | ... AG12: =IF(AND($S12="DONE", ISNUMBER(FIND(","&AG$1&",", ","&SUBSTITUTE($O12," ","")&","))), 1/SUMPRODUCT(--ISNUMBER(FIND(","&AG$1&",", ","&SUBSTITUTE($O$2:$O$1012," ","")&",")), --($S$2:$S$1012="DONE")), 0)
B13: L_Labor_NagY_NagX_S08_01 | C13: L_Labor_NagY_NagX_S08_01_Enemy | D13: L_Labor_NagY_NagX_S08_01_Reward | F13: /Game/Levels/Maps/Labor/SubLevel/Labor_S08/L_Labor_NagY_NagX_S08_01.L_Labor_NagY_NagX_S08_01 | G13: /Script/Engine.World'/Game/Levels/Maps/Labor/SubLevel/Labor_S08/L_Labor_NagY_NagX_S08_01_Enemy.L_Labor_NagY_NagX_S08_01_Enemy' | H13: /Script/Engine.World'/Game/Levels/Maps/Labor/SubLevel/Labor_S08/L_Labor_NagY_NagX_S08_01_Reward.L_Labor_NagY_NagX_S08_01_Reward' | I13: S08 | J13: 2_Reward | K13: 3_NagY | M13: Labor | N13: 1_NagX | O13: 1,2,3,4,5,6,7,8 | P13: 01 | S13: DONE | T13: NagYNagX | V13: =IF(SUM(X13:AG13)=0, 0, SUM(X13:AG13) / SUM($X$2:$AG$1012)) | X13: =IF(AND($S13="DONE", ISNUMBER(FIND(","&X$1&",", ","&SUBSTITUTE($O13," ","")&","))), 1/SUMPRODUCT(--ISNUMBER(FIND(","&X$1&",", ","&SUBSTITUTE($O$2:$O$1012," ","")&",")), --($S$2:$S$1012="DONE")), 0) | Y13: =IF(AND($S13="DONE", ISNUMBER(FIND(","&Y$1&",", ","&SUBSTITUTE($O13," ","")&","))), 1/SUMPRODUCT(--ISNUMBER(FIND(","&Y$1&",", ","&SUBSTITUTE($O$2:$O$1012," ","")&",")), --($S$2:$S$1012="DONE")), 0) | Z13: =IF(AND($S13="DONE", ISNUMBER(FIND(","&Z$1&",", ","&SUBSTITUTE($O13," ","")&","))), 1/SUMPRODUCT(--ISNUMBER(FIND(","&Z$1&",", ","&SUBSTITUTE($O$2:$O$1012," ","")&",")), --($S$2:$S$1012="DONE")), 0) | AA13: =IF(AND($S13="DONE", ISNUMBER(FIND(","&AA$1&",", ","&SUBSTITUTE($O13," ","")&","))), 1/SUMPRODUCT(--ISNUMBER(FIND(","&AA$1&",", ","&SUBSTITUTE($O$2:$O$1012," ","")&",")), --($S$2:$S$1012="DONE")), 0) | AB13: =IF(AND($S13="DONE", ISNUMBER(FIND(","&AB$1&",", ","&SUBSTITUTE($O13," ","")&","))), 1/SUMPRODUCT(--ISNUMBER(FIND(","&AB$1&",", ","&SUBSTITUTE($O$2:$O$1012," ","")&",")), --($S$2:$S$1012="DONE")), 0) | AC13: =IF(AND($S13="DONE", ISNUMBER(FIND(","&AC$1&",", ","&SUBSTITUTE($O13," ","")&","))), 1/SUMPRODUCT(--ISNUMBER(FIND(","&AC$1&",", ","&SUBSTITUTE($O$2:$O$1012," ","")&",")), --($S$2:$S$1012="DONE")), 0) | AD13: =IF(AND($S13="DONE", ISNUMBER(FIND(","&AD$1&",", ","&SUBSTITUTE($O13," ","")&","))), 1/SUMPRODUCT(--ISNUMBER(FIND(","&AD$1&",", ","&SUBSTITUTE($O$2:$O$1012," ","")&",")), --($S$2:$S$1012="DONE")), 0) | AE13: =IF(AND($S13="DONE", ISNUMBER(FIND(","&AE$1&",", ","&SUBSTITUTE($O13," ","")&","))), 1/SUMPRODUCT(--ISNUMBER(FIND(","&AE$1&",", ","&SUBSTITUTE($O$2:$O$1012," ","")&",")), --($S$2:$S$1012="DONE")), 0) | ... AG13: =IF(AND($S13="DONE", ISNUMBER(FIND(","&AG$1&",", ","&SUBSTITUTE($O13," ","")&","))), 1/SUMPRODUCT(--ISNUMBER(FIND(","&AG$1&",", ","&SUBSTITUTE($O$2:$O$1012," ","")&",")), --($S$2:$S$1012="DONE")), 0)
B14: L_Labor_Initial_NagY_S09_01 | C14: L_Labor_Initial_NagY_S09_01_Enemy | D14: L_Labor_Initial_NagY_S09_01_Reward | F14: /Game/Levels/Maps/Labor/SubLevel/Labor_S09/L_Labor_Initial_NagY_S09_01.L_Labor_Initial_NagY_S09_01 | G14: /Script/Engine.World'/Game/Levels/Maps/Labor/SubLevel/Labor_S09/L_Labor_Initial_NagY_S09_01_Enemy.L_Labor_Initial_NagY_S09_01_Enemy' | H14: /Script/Engine.World'/Game/Levels/Maps/Labor/SubLevel/Labor_S09/L_Labor_Initial_NagY_S09_01_Reward.L_Labor_Initial_NagY_S09_01_Reward' | I14: S09 | J14: 1_Initial | K14: 0_Initial | M14: Labor | N14: 3_NagY | O14: 1 | P14: 01 | S14: DONE | T14: InitialNagY | V14: =IF(SUM(X14:AG14)=0, 0, SUM(X14:AG14) / SUM($X$2:$AG$1012)) | X14: =IF(AND($S14="DONE", ISNUMBER(FIND(","&X$1&",", ","&SUBSTITUTE($O14," ","")&","))), 1/SUMPRODUCT(--ISNUMBER(FIND(","&X$1&",", ","&SUBSTITUTE($O$2:$O$1012," ","")&",")), --($S$2:$S$1012="DONE")), 0) | Y14: =IF(AND($S14="DONE", ISNUMBER(FIND(","&Y$1&",", ","&SUBSTITUTE($O14," ","")&","))), 1/SUMPRODUCT(--ISNUMBER(FIND(","&Y$1&",", ","&SUBSTITUTE($O$2:$O$1012," ","")&",")), --($S$2:$S$1012="DONE")), 0) | Z14: =IF(AND($S14="DONE", ISNUMBER(FIND(","&Z$1&",", ","&SUBSTITUTE($O14," ","")&","))), 1/SUMPRODUCT(--ISNUMBER(FIND(","&Z$1&",", ","&SUBSTITUTE($O$2:$O$1012," ","")&",")), --($S$2:$S$1012="DONE")), 0) | AA14: =IF(AND($S14="DONE", ISNUMBER(FIND(","&AA$1&",", ","&SUBSTITUTE($O14," ","")&","))), 1/SUMPRODUCT(--ISNUMBER(FIND(","&AA$1&",", ","&SUBSTITUTE($O$2:$O$1012," ","")&",")), --($S$2:$S$1012="DONE")), 0) | AB14: =IF(AND($S14="DONE", ISNUMBER(FIND(","&AB$1&",", ","&SUBSTITUTE($O14," ","")&","))), 1/SUMPRODUCT(--ISNUMBER(FIND(","&AB$1&",", ","&SUBSTITUTE($O$2:$O$1012," ","")&",")), --($S$2:$S$1012="DONE")), 0) | AC14: =IF(AND($S14="DONE", ISNUMBER(FIND(","&AC$1&",", ","&SUBSTITUTE($O14," ","")&","))), 1/SUMPRODUCT(--ISNUMBER(FIND(","&AC$1&",", ","&SUBSTITUTE($O$2:$O$1012," ","")&",")), --($S$2:$S$1012="DONE")), 0) | AD14: =IF(AND($S14="DONE", ISNUMBER(FIND(","&AD$1&",", ","&SUBSTITUTE($O14," ","")&","))), 1/SUMPRODUCT(--ISNUMBER(FIND(","&AD$1&",", ","&SUBSTITUTE($O$2:$O$1012," ","")&",")), --($S$2:$S$1012="DONE")), 0) | AE14: =IF(AND($S14="DONE", ISNUMBER(FIND(","&AE$1&",", ","&SUBSTITUTE($O14," ","")&","))), 1/SUMPRODUCT(--ISNUMBER(FIND(","&AE$1&",", ","&SUBSTITUTE($O$2:$O$1012," ","")&",")), --($S$2:$S$1012="DONE")), 0) | ... AG14: =IF(AND($S14="DONE", ISNUMBER(FIND(","&AG$1&",", ","&SUBSTITUTE($O14," ","")&","))), 1/SUMPRODUCT(--ISNUMBER(FIND(","&AG$1&",", ","&SUBSTITUTE($O$2:$O$1012," ","")&",")), --($S$2:$S$1012="DONE")), 0)
B15: L_Labor_Initial_NagX_S09_01 | C15: L_Labor_Initial_NagX_S09_01_Enemy | D15: L_Labor_Initial_NagX_S09_01_Reward | F15: /Game/Levels/Maps/Labor/SubLevel/Labor_S09/L_Labor_Initial_NagX_S09_01.L_Labor_Initial_NagX_S09_01 | G15: /Script/Engine.World'/Game/Levels/Maps/Labor/SubLevel/Labor_S09/L_Labor_Initial_NagX_S09_01_Enemy.L_Labor_Initial_NagX_S09_01_Enemy' | H15: /Script/Engine.World'/Game/Levels/Maps/Labor/SubLevel/Labor_S09/L_Labor_Initial_NagX_S09_01_Reward.L_Labor_Initial_NagX_S09_01_Reward' | I15: S09 | J15: 1_Initial | K15: 0_Initial | M15: Labor | N15: 1_NagX | O15: 1 | P15: 01 | S15: NEED FIX | V15: =IF(SUM(X15:AG15)=0, 0, SUM(X15:AG15) / SUM($X$2:$AG$1012)) | X15: =IF(AND($S15="DONE", ISNUMBER(FIND(","&X$1&",", ","&SUBSTITUTE($O15," ","")&","))), 1/SUMPRODUCT(--ISNUMBER(FIND(","&X$1&",", ","&SUBSTITUTE($O$2:$O$1012," ","")&",")), --($S$2:$S$1012="DONE")), 0) | Y15: =IF(AND($S15="DONE", ISNUMBER(FIND(","&Y$1&",", ","&SUBSTITUTE($O15," ","")&","))), 1/SUMPRODUCT(--ISNUMBER(FIND(","&Y$1&",", ","&SUBSTITUTE($O$2:$O$1012," ","")&",")), --($S$2:$S$1012="DONE")), 0) | Z15: =IF(AND($S15="DONE", ISNUMBER(FIND(","&Z$1&",", ","&SUBSTITUTE($O15," ","")&","))), 1/SUMPRODUCT(--ISNUMBER(FIND(","&Z$1&",", ","&SUBSTITUTE($O$2:$O$1012," ","")&",")), --($S$2:$S$1012="DONE")), 0) | AA15: =IF(AND($S15="DONE", ISNUMBER(FIND(","&AA$1&",", ","&SUBSTITUTE($O15," ","")&","))), 1/SUMPRODUCT(--ISNUMBER(FIND(","&AA$1&",", ","&SUBSTITUTE($O$2:$O$1012," ","")&",")), --($S$2:$S$1012="DONE")), 0) | AB15: =IF(AND($S15="DONE", ISNUMBER(FIND(","&AB$1&",", ","&SUBSTITUTE($O15," ","")&","))), 1/SUMPRODUCT(--ISNUMBER(FIND(","&AB$1&",", ","&SUBSTITUTE($O$2:$O$1012," ","")&",")), --($S$2:$S$1012="DONE")), 0) | AC15: =IF(AND($S15="DONE", ISNUMBER(FIND(","&AC$1&",", ","&SUBSTITUTE($O15," ","")&","))), 1/SUMPRODUCT(--ISNUMBER(FIND(","&AC$1&",", ","&SUBSTITUTE($O$2:$O$1012," ","")&",")), --($S$2:$S$1012="DONE")), 0) | AD15: =IF(AND($S15="DONE", ISNUMBER(FIND(","&AD$1&",", ","&SUBSTITUTE($O15," ","")&","))), 1/SUMPRODUCT(--ISNUMBER(FIND(","&AD$1&",", ","&SUBSTITUTE($O$2:$O$1012," ","")&",")), --($S$2:$S$1012="DONE")), 0) | AE15: =IF(AND($S15="DONE", ISNUMBER(FIND(","&AE$1&",", ","&SUBSTITUTE($O15," ","")&","))), 1/SUMPRODUCT(--ISNUMBER(FIND(","&AE$1&",", ","&SUBSTITUTE($O$2:$O$1012," ","")&",")), --($S$2:$S$1012="DONE")), 0) | ... AG15: =IF(AND($S15="DONE", ISNUMBER(FIND(","&AG$1&",", ","&SUBSTITUTE($O15," ","")&","))), 1/SUMPRODUCT(--ISNUMBER(FIND(","&AG$1&",", ","&SUBSTITUTE($O$2:$O$1012," ","")&",")), --($S$2:$S$1012="DONE")), 0)
B16: L_Labor_Initial_PosY_S09_01 | C16: L_Labor_Initial_PosY_S09_01_Enemy | D16: L_Labor_Initial_PosY_S09_01_Reward | F16: /Game/Levels/Maps/Labor/SubLevel/Labor_S09/L_Labor_Initial_PosY_S09_01.L_Labor_Initial_PosY_S09_01 | G16: /Script/Engine.World'/Game/Levels/Maps/Labor/SubLevel/Labor_S09/L_Labor_Initial_PosY_S09_01_Enemy.L_Labor_Initial_PosY_S09_01_Enemy' | H16: /Script/Engine.World'/Game/Levels/Maps/Labor/SubLevel/Labor_S09/L_Labor_Initial_PosY_S09_01_Reward.L_Labor_Initial_PosY_S09_01_Reward' | I16: S09 | J16: 1_Initial | K16: 0_Initial | M16: Labor | N16: 2_PosY | O16: 1 | P16: 01 | S16: NEED FIX | V16: =IF(SUM(X16:AG16)=0, 0, SUM(X16:AG16) / SUM($X$2:$AG$1012)) | X16: =IF(AND($S16="DONE", ISNUMBER(FIND(","&X$1&",", ","&SUBSTITUTE($O16," ","")&","))), 1/SUMPRODUCT(--ISNUMBER(FIND(","&X$1&",", ","&SUBSTITUTE($O$2:$O$1012," ","")&",")), --($S$2:$S$1012="DONE")), 0) | Y16: =IF(AND($S16="DONE", ISNUMBER(FIND(","&Y$1&",", ","&SUBSTITUTE($O16," ","")&","))), 1/SUMPRODUCT(--ISNUMBER(FIND(","&Y$1&",", ","&SUBSTITUTE($O$2:$O$1012," ","")&",")), --($S$2:$S$1012="DONE")), 0) | Z16: =IF(AND($S16="DONE", ISNUMBER(FIND(","&Z$1&",", ","&SUBSTITUTE($O16," ","")&","))), 1/SUMPRODUCT(--ISNUMBER(FIND(","&Z$1&",", ","&SUBSTITUTE($O$2:$O$1012," ","")&",")), --($S$2:$S$1012="DONE")), 0) | AA16: =IF(AND($S16="DONE", ISNUMBER(FIND(","&AA$1&",", ","&SUBSTITUTE($O16," ","")&","))), 1/SUMPRODUCT(--ISNUMBER(FIND(","&AA$1&",", ","&SUBSTITUTE($O$2:$O$1012," ","")&",")), --($S$2:$S$1012="DONE")), 0) | AB16: =IF(AND($S16="DONE", ISNUMBER(FIND(","&AB$1&",", ","&SUBSTITUTE($O16," ","")&","))), 1/SUMPRODUCT(--ISNUMBER(FIND(","&AB$1&",", ","&SUBSTITUTE($O$2:$O$1012," ","")&",")), --($S$2:$S$1012="DONE")), 0) | AC16: =IF(AND($S16="DONE", ISNUMBER(FIND(","&AC$1&",", ","&SUBSTITUTE($O16," ","")&","))), 1/SUMPRODUCT(--ISNUMBER(FIND(","&AC$1&",", ","&SUBSTITUTE($O$2:$O$1012," ","")&",")), --($S$2:$S$1012="DONE")), 0) | AD16: =IF(AND($S16="DONE", ISNUMBER(FIND(","&AD$1&",", ","&SUBSTITUTE($O16," ","")&","))), 1/SUMPRODUCT(--ISNUMBER(FIND(","&AD$1&",", ","&SUBSTITUTE($O$2:$O$1012," ","")&",")), --($S$2:$S$1012="DONE")), 0) | AE16: =IF(AND($S16="DONE", ISNUMBER(FIND(","&AE$1&",", ","&SUBSTITUTE($O16," ","")&","))), 1/SUMPRODUCT(--ISNUMBER(FIND(","&AE$1&",", ","&SUBSTITUTE($O$2:$O$1012," ","")&",")), --($S$2:$S$1012="DONE")), 0) | ... AG16: =IF(AND($S16="DONE", ISNUMBER(FIND(","&AG$1&",", ","&SUBSTITUTE($O16," ","")&","))), 1/SUMPRODUCT(--ISNUMBER(FIND(","&AG$1&",", ","&SUBSTITUTE($O$2:$O$1012," ","")&",")), --($S$2:$S$1012="DONE")), 0)
B17: L_Labor_Initial_NagY_S09_01 | C17: L_Labor_Initial_NagY_S09_01_Enemy | D17: L_Labor_Initial_NagY_S09_01_Reward | F17: /Game/Levels/Maps/Labor/SubLevel/Labor_S09/L_Labor_Initial_NagY_S09_01.L_Labor_Initial_NagY_S09_01 | G17: /Script/Engine.World'/Game/Levels/Maps/Labor/SubLevel/Labor_S09/L_Labor_Initial_NagY_S09_01_Enemy.L_Labor_Initial_NagY_S09_01_Enemy' | H17: /Script/Engine.World'/Game/Levels/Maps/Labor/SubLevel/Labor_S09/L_Labor_Initial_NagY_S09_01_Reward.L_Labor_Initial_NagY_S09_01_Reward' | I17: S09 | J17: 1_Initial | K17: 0_Initial | M17: Labor | N17: 3_NagY | O17: 1 | P17: 01 | S17: NEED FIX | V17: =IF(SUM(X17:AG17)=0, 0, SUM(X17:AG17) / SUM($X$2:$AG$1012)) | X17: =IF(AND($S17="DONE", ISNUMBER(FIND(","&X$1&",", ","&SUBSTITUTE($O17," ","")&","))), 1/SUMPRODUCT(--ISNUMBER(FIND(","&X$1&",", ","&SUBSTITUTE($O$2:$O$1012," ","")&",")), --($S$2:$S$1012="DONE")), 0) | Y17: =IF(AND($S17="DONE", ISNUMBER(FIND(","&Y$1&",", ","&SUBSTITUTE($O17," ","")&","))), 1/SUMPRODUCT(--ISNUMBER(FIND(","&Y$1&",", ","&SUBSTITUTE($O$2:$O$1012," ","")&",")), --($S$2:$S$1012="DONE")), 0) | Z17: =IF(AND($S17="DONE", ISNUMBER(FIND(","&Z$1&",", ","&SUBSTITUTE($O17," ","")&","))), 1/SUMPRODUCT(--ISNUMBER(FIND(","&Z$1&",", ","&SUBSTITUTE($O$2:$O$1012," ","")&",")), --($S$2:$S$1012="DONE")), 0) | AA17: =IF(AND($S17="DONE", ISNUMBER(FIND(","&AA$1&",", ","&SUBSTITUTE($O17," ","")&","))), 1/SUMPRODUCT(--ISNUMBER(FIND(","&AA$1&",", ","&SUBSTITUTE($O$2:$O$1012," ","")&",")), --($S$2:$S$1012="DONE")), 0) | AB17: =IF(AND($S17="DONE", ISNUMBER(FIND(","&AB$1&",", ","&SUBSTITUTE($O17," ","")&","))), 1/SUMPRODUCT(--ISNUMBER(FIND(","&AB$1&",", ","&SUBSTITUTE($O$2:$O$1012," ","")&",")), --($S$2:$S$1012="DONE")), 0) | AC17: =IF(AND($S17="DONE", ISNUMBER(FIND(","&AC$1&",", ","&SUBSTITUTE($O17," ","")&","))), 1/SUMPRODUCT(--ISNUMBER(FIND(","&AC$1&",", ","&SUBSTITUTE($O$2:$O$1012," ","")&",")), --($S$2:$S$1012="DONE")), 0) | AD17: =IF(AND($S17="DONE", ISNUMBER(FIND(","&AD$1&",", ","&SUBSTITUTE($O17," ","")&","))), 1/SUMPRODUCT(--ISNUMBER(FIND(","&AD$1&",", ","&SUBSTITUTE($O$2:$O$1012," ","")&",")), --($S$2:$S$1012="DONE")), 0) | AE17: =IF(AND($S17="DONE", ISNUMBER(FIND(","&AE$1&",", ","&SUBSTITUTE($O17," ","")&","))), 1/SUMPRODUCT(--ISNUMBER(FIND(","&AE$1&",", ","&SUBSTITUTE($O$2:$O$1012," ","")&",")), --($S$2:$S$1012="DONE")), 0) | ... AG17: =IF(AND($S17="DONE", ISNUMBER(FIND(","&AG$1&",", ","&SUBSTITUTE($O17," ","")&","))), 1/SUMPRODUCT(--ISNUMBER(FIND(","&AG$1&",", ","&SUBSTITUTE($O$2:$O$1012," ","")&",")), --($S$2:$S$1012="DONE")), 0)
B18: L_Labor_Initial_NagY_S09_01 | C18: L_Labor_Initial_NagY_S09_01_Enemy | D18: L_Labor_Initial_NagY_S09_01_Reward | F18: /Game/Levels/Maps/Labor/SubLevel/Labor_S09/L_Labor_Initial_NagY_S09_01.L_Labor_Initial_NagY_S09_01 | G18: /Script/Engine.World'/Game/Levels/Maps/Labor/SubLevel/Labor_S09/L_Labor_Initial_NagY_S09_01_Enemy.L_Labor_Initial_NagY_S09_01_Enemy' | H18: /Script/Engine.World'/Game/Levels/Maps/Labor/SubLevel/Labor_S09/L_Labor_Initial_NagY_S09_01_Reward.L_Labor_Initial_NagY_S09_01_Reward' | I18: S09 | J18: 0_Regular | K18: 0_Initial | M18: Labor | N18: 3_NagY | O18: 1,2,3,4,5,6,7,8 | P18: 01 | S18: NEED FIX | V18: =IF(SUM(X18:AG18)=0, 0, SUM(X18:AG18) / SUM($X$2:$AG$1012)) | X18: =IF(AND($S18="DONE", ISNUMBER(FIND(","&X$1&",", ","&SUBSTITUTE($O18," ","")&","))), 1/SUMPRODUCT(--ISNUMBER(FIND(","&X$1&",", ","&SUBSTITUTE($O$2:$O$1012," ","")&",")), --($S$2:$S$1012="DONE")), 0) | Y18: =IF(AND($S18="DONE", ISNUMBER(FIND(","&Y$1&",", ","&SUBSTITUTE($O18," ","")&","))), 1/SUMPRODUCT(--ISNUMBER(FIND(","&Y$1&",", ","&SUBSTITUTE($O$2:$O$1012," ","")&",")), --($S$2:$S$1012="DONE")), 0) | Z18: =IF(AND($S18="DONE", ISNUMBER(FIND(","&Z$1&",", ","&SUBSTITUTE($O18," ","")&","))), 1/SUMPRODUCT(--ISNUMBER(FIND(","&Z$1&",", ","&SUBSTITUTE($O$2:$O$1012," ","")&",")), --($S$2:$S$1012="DONE")), 0) | AA18: =IF(AND($S18="DONE", ISNUMBER(FIND(","&AA$1&",", ","&SUBSTITUTE($O18," ","")&","))), 1/SUMPRODUCT(--ISNUMBER(FIND(","&AA$1&",", ","&SUBSTITUTE($O$2:$O$1012," ","")&",")), --($S$2:$S$1012="DONE")), 0) | AB18: =IF(AND($S18="DONE", ISNUMBER(FIND(","&AB$1&",", ","&SUBSTITUTE($O18," ","")&","))), 1/SUMPRODUCT(--ISNUMBER(FIND(","&AB$1&",", ","&SUBSTITUTE($O$2:$O$1012," ","")&",")), --($S$2:$S$1012="DONE")), 0) | AC18: =IF(AND($S18="DONE", ISNUMBER(FIND(","&AC$1&",", ","&SUBSTITUTE($O18," ","")&","))), 1/SUMPRODUCT(--ISNUMBER(FIND(","&AC$1&",", ","&SUBSTITUTE($O$2:$O$1012," ","")&",")), --($S$2:$S$1012="DONE")), 0) | AD18: =IF(AND($S18="DONE", ISNUMBER(FIND(","&AD$1&",", ","&SUBSTITUTE($O18," ","")&","))), 1/SUMPRODUCT(--ISNUMBER(FIND(","&AD$1&",", ","&SUBSTITUTE($O$2:$O$1012," ","")&",")), --($S$2:$S$1012="DONE")), 0) | AE18: =IF(AND($S18="DONE", ISNUMBER(FIND(","&AE$1&",", ","&SUBSTITUTE($O18," ","")&","))), 1/SUMPRODUCT(--ISNUMBER(FIND(","&AE$1&",", ","&SUBSTITUTE($O$2:$O$1012," ","")&",")), --($S$2:$S$1012="DONE")), 0) | ... AG18: =IF(AND($S18="DONE", ISNUMBER(FIND(","&AG$1&",", ","&SUBSTITUTE($O18," ","")&","))), 1/SUMPRODUCT(--ISNUMBER(FIND(","&AG$1&",", ","&SUBSTITUTE($O$2:$O$1012," ","")&",")), --($S$2:$S$1012="DONE")), 0)
