Workbook

Sheet 动画分类
A1: 动作来源 | B1: 供应商 | C1: 使用中 | E1: 动作分类 | F1: 优先级 | G1: 定义
A2: Sword Animation Pro | B2: MoCap | C2: =COUNTIF('动画列表'!1:200,A2) | E2: Pisto | F2: P0 | G2: 手枪动画；针对主、副手在枪柄1处，手持射击的武器动画
A3: Sword Animation Pack | B3: 9CG | C3: =COUNTIF('动画列表'!1:200,A3) | E3: DuoPisto | F3: P2 | G3: 双枪动画；针对主、副手在枪柄处，手持2把武器射击的武器动画
A4: Dynamic Sword Animset | B4: Blueisland A | C4: =COUNTIF('动画列表'!1:200,A4) | E4: Rifle | F4: P0 | G4: 步枪动画；针对主手在抢柄、副手在护木、抵肩射击的武器使用的动画
A5: Frank RPG Katana | B5: Wemakethegame | C5: =COUNTIF('动画列表'!1:200,A5) | E5: Launcher | F5: P1 | G5: 火箭筒动画；针对主手在抢柄、副手在枪身或握把、肩扛射击的武器使用的动画
A6: Pisto Pro | B6: MoCap | C6: =COUNTIF('动画列表'!1:200,A6) | E6: MachineGun | F6: P1 | G6: 机关枪动画；针对主手在抢柄、副手在枪身或握把、手提射击的武器使用的动画
A7: Rifle Shooter Pro | B7: MoCap | C7: =COUNTIF('动画列表'!1:200,A7) | E7: Sword | F7: P0 | G7: 短剑动画；针对主手在剑柄、单手挥舞的轻型利器或钝器武器使用的动画
A8: Sword and Shield Animation Pack | B8: 9CG | C8: =COUNTIF('动画列表'!1:200,A8) | E8: DuoSword | F8: P2 | G8: 短剑动画；针对主、副手在剑柄、双手各挥舞1把轻型利器或钝器武器使用的动画
A9: Longsword Animset Pro | B9: Kubold | C9: =COUNTIF('动画列表'!1:200,A9) | E9: LongSword | F9: P0 | G9: 长剑动画；针对主、副手在剑柄2处、双手挥舞的中型利器或钝器武器使用的动画
A10: Lyra | B10: Epic | C10: =COUNTIF('动画列表'!1:200,A10) | E10: Katana | F10: P2 | G10: 太刀动画；类似于长剑动画，只是针对太刀优化动作
A11: Mixamo | B11: Adobe | C11: =COUNTIF('动画列表'!1:200,A11) | E11: GreatSword | F11: P1 | G11: 巨剑动画；针对主、副手在剑柄2处、双手挥舞的重型利器或钝器武器使用的动画
A12: RollsAndDodges | B12: Hammerhead | C12: =COUNTIF('动画列表'!1:200,A12) | E12: Fist | F12: P2 | G12: 单拳动画；针对仅主手挥拳的武器使用的动画
A13: GreatSword Animset | B13: WeaponMaster Animset | C13: =COUNTIF('动画列表'!1:200,A13) | E13: DuoFist | F13: P2 | G13: 双拳动画；针对主、副手都挥拳的武器使用的动画
A14: Essential Great Sword Animation Pack | B14: space.bar.anim | C14: =COUNTIF('动画列表'!1:200,A14) | E14: UnArmed | F14: P0 | G14: 空手动画；未装备武器时的动画
A15: Essential Sword And Shield Animation Pack | B15: space.bar.anim | C15: =COUNTIF('动画列表'!1:200,A15)

Sheet 动画列表
A1: 武器类型 | B1: 动作分类 | G1: Equip / Reload (if ranged) | H1: Idle / Rest | I1: Walk | J1: Turn | K1: Jog | L1: Attack | M1: Jump | N1: Dash | O1: Crouch Walk | P1: Crouch / Crouch Idle Swap | Q1: Roll
A2: 手枪 | B2: Pisto | G2: Pisto Pro | H2: Pisto Pro | I2: Pisto Pro | J2: Pisto Pro | K2: Pisto Pro | L2: Pisto Pro | M2: Pisto Pro | N2: RollsAndDodges
A3: 手枪 | B3: DuoPisto | N3: RollsAndDodges
A4: 步枪,冲锋枪,霰弹枪 | B4: Rifle | G4: Lyra | H4: Lyra | I4: Lyra | J4: Lyra | K4: Lyra | L4: Lyra | M4: Lyra | N4: RollsAndDodges
A5: 发射器 | B5: Launcher | N5: RollsAndDodges
A6: 机关枪 | B6: MachineGun | N6: RollsAndDodges
A7: 短刀,锤 | B7: Sword | G7: Essential Sword And Shield Animation Pack | H7: Essential Sword And Shield Animation Pack | I7: Essential Sword And Shield Animation Pack | J7: Essential Sword And Shield Animation Pack | K7: Essential Sword And Shield Animation Pack | L7: Essential Sword And Shield Animation Pack | M7: Essential Sword And Shield Animation Pack | N7: RollsAndDodges
A8: 短刀,锤 | B8: DuoSword | N8: RollsAndDodges
A9: 长刀 | B9: LongSword | G9: Longsword Animset Pro | H9: Longsword Animset Pro | I9: Longsword Animset Pro | J9: Longsword Animset Pro | K9: Longsword Animset Pro | L9: Longsword Animset Pro | M9: Longsword Animset Pro | N9: RollsAndDodges
B10: Katana | N10: RollsAndDodges
A11: 巨锤 | B11: GreatSword | G11: Essential Great Sword Animation Pack | H11: Essential Great Sword Animation Pack | I11: Essential Great Sword Animation Pack | J11: Essential Great Sword Animation Pack | K11: Essential Great Sword Animation Pack | L11: Essential Great Sword Animation Pack | M11: Essential Great Sword Animation Pack | N11: RollsAndDodges
A12: 单拳套 | B12: Fist | N12: RollsAndDodges
A13: 双拳套 | B13: DuoFist | N13: RollsAndDodges

Sheet 攻击动作拆分
A1: 动作分类 | B1: 动画名称 | C1: 前摇截止 | D1: 间隔截止 | E1: 后摇截止 | F1: 前摇 | G1: 间隔 | H1: 后摇 | I1: 缩放目标 | J1: 缩放前摇 | K1: 缩放间隔 | L1: 缩放后摇
A2: LongSword | B2: Average | I2: 0.8 | J2: =AVERAGE(J3:J6) | K2: =AVERAGE(K3:K6) | L2: =AVERAGE(L3:L6)
A3: LongSword | B3: Longs_Attack_L2 | C3: 0.44 | D3: 0.7 | E3: 1.06 | F3: =C3 | G3: =D3-F3 | H3: =E3-D3 | I3: =I2 | J3: =F3*(I3/E3) | K3: =G3*I3/E3 | L3: =H3*I3/E3
A4: LongSword | B4: Longs_Attack_RD3 | C4: 0.47 | D4: 0.62 | E4: 1.12 | F4: =C4 | G4: =D4-F4 | H4: =E4-D4 | I4: =I3 | J4: =F4*(I4/E4) | K4: =G4*I4/E4 | L4: =H4*I4/E4
A5: LongSword | B5: Longs_Attack_LD1 | C5: 0.53 | D5: 0.91 | E5: 1.2 | F5: =C5 | G5: =D5-F5 | H5: =E5-D5 | I5: =I4 | J5: =F5*(I5/E5) | K5: =G5*I5/E5 | L5: =H5*I5/E5
A6: LongSword | B6: Longs_Attack_RD2 | C6: 0.79 | D6: 1.05 | E6: 1.41 | F6: =C6 | G6: =D6-F6 | H6: =E6-D6 | I6: =I5 | J6: =F6*(I6/E6) | K6: =G6*I6/E6 | L6: =H6*I6/E6
A7: GreatSword | B7: Average | I7: 1.1 | J7: =AVERAGE(J8:J9) | K7: =AVERAGE(K8:K9) | L7: =AVERAGE(L8:L9)
A8: GreatSword | B8: Greats_Attack_01 | C8: 0.59 | D8: 0.71 | E8: 1.21 | F8: =C8 | G8: =D8-F8 | H8: =E8-D8 | I8: =I7 | J8: =F8*(I8/E8) | K8: =G8*I8/E8 | L8: =H8*I8/E8
A9: GreatSword | B9: Greats_Attack_02 | C9: 0.45 | D9: 0.53 | E9: 0.97 | F9: =C9 | G9: =D9-F9 | H9: =E9-D9 | I9: =I8 | J9: =F9*(I9/E9) | K9: =G9*I9/E9 | L9: =H9*I9/E9
A10: Sword | B10: Average | I10: 0.6 | J10: =AVERAGE(J11:J12) | K10: =AVERAGE(K11:K12) | L10: =AVERAGE(L11:L12)
A11: Sword | B11: SwordV2_Attack_02 | C11: 0.34 | D11: 0.39 | E11: 0.93 | F11: =C11 | G11: =D11-F11 | H11: =E11-D11 | I11: =I10 | J11: =F11*(I11/E11) | K11: =G11*I11/E11 | L11: =H11*I11/E11
A12: Sword | B12: Sword1H_Attack_2 | C12: 0.25 | D12: 0.31 | E12: 0.53 | F12: =C12 | G12: =D12-F12 | H12: =E12-D12 | I12: =I11 | J12: =F12*(I12/E12) | K12: =G12*I12/E12 | L12: =H12*I12/E12
A13: Pisto
A14: DuoPisto
A15: Rifle
A16: Launcher
A17: MachineGun
A18: DuoSword
A19: Katana
A20: Fist
A21: DuoFist

Sheet VFX分类
A1: 供应商

Sheet VFX列表
A1: 用途 | B1: 资产 | C1: 调整 | D1: 备注
A2: 动能 · 远程武器 · 弹道
A3: 动能 · 远程武器 · 枪口
A4: 动能 · 远程武器 · 命中
A5: 远程武器 · 瞄准激光
A9: 动能 · 近战武器 · 尾迹
A10: 动能 · 近战武器 · 命中
A11: 角色 · 护甲受击
A12: 角色 · 生命受击
A13: 角色 · 护甲归零
A14: 角色 · 生命归零
A15: 角色 · 死亡损毁
A16: 角色 · 死亡出血

Sheet VFX规则
A1: VFX动态规则 | B1: https://www.figma.com/board/XpRcYn51iokcAnq5kT85nf/%E8%B7%83%E5%85%A5%E8%BF%B7%E5%9F%8E---%E7%99%BD%E6%9D%BF?node-id=785-2206&t=MIq0fZbAOAJhjy8i-4
A2: 瞄准性质 | B2: 释放性质 | C2: 技能示例 | D2: VFX开始 | E2: VFX中间 | F2: VFX结束
A3: 定向 | B3: 瞬发；没有抬手 | C3: 玩家：独头弹 | D3: 无，瞬发技能不播放瞄准VFX | E3: 无 | F3: 无
A4: 定向 | B4: 瞄准 | C4: 玩家：麻痹射击 | D4: 展示完整的VFX | E4: 维持不变 | F4: 消失
D5: 箭头宽度 = 技能伤害宽度
D6: 箭头长度 = 技能伤害距离
A7: 定向 | B7: 蓄力；影响射程，提前释放距离更短 | C7: 玩家：暂无 | D7: 展示长度被压缩的VFX | E7: 箭头逐渐变长 | F7: 展示完整的VFX
D8: 箭头宽度 = 技能伤害宽度 | E8: 箭头宽度 = 技能伤害宽度 | F8: 箭头宽度 = 技能伤害宽度
D9: 箭头长度 = 预设的最小距离 | E9: 箭头长度 = 随时间变长 | F9: 箭头长度 = 技能伤害距离
A11: 定向 | B11: 蓄力；影响释放，蓄力时长不达标会取消 | C11: 玩家：居合斩 | D11: 展示长度被压缩的VFX，和上一种类似，但VFX褪色 | E11: 箭头逐渐变长 | F11: 展示完整的VFX，并且VFX恢复成正常颜色
D12: 箭头宽度 = 技能伤害宽度 | E12: 箭头宽度 = 技能伤害宽度 | F12: 箭头宽度 = 技能伤害宽度
D13: 箭头长度 = 预设的最小距离 | E13: 箭头长度 = 随时间变长 | F13: 箭头长度 = 技能伤害距离
A15: 定向 | B15: 蓄力；影响伤害 | C15: 玩家：暂无 | D15: 展示完整的VFX，但VFX褪色 | E15: 一条颜色加深的VFX逐渐变长 | F15: 展示完整的VFX
B16: 瞬发；有明显抬手，用于提示抬手时长 | C16: 敌人：冲刺拳击 | D16: 箭头宽度 = 技能伤害宽度 | E16: 箭头宽度 = 技能伤害宽度 | F16: 箭头宽度 = 技能伤害宽度
B17: 敌人的定向技能前摇提示 | D17: 箭头长度 = 技能伤害距离 | E17: 箭头长度 = 技能伤害距离 | F17: 箭头长度 = 技能伤害距离
A19: 定点 | B19: 瞬发；没有抬手 | C19: 玩家：暂无 | D19: 无，瞬发技能不播放瞄准VFX | E19: 无 | F19: 无

Sheet SFX分类

Sheet SFX列表
A1: Action Name | B1: SFX Name | C1: 名称描述 | D1: 事件类型 | E1: 音效类型 | F1: 交互对象 | G1: 描述 1 | H1: 描述 2 | I1: 进度安排 | J1: 版本安排 | K1: 状态 | L1: 音效需求 | M1: 程序备注
A2: =D2&"_"&B2 | B2: =E2 & IF(F2<>"", "_" & F2, "") & IF(G2<>"", "_" & G2, "") & IF(H2<>"", "_" & H2, "") | C2: 电梯运行 | D2: Play | E2: AMB | F2: Lift | G2: Loop | I2: P2 | J2: v0.0.5
A3: =D3&"_"&B3 | B3: =E3 & IF(F3<>"", "_" & F3, "") & IF(G3<>"", "_" & G3, "") & IF(H3<>"", "_" & H3, "") | C3: 电梯运行 | D3: Stop | E3: AMB | F3: Lift | G3: Loop | I3: P2 | J3: v0.0.5
A4: =D4&"_"&B4 | B4: =E4 & IF(F4<>"", "_" & F4, "") & IF(G4<>"", "_" & G4, "") & IF(H4<>"", "_" & H4, "") | C4: 电梯启动 | D4: Play | E4: AMB | F4: Lift | G4: Start | I4: P1 | J4: v0.0.5
A5: =D5&"_"&B5 | B5: =E5 & IF(F5<>"", "_" & F5, "") & IF(G5<>"", "_" & G5, "") & IF(H5<>"", "_" & H5, "") | C5: 电梯停止 | D5: Play | E5: AMB | F5: Lift | G5: Stop | I5: P1 | J5: v0.0.5
A6: =D6&"_"&B6 | B6: =E6 & IF(F6<>"", "_" & F6, "") & IF(G6<>"", "_" & G6, "") & IF(H6<>"", "_" & H6, "") | C6: 电梯开门 | D6: Play | E6: UI | F6: Lift | G6: Door | H6: Open | I6: P1 | J6: v0.0.5
A7: =D7&"_"&B7 | B7: =E7 & IF(F7<>"", "_" & F7, "") & IF(G7<>"", "_" & G7, "") & IF(H7<>"", "_" & H7, "") | C7: 电梯关门 | D7: Play | E7: UI | F7: Lift | G7: Door | H7: Close | I7: P1 | J7: v0.0.5
A8: =D8&"_"&B8 | B8: =E8 & IF(F8<>"", "_" & F8, "") & IF(G8<>"", "_" & G8, "") & IF(H8<>"", "_" & H8, "") | C8: 玩家脚步声 | D8: Play | E8: Hero | F8: FootStep | I8: P0 | J8: v0.0.4 | L8: 只需要1步的声音，需要3~4个变体，可以自由组合；脚步应该类似于踩在人造石？高密度塑料？地面 | M8: 针对玩家不同的移动速度需要有解决方案，另外需要能随机播放预先准备好的脚步
A9: =D9&"_"&B9 | B9: =E9 & IF(F9<>"", "_" & F9, "") & IF(G9<>"", "_" & G9, "") & IF(H9<>"", "_" & H9, "") | C9: 玩家冲刺 | D9: Play | E9: Hero | F9: Dash | I9: P0 | J9: v0.0.4 | L9: 改为冲刺 | M9: 翻滚动作应该在持续期间（从起点到终点）持续更新声音刺激源
A10: =D10&"_"&B10 | B10: =E10 & IF(F10<>"", "_" & F10, "") & IF(G10<>"", "_" & G10, "") & IF(H10<>"", "_" & H10, "") | C10: 玩家翻滚 | D10: Play | E10: Hero | F10: Roll | I10: P0 | J10: v0.0.4
A11: =D11&"_"&B11 | B11: =E11 & IF(F11<>"", "_" & F11, "") & IF(G11<>"", "_" & G11, "") & IF(H11<>"", "_" & H11, "") | C11: 靠近可交互对象 | D11: Play | E11: UI | F11: Common | G11: GetInRange | I11: P0 | J11: v0.0.4 | L11: 交互提示UI本来很小，靠近以后会缩放变大方便玩家注意，音效应该对应类似于全息影像缩放音效，动画暂时没有
A12: =D12&"_"&B12 | B12: =E12 & IF(F12<>"", "_" & F12, "") & IF(G12<>"", "_" & G12, "") & IF(H12<>"", "_" & H12, "") | C12: 按下F打开武器打印机UI | D12: Play | E12: UI | F12: WeaponPrinter | G12: Open | I12: P1 | J12: v0.0.5 | L12: 镜头效果tbd
A13: =D13&"_"&B13 | B13: =E13 & IF(F13<>"", "_" & F13, "") & IF(G13<>"", "_" & G13, "") & IF(H13<>"", "_" & H13, "") | C13: 按下R重新打印武器 | D13: Play | E13: UI | F13: WeaponPrinter | G13: Refresh | I13: P1 | J13: v0.0.5
A14: =D14&"_"&B14 | B14: =E14 & IF(F14<>"", "_" & F14, "") & IF(G14<>"", "_" & G14, "") & IF(H14<>"", "_" & H14, "") | C14: 按下G升级武器 | D14: Play | E14: UI | F14: WeaponPrinter | G14: Upgrade | I14: P1 | J14: v0.0.5
A15: =D15&"_"&B15 | B15: =E15 & IF(F15<>"", "_" & F15, "") & IF(G15<>"", "_" & G15, "") & IF(H15<>"", "_" & H15, "") | C15: 按下F获取武器 | D15: Play | E15: UI | F15: WeaponPrinter | G15: Confirm | I15: P1 | J15: v0.0.5 | L15: 没有镜头效果，按下直接获得武器，类似于装备从高压储物柜拿出来的声音
A16: =D16&"_"&B16 | B16: =E16 & IF(F16<>"", "_" & F16, "") & IF(G16<>"", "_" & G16, "") & IF(H16<>"", "_" & H16, "") | C16: 信用点增加 | D16: Play | E16: UI | F16: Credit | G16: Add | I16: P1 | J16: v0.0.5 | L16: 没有镜头效果，有很多事件可能触发信用点减少，类似于数据传输的声音，积极
A17: =D17&"_"&B17 | B17: =E17 & IF(F17<>"", "_" & F17, "") & IF(G17<>"", "_" & G17, "") & IF(H17<>"", "_" & H17, "") | C17: 信用点减少 | D17: Play | E17: UI | F17: Credit | G17: Deduct | I17: P1 | J17: v0.0.5 | L17: 没有镜头效果，有很多事件可能触发信用点减少，类似于数据传输的声音，消极
A18: =D18&"_"&B18 | B18: =E18 & IF(F18<>"", "_" & F18, "") & IF(G18<>"", "_" & G18, "") & IF(H18<>"", "_" & H18, "") | C18: 按下F购买子弹 | D18: Play | E18: UI | F18: AmmoVEM | G18: Confirm | I18: P1 | J18: v0.0.5 | L18: 没有镜头效果，按下直接获得子弹，类似于自动贩卖机掉东西的声音
A19: =D19&"_"&B19 | B19: =E19 & IF(F19<>"", "_" & F19, "") & IF(G19<>"", "_" & G19, "") & IF(H19<>"", "_" & H19, "") | C19: 按下F回复生命值 | D19: Play | E19: UI | F19: HealingPod | G19: Confirm | I19: P1 | J19: v0.0.5 | L19: 没有镜头效果，按下直接获得生命值，类似于喷雾+常规游戏回血的声音
A20: =D20&"_"&B20 | B20: =E20 & IF(F20<>"", "_" & F20, "") & IF(G20<>"", "_" & G20, "") & IF(H20<>"", "_" & H20, "") | C20: 按下F获得信用点 | D20: Play | E20: UI | F20: HealingPod | G20: Confirm | I20: P1 | J20: v0.0.5 | L20: 没有镜头效果，按下直接获得信用点，类似于黑客侵入+数据传输的声音
A21: =D21&"_"&B21 | B21: =E21 & IF(F21<>"", "_" & F21, "") & IF(G21<>"", "_" & G21, "") & IF(H21<>"", "_" & H21, "") | C21: 按下F获得护甲值 | D21: Play | E21: UI | F21: ArmorReinforcer | G21: Confirm | I21: P1 | J21: v0.0.5 | L21: 没有镜头效果，按下直接获得护甲值，类似于电磁护盾充能的声音
A22: =D22&"_"&B22 | B22: =E22 & IF(F22<>"", "_" & F22, "") & IF(G22<>"", "_" & G22, "") & IF(H22<>"", "_" & H22, "") | C22: 对话滚出的打字音 | D22: Play | E22: UI | F22: Dialogue | G22: Rollout | I22: P2 | J22: v0.0.5 | L22: 动画tbd
A23: =D23&"_"&B23 | B23: =E23 & IF(F23<>"", "_" & F23, "") & IF(G23<>"", "_" & G23, "") & IF(H23<>"", "_" & H23, "") | C23: 通用按键/鼠标悬浮 | D23: Play | E23: UI | F23: Cursor | G23: Hover | I23: P1 | J23: v0.0.5 | L23: 动画tbd
A24: =D24&"_"&B24 | B24: =E24 & IF(F24<>"", "_" & F24, "") & IF(G24<>"", "_" & G24, "") & IF(H24<>"", "_" & H24, "") | C24: 通用按键/鼠标确认 | D24: Play | E24: UI | F24: Cursor | G24: Confirm | I24: P1 | J24: v0.0.5 | L24: 动画tbd
A25: =D25&"_"&B25 | B25: =E25 & IF(F25<>"", "_" & F25, "") & IF(G25<>"", "_" & G25, "") & IF(H25<>"", "_" & H25, "") | C25: 小型门打开 | D25: Play | E25: UI | F25: SmallDoor | G25: Open | I25: P0 | J25: v0.0.4 | L25: 动画tbd
A26: =D26&"_"&B26 | B26: =E26 & IF(F26<>"", "_" & F26, "") & IF(G26<>"", "_" & G26, "") & IF(H26<>"", "_" & H26, "") | C26: 小型门关闭 | D26: Play | E26: UI | F26: SmallDoor | G26: Close | I26: P0 | J26: v0.0.4 | L26: 动画tbd
... A30: =D30&"_"&B30 | B30: =E30 & IF(F30<>"", "_" & F30, "") & IF(G30<>"", "_" & G30, "") & IF(H30<>"", "_" & H30, "") | C30: 巨型门关闭 | D30: Play | E30: UI | F30: LargeDoor | G30: Close | I30: P2 | J30: v0.0.5 | L30: 动画tbd
A31: =D31&"_"&B31 | B31: =E31 & IF(F31<>"", "_" & F31, "") & IF(G31<>"", "_" & G31, "") & IF(H31<>"", "_" & H31, "") | C31: 动能/枪械/发射音效 | D31: Play | E31: Attack | F31: Ranged | G31: Gun | H31: Kinetic | I31: P1 | J31: v0.0.5
A32: =D32&"_"&B32 | B32: =E32 & IF(F32<>"", "_" & F32, "") & IF(G32<>"", "_" & G32, "") & IF(H32<>"", "_" & H32, "") | C32: 动能/枪械/击中音效 | D32: Play | E32: Impact | F32: Ranged | G32: Gun | H32: Kinetic | I32: P1 | J32: v0.0.5
A33: =D33&"_"&B33 | B33: =E33 & IF(F33<>"", "_" & F33, "") & IF(G33<>"", "_" & G33, "") & IF(H33<>"", "_" & H33, "") | C33: 电磁/枪械/发射音效 | D33: Play | E33: Attack | F33: Ranged | G33: Gun | H33: Electrical | I33: P1 | J33: v0.0.5
A34: =D34&"_"&B34 | B34: =E34 & IF(F34<>"", "_" & F34, "") & IF(G34<>"", "_" & G34, "") & IF(H34<>"", "_" & H34, "") | C34: 电磁/枪械/击中音效 | D34: Play | E34: Impact | F34: Ranged | G34: Gun | H34: Electrical | I34: P1 | J34: v0.0.5
A35: =D35&"_"&B35 | B35: =E35 & IF(F35<>"", "_" & F35, "") & IF(G35<>"", "_" & G35, "") & IF(H35<>"", "_" & H35, "") | C35: 热能/枪械/发射音效 | D35: Play | E35: Attack | F35: Ranged | G35: Gun | H35: Thermal | I35: P1 | J35: v0.0.5
A36: =D36&"_"&B36 | B36: =E36 & IF(F36<>"", "_" & F36, "") & IF(G36<>"", "_" & G36, "") & IF(H36<>"", "_" & H36, "") | C36: 热能/枪械/击中音效 | D36: Play | E36: Impact | F36: Ranged | G36: Gun | H36: Thermal | I36: P1 | J36: v0.0.5
A37: =D37&"_"&B37 | B37: =E37 & IF(F37<>"", "_" & F37, "") & IF(G37<>"", "_" & G37, "") & IF(H37<>"", "_" & H37, "") | C37: 热能/喷射器/发射音效 | D37: Play | E37: Attack | F37: Ranged | G37: Thrower | H37: Thermal | I37: P1 | J37: v0.0.5
A38: =D38&"_"&B38 | B38: =E38 & IF(F38<>"", "_" & F38, "") & IF(G38<>"", "_" & G38, "") & IF(H38<>"", "_" & H38, "") | C38: 热能/喷射器/击中音效 | D38: Play | E38: Impact | F38: Ranged | G38: Thrower | H38: Thermal | I38: P1 | J38: v0.0.5
A39: =D39&"_"&B39 | B39: =E39 & IF(F39<>"", "_" & F39, "") & IF(G39<>"", "_" & G39, "") & IF(H39<>"", "_" & H39, "") | C39: 单手/锐器/挥舞 | D39: Play | E39: Attack | F39: OneHand | G39: Sharp | I39: P1 | J39: v0.0.4
A40: =D40&"_"&B40 | B40: =E40 & IF(F40<>"", "_" & F40, "") & IF(G40<>"", "_" & G40, "") & IF(H40<>"", "_" & H40, "") | C40: 单手/锐器/击中 | D40: Play | E40: Impact | F40: OneHand | G40: Sharp | I40: P1 | J40: v0.0.4
A41: =D41&"_"&B41 | B41: =E41 & IF(F41<>"", "_" & F41, "") & IF(G41<>"", "_" & G41, "") & IF(H41<>"", "_" & H41, "") | C41: 双手轻型/锐器/挥舞 | D41: Play | E41: Attack | F41: TwoHand | G41: Sharp | I41: P0 | J41: v0.0.4
A42: =D42&"_"&B42 | B42: =E42 & IF(F42<>"", "_" & F42, "") & IF(G42<>"", "_" & G42, "") & IF(H42<>"", "_" & H42, "") | C42: 双手轻型/锐器/击中 | D42: Play | E42: Impact | F42: TwoHand | G42: Sharp | I42: P0 | J42: v0.0.4
A43: =D43&"_"&B43 | B43: =E43 & IF(F43<>"", "_" & F43, "") & IF(G43<>"", "_" & G43, "") & IF(H43<>"", "_" & H43, "") | C43: 双手重型/锐器/挥舞 | D43: Play | E43: Attack | F43: Heavy | G43: Sharp | I43: P1 | J43: v0.0.4
...

Sheet Sheet9
